Workbook

Sheet Cover
A1: 02 — Market Sizing: U.S. Vertical Opportunity for Clay
A2: Independent portfolio case study by Zhuoran (Zora) Wang · Not commissioned by or affiliated with Clay Labs Inc. · Research reference date: 2026-10-18
A4: Purpose | B4: Size and compare three candidate U.S. verticals bottom-up (unique firms × annual contract value), with explicit TAM / SAM / SOM definitions and sensitivity ranges.
A5: TAM | B5: Annual revenue if every in-scope firm (20+ employees, segment NAICS) bought Clay at the size-band ACV. A theoretical ceiling, not a forecast.
A6: SAM | B6: TAM firms filtered to those with (1) an active B2B outbound / territory sales motion and (2) a CRM/data stack Clay can integrate with today (Growth tier and above).
A7: SOM | B7: Year-3 ARR potential from SAM firms at a uniform 'fair-share' penetration rate. Phase 1 deliberately applies the SAME penetration to every segment; segment-specific right-to-win is assessed in Phases 2–3.
A8: Unit of analysis | B8: Unique FIRMS (enterprises), never establishments. Firm counts are de-duplicated across sub-industries using Census-measured overlap (see Firm_Counts).
A9: Primary data | B9: 2022 Economic Census — Establishment & Firm Size Statistics, Employment Size of Firms (EC2200SIZEEMPFIRM); BLS OEWS May 2025 industry-specific estimates. See Sources.
A10: Not a forecast | B10: Nothing here is a Clay forecast or uses Clay internal data. ACV, readiness and penetration inputs are labeled benchmarks [B] or scenario assumptions [D].
A11: Color legend | B11: Blue text = hardcoded input · Black = formula · Green = formula linking another tab · Yellow fill = key judgment-based assumption.
A12: Evidence classes | B12: A = verified public fact · B = external benchmark / third-party estimate · C = analyst estimate (derived) · D = scenario assumption · E = recommendation.
A13: Tabs | B13: Executive_Summary → Assumptions → Firm_Counts → Segment_Profile → TAM_SAM_SOM → Sensitivity → Hypothesis_Tests → Segment_Defs → Raw_Census → Raw_OEWS → Sources

Sheet Executive_Summary
A1: Executive summary — Phase 1 market sizing (Base case unless noted)
A2: All $ are annual. SOM = year-3 ARR potential at uniform fair-share penetration (scenario output, not a forecast). Segments are alternatives; do not add them.
A4: Metric | B4: A. Industrial Distribution | C4: B. Industrial Manufacturing | D4: C. B2B Professional Services | E4: Unit / class
A5: Unique firms, 20+ employees | B5: =Firm_Counts!D61 -> 11493.544 | C5: =Firm_Counts!E61 -> 23784.588 | D5: =Firm_Counts!F61 -> 33035.014 | E5: firms · [C] from [A]
A6: of which SMB (20–99) | B6: =Firm_Counts!D58 -> 9106.2022 | C6: =Firm_Counts!E58 -> 18442.232 | D6: =Firm_Counts!F58 -> 26020.542 | E6: firms
A7: of which Mid-Market (100–499) | B7: =Firm_Counts!D59 -> 2011.3421 | C7: =Firm_Counts!E59 -> 4448.9884 | D7: =Firm_Counts!F59 -> 5775.4045 | E7: firms
A8: of which Enterprise (500+) | B8: =Firm_Counts!D60 -> 376 | C8: =Firm_Counts!E60 -> 893.36787 | D8: =Firm_Counts!F60 -> 1239.0676 | E8: firms
A9: TAM (Base) | B9: =TAM_SAM_SOM!E9 -> 1.3108336e+08 | C9: =TAM_SAM_SOM!E13 -> 2.8089858e+08 | D9: =TAM_SAM_SOM!E17 -> 3.8500621e+08 | E9: $/yr · [C]/[D]
A10: SAM (Base) | B10: =TAM_SAM_SOM!I9 -> 68163347 | C10: =TAM_SAM_SOM!I13 -> 75842617 | D10: =TAM_SAM_SOM!I17 -> 1.4822739e+08 | E10: $/yr · [C]/[D]
A11: SOM — year-3 ARR potential (Base) | B11: =TAM_SAM_SOM!L9 -> 1864123.6 | C11: =TAM_SAM_SOM!L13 -> 2149272.5 | D11: =TAM_SAM_SOM!L17 -> 4178480.9 | E11: $/yr · [D]
A12: SOM range — compounded Low | B12: =TAM_SAM_SOM!L26 -> 240197.34 | C12: =TAM_SAM_SOM!L30 -> 211060.82 | D12: =TAM_SAM_SOM!L34 -> 469215.74 | E12: $/yr · outer bound
A13: SOM range — compounded High | B13: =TAM_SAM_SOM!L43 -> 8834852.7 | C13: =TAM_SAM_SOM!L47 -> 12980959 | D13: =TAM_SAM_SOM!L51 -> 23406300 | E13: $/yr · outer bound
A14: SOM customers, year 3 (Base) | B14: =TAM_SAM_SOM!K9 -> 114.13651 | C14: =TAM_SAM_SOM!K13 -> 125.20041 | D14: =TAM_SAM_SOM!K17 -> 245.59701 | E14: customers · [D]
A15: SAM as % of TAM | B15: =B10/B9 -> 0.52 | C15: =C10/C9 -> 0.27 | D15: =D10/D9 -> 0.385 | E15: % · [D]
A17: Structural profile
A18: Sales occupations share of employment (all industries ≈ 8.6%) | B18: =Segment_Profile!B13 -> 0.2195913 | C18: =Segment_Profile!C13 -> 0.027389137 | D18: =Segment_Profile!D13 -> 0.061716312 | E18: % · [C] from OEWS
A19: Computer & math occupations share (all industries ≈ 3.4%) | B19: =Segment_Profile!B18 -> 0.023270103 | C19: =Segment_Profile!C18 -> 0.015371036 | D19: =Segment_Profile!D18 -> 0.24190733 | E19: % · [C] from OEWS
A20: Implied sales staff per 20+ firm | B20: =Segment_Profile!B19 -> 27.700087 | C20: =Segment_Profile!C19 -> 3.6494993 | D20: =Segment_Profile!D19 -> 9.3223336 | E20: people · [C]
A22: Sanity checks
A23: Clay customers reported (Sep 2026, S03) — for scale | B23: 17000 | E23: customers · [A*]
A24: Base SOM customers as % of Clay's total customer count | B24: =B14/$B$23 -> 0.0067139126 | C24: =C14/$B$23 -> 0.0073647297 | D24: =D14/$B$23 -> 0.014446883 | E24: % · [C]
A25: Clay ARR, third-party estimate (Sep 2026, S23; was ~$150M in May 2026, S04) — for scale | B25: 200000000 | E25: $/yr · [B] estimate
A26: Base SOM ARR as % of Clay's estimated ARR | B26: =B11/$B$25 -> 0.0093206179 | C26: =C11/$B$25 -> 0.010746362 | D26: =D11/$B$25 -> 0.020892405 | E26: % · [C] (H8 context)
A28: Key takeaways (Phase 1)
A29: 1. Industrial distribution is the smallest segment by firm count (H2 rejected): professional services offers nearly 3× the 20+ firm universe and the largest TAM, SAM and SOM at equal ACV and penetration.
A30: 2. Distribution is the most sales-intensive vertical in scope — sales occupations are ~22% of employment (~2.5× the economy-wide share) and an in-scope firm employs ~28 sales staff on average. Because so many distributors run active sales motions, distribution's SAM is roughly equal to manufacturing's despite having half the firms.
A31: 3. Manufacturing is large in firm count but has the weakest direct-sales motion (~2.7% sales occupations); much of its selling is outsourced to distributors and reps — a reason to reach manufacturers through the distribution channel rather than as a stand-alone vertical.
A32: 4. Builder capacity is the mirror image of need: professional services has near-software levels of technical staff; distribution and manufacturing are below the economy-wide average (preliminary support for H4).
A33: 5. At uniform fair-share penetration, every segment's 3-year SOM is ~1–2% of Clay's estimated ARR — any vertical program is an incremental growth option, not a pivot (context for H8).

Sheet Assumptions
A1: Assumptions — every judgment-based input in one place (Low / Base / High)
A2: Low and High are compounded in the scenario outer bounds on TAM_SAM_SOM; one-at-a-time swings are on Sensitivity. Edit blue cells only.
A4: ID | B4: Parameter | C4: Applies to | D4: Low | E4: Base | F4: High | G4: Unit | H4: Class | I4: Source / rationale
A5: A1 | B5: Annual contract value (ACV) | C5: SMB (20–99) | D5: 5352 | E5: 7500 | F5: 12000 | G5: $/yr | H5: B/D | I5: Low = Growth-tier entry at list, annual billing ($446/mo × 12; S01 [A]). CRM sync, webhooks and HTTP API require Growth or above. Base/High allow for additional Actions / Data-Credit tiers. Vendr reports mid-market buyers at ~$10K–$30K (S16 [B]).
A6: A2 | B6: Annual contract value (ACV) | C6: Mid-Market (100–499) | D6: 12000 | E6: 20000 | F6: 35000 | G6: $/yr | H6: B/D | I6: Anchored on Vendr's reported mid-market range of ~$10K–$30K/yr (S16 [B], updated Feb 2026; vendor-reported, small sample).
A7: A3 | B7: Annual contract value (ACV) | C7: Enterprise (500+) | D7: 30000 | E7: 60000 | F7: 120000 | G7: $/yr | H7: B/D | I7: Base = Vendr median $59,996/yr across 96 purchases; observed range $16,500–$170,000 (S16 [B]). Negotiated, sales-led deals; skews larger than self-serve.
A8: A4 | B8: SAM filter 1 — active B2B outbound / territory sales motion | C8: A. Industrial Distribution | D8: 0.65 | E8: 0.8 | F8: 0.9 | G8: % firms | H8: D | I8: Distribution is the most sales-intensive segment: sales occupations = ~22% of employment vs ~8.6% economy-wide (≈2.5×) (OEWS May 2025, S15 [A]; see Segment_Profile).
A9: A5 | B9: SAM filter 1 — active B2B outbound / territory sales motion | C9: B. Industrial Manufacturing | D9: 0.3 | E9: 0.45 | F9: 0.6 | G9: % firms | H9: D | I9: Sales occupations only ~2.7% of manufacturing employment (S15 [A]) — consistent with many manufacturers selling through distributors and independent reps rather than direct outbound teams.
A10: A6 | B10: SAM filter 1 — active B2B outbound / territory sales motion | C10: C. B2B Professional Services | D10: 0.4 | E10: 0.55 | F10: 0.7 | G10: % firms | H10: D | I10: Sales occupations ~6.2% of employment (S15 [A]), but BD is often done by billable 'seller-doers' (partners/principals) not counted as sales staff; A&E skews RFP-driven.
A11: A7 | B11: SAM filter 2 — CRM / data stack Clay can integrate with | C11: A. Industrial Distribution | D11: 0.52 | E11: 0.65 | F11: 0.76 | G11: % firms | H11: B/D | I11: Distribution Strategy Group 2022 survey of distributors ($10M–$500M revenue; n=96 respondents, 66 distributors): 52% general-purpose CRM, 15% purpose-built, 9% custom, 9% ERP-provided, 15% none (S17 [B]). Low = general-purpose only; High = any non-ERP CRM.
A12: A8 | B12: SAM filter 2 — CRM / data stack Clay can integrate with | C12: B. Industrial Manufacturing | D12: 0.45 | E12: 0.6 | F12: 0.75 | G12: % firms | H12: D | I12: No reliable public adoption rate found (a 2023 vendor-sponsored survey reported usage frequency, not adoption — not used). Set slightly below distribution given lower sales-function density. KEY DATA GAP.
A13: A9 | B13: SAM filter 2 — CRM / data stack Clay can integrate with | C13: C. B2B Professional Services | D13: 0.55 | E13: 0.7 | F13: 0.85 | G13: % firms | H13: D | I13: No reliable public adoption rate found. Set above distribution given far higher technical workforce share (computer occupations ~24% of employment vs ~2% in distribution; S15 [A]). KEY DATA GAP.
A14: A10 | B14: 3-year penetration of SAM firms (uniform across segments) | C14: SMB (20–99) | D14: 0.005 | E14: 0.015 | F14: 0.03 | G14: % SAM firms | H14: D | I14: Fair-share assumption for a focused vertical program over three years. Deliberately identical across segments in Phase 1. Sanity check vs Clay's 17,000+ total customers on Executive_Summary.
A15: A11 | B15: 3-year penetration of SAM firms (uniform across segments) | C15: Mid-Market (100–499) | D15: 0.01 | E15: 0.03 | F15: 0.06 | G15: % SAM firms | H15: D | I15: Higher than SMB: sales-assisted motion concentrates effort on fewer, larger accounts.
A16: A12 | B16: 3-year penetration of SAM firms (uniform across segments) | C16: Enterprise (500+) | D16: 0.02 | E16: 0.06 | F16: 0.12 | G16: % SAM firms | H16: D | I16: Highest: named-account coverage; Clay reports >200% enterprise NRR (S02 [A]) indicating strong land-and-expand once in.
A18: Note: there is no segment-specific ACV multiplier and no segment-specific penetration in Phase 1 by design — Phase 1 isolates market size and reachability. Competitive position and right-to-win enter in Phases 2–3; any segment-specific ACV evidence (e.g., seller headcount driving usage) is tested in Phase 4.

Sheet Firm_Counts
A1: Firm counts — unique U.S. firms by segment and firm size (2022)
A2: Firms operated for the entire year. Suppressed cells imputed (block 2). Sub-industry totals de-duplicated with Census-measured overlap (block 3). Establishments shown for contrast only — never used as the counting unit.
A4: Segment | B4: NAICS | C4: Industry | D4: 20-49 | E4: 50-99 | F4: 100-249 | G4: 250-499 | H4: 500+ | I4: Firms 20+ | J4: Firms <20 | K4: All FY firms | L4: FY establishments | M4: Estab. per firm
A5: A. Industrial Distribution | B5: 4235 | C5: Metal & Mineral (except Petroleum) Merchant Wholesalers | D5: =SUMIFS(Raw_Census!$D$5:$D$379,Raw_Census!$A$5:$A$379,$B5&"|"&D$4) -> 771 | E5: =E28 -> 262.65787 | F5: =F28 -> 161.32381 | G5: =G28 -> 51.018318 | H5: =SUMIFS(Raw_Census!$D$5:$D$379,Raw_Census!$A$5:$A$379,$B5&"|"&H$4) -> 22 | I5: =SUM(D5:H5) -> 1268 | J5: =SUMIFS(Raw_Census!$D$5:$D$379,Raw_Census!$A$5:$A$379,$B5&"|0-4")+SUMIFS(Raw_Census!$D$5:$D$379,Raw_Census!$A$5:$A$379,$B5&"|5-9")+SUMIFS(Raw_Census!$D$5:$D$379,Raw_Census!$A$5:$A$379,$B5&"|10-19") -> 4559 | K5: =SUMIFS(Raw_Census!$D$5:$D$379,Raw_Census!$A$5:$A$379,$B5&"|FY") -> 5827 | L5: =SUMIFS(Raw_Census!$F$5:$F$379,Raw_Census!$A$5:$A$379,$B5&"|FY") -> 8293 | M5: =IFERROR(L5/K5,0) -> 1.4232023
A6: A. Industrial Distribution | B6: 4236 | C6: Household Appliances & Electrical/Electronic Goods Merchant Wholesalers | D6: =SUMIFS(Raw_Census!$D$5:$D$379,Raw_Census!$A$5:$A$379,$B6&"|"&D$4) -> 1408 | E6: =SUMIFS(Raw_Census!$D$5:$D$379,Raw_Census!$A$5:$A$379,$B6&"|"&E$4) -> 570 | F6: =SUMIFS(Raw_Census!$D$5:$D$379,Raw_Census!$A$5:$A$379,$B6&"|"&F$4) -> 350 | G6: =SUMIFS(Raw_Census!$D$5:$D$379,Raw_Census!$A$5:$A$379,$B6&"|"&G$4) -> 136 | H6: =SUMIFS(Raw_Census!$D$5:$D$379,Raw_Census!$A$5:$A$379,$B6&"|"&H$4) -> 114 | I6: =SUM(D6:H6) -> 2578 | J6: =SUMIFS(Raw_Census!$D$5:$D$379,Raw_Census!$A$5:$A$379,$B6&"|0-4")+SUMIFS(Raw_Census!$D$5:$D$379,Raw_Census!$A$5:$A$379,$B6&"|5-9")+SUMIFS(Raw_Census!$D$5:$D$379,Raw_Census!$A$5:$A$379,$B6&"|10-19") -> 11708 | K6: =SUMIFS(Raw_Census!$D$5:$D$379,Raw_Census!$A$5:$A$379,$B6&"|FY") -> 14286 | L6: =SUMIFS(Raw_Census!$F$5:$F$379,Raw_Census!$A$5:$A$379,$B6&"|FY") -> 23428 | M6: =IFERROR(L6/K6,0) -> 1.6399272
A7: A. Industrial Distribution | B7: 4237 | C7: Hardware, Plumbing & Heating Equipment Merchant Wholesalers | D7: =SUMIFS(Raw_Census!$D$5:$D$379,Raw_Census!$A$5:$A$379,$B7&"|"&D$4) -> 1013 | E7: =SUMIFS(Raw_Census!$D$5:$D$379,Raw_Census!$A$5:$A$379,$B7&"|"&E$4) -> 424 | F7: =SUMIFS(Raw_Census!$D$5:$D$379,Raw_Census!$A$5:$A$379,$B7&"|"&F$4) -> 242 | G7: =SUMIFS(Raw_Census!$D$5:$D$379,Raw_Census!$A$5:$A$379,$B7&"|"&G$4) -> 85 | H7: =SUMIFS(Raw_Census!$D$5:$D$379,Raw_Census!$A$5:$A$379,$B7&"|"&H$4) -> 57 | I7: =SUM(D7:H7) -> 1821 | J7: =SUMIFS(Raw_Census!$D$5:$D$379,Raw_Census!$A$5:$A$379,$B7&"|0-4")+SUMIFS(Raw_Census!$D$5:$D$379,Raw_Census!$A$5:$A$379,$B7&"|5-9")+SUMIFS(Raw_Census!$D$5:$D$379,Raw_Census!$A$5:$A$379,$B7&"|10-19") -> 6792 | K7: =SUMIFS(Raw_Census!$D$5:$D$379,Raw_Census!$A$5:$A$379,$B7&"|FY") -> 8613 | L7: =SUMIFS(Raw_Census!$F$5:$F$379,Raw_Census!$A$5:$A$379,$B7&"|FY") -> 19057 | M7: =IFERROR(L7/K7,0) -> 2.2125856
A8: A. Industrial Distribution | B8: 4238 | C8: Machinery, Equipment & Supplies Merchant Wholesalers | D8: =SUMIFS(Raw_Census!$D$5:$D$379,Raw_Census!$A$5:$A$379,$B8&"|"&D$4) -> 3622 | E8: =SUMIFS(Raw_Census!$D$5:$D$379,Raw_Census!$A$5:$A$379,$B8&"|"&E$4) -> 1218 | F8: =SUMIFS(Raw_Census!$D$5:$D$379,Raw_Census!$A$5:$A$379,$B8&"|"&F$4) -> 746 | G8: =SUMIFS(Raw_Census!$D$5:$D$379,Raw_Census!$A$5:$A$379,$B8&"|"&G$4) -> 240 | H8: =SUMIFS(Raw_Census!$D$5:$D$379,Raw_Census!$A$5:$A$379,$B8&"|"&H$4) -> 183 | I8: =SUM(D8:H8) -> 6009 | J8: =SUMIFS(Raw_Census!$D$5:$D$379,Raw_Census!$A$5:$A$379,$B8&"|0-4")+SUMIFS(Raw_Census!$D$5:$D$379,Raw_Census!$A$5:$A$379,$B8&"|5-9")+SUMIFS(Raw_Census!$D$5:$D$379,Raw_Census!$A$5:$A$379,$B8&"|10-19") -> 27128 | K8: =SUMIFS(Raw_Census!$D$5:$D$379,Raw_Census!$A$5:$A$379,$B8&"|FY") -> 33137 | L8: =SUMIFS(Raw_Census!$F$5:$F$379,Raw_Census!$A$5:$A$379,$B8&"|FY") -> 52144 | M8: =IFERROR(L8/K8,0) -> 1.5735884
A9: A. Industrial Distribution — subtotal (before de-dup) | D9: =SUM(D5:D8) -> 6814 | E9: =SUM(E5:E8) -> 2474.6579 | F9: =SUM(F5:F8) -> 1499.3238 | G9: =SUM(G5:G8) -> 512.01832 | H9: =SUM(H5:H8) -> 376 | I9: =SUM(I5:I8) -> 11676 | J9: =SUM(J5:J8) -> 50187 | K9: =SUM(K5:K8) -> 61863 | L9: =SUM(L5:L8) -> 102922 | M9: =IFERROR(L9/K9,0) -> 1.6637085
A11: B. Industrial Manufacturing | B11: 326 | C11: Plastics & Rubber Products Manufacturing | D11: =SUMIFS(Raw_Census!$D$5:$D$379,Raw_Census!$A$5:$A$379,$B11&"|"&D$4) -> 1505 | E11: =SUMIFS(Raw_Census!$D$5:$D$379,Raw_Census!$A$5:$A$379,$B11&"|"&E$4) -> 935 | F11: =SUMIFS(Raw_Census!$D$5:$D$379,Raw_Census!$A$5:$A$379,$B11&"|"&F$4) -> 760 | G11: =SUMIFS(Raw_Census!$D$5:$D$379,Raw_Census!$A$5:$A$379,$B11&"|"&G$4) -> 313 | H11: =SUMIFS(Raw_Census!$D$5:$D$379,Raw_Census!$A$5:$A$379,$B11&"|"&H$4) -> 277 | I11: =SUM(D11:H11) -> 3790 | J11: =SUMIFS(Raw_Census!$D$5:$D$379,Raw_Census!$A$5:$A$379,$B11&"|0-4")+SUMIFS(Raw_Census!$D$5:$D$379,Raw_Census!$A$5:$A$379,$B11&"|5-9")+SUMIFS(Raw_Census!$D$5:$D$379,Raw_Census!$A$5:$A$379,$B11&"|10-19") -> 4626 | K11: =SUMIFS(Raw_Census!$D$5:$D$379,Raw_Census!$A$5:$A$379,$B11&"|FY") -> 8416 | L11: =SUMIFS(Raw_Census!$F$5:$F$379,Raw_Census!$A$5:$A$379,$B11&"|FY") -> 11550 | M11: =IFERROR(L11/K11,0) -> 1.3723859
A12: B. Industrial Manufacturing | B12: 332 | C12: Fabricated Metal Product Manufacturing | D12: =SUMIFS(Raw_Census!$D$5:$D$379,Raw_Census!$A$5:$A$379,$B12&"|"&D$4) -> 7758 | E12: =SUMIFS(Raw_Census!$D$5:$D$379,Raw_Census!$A$5:$A$379,$B12&"|"&E$4) -> 3050 | F12: =SUMIFS(Raw_Census!$D$5:$D$379,Raw_Census!$A$5:$A$379,$B12&"|"&F$4) -> 1685 | G12: =SUMIFS(Raw_Census!$D$5:$D$379,Raw_Census!$A$5:$A$379,$B12&"|"&G$4) -> 423 | H12: =SUMIFS(Raw_Census!$D$5:$D$379,Raw_Census!$A$5:$A$379,$B12&"|"&H$4) -> 278 | I12: =SUM(D12:H12) -> 13194 | J12: =SUMIFS(Raw_Census!$D$5:$D$379,Raw_Census!$A$5:$A$379,$B12&"|0-4")+SUMIFS(Raw_Census!$D$5:$D$379,Raw_Census!$A$5:$A$379,$B12&"|5-9")+SUMIFS(Raw_Census!$D$5:$D$379,Raw_Census!$A$5:$A$379,$B12&"|10-19") -> 36021 | K12: =SUMIFS(Raw_Census!$D$5:$D$379,Raw_Census!$A$5:$A$379,$B12&"|FY") -> 49215 | L12: =SUMIFS(Raw_Census!$F$5:$F$379,Raw_Census!$A$5:$A$379,$B12&"|FY") -> 53708 | M12: =IFERROR(L12/K12,0) -> 1.0912933
A13: B. Industrial Manufacturing | B13: 333 | C13: Machinery Manufacturing | D13: =SUMIFS(Raw_Census!$D$5:$D$379,Raw_Census!$A$5:$A$379,$B13&"|"&D$4) -> 3291 | E13: =SUMIFS(Raw_Census!$D$5:$D$379,Raw_Census!$A$5:$A$379,$B13&"|"&E$4) -> 1484 | F13: =SUMIFS(Raw_Census!$D$5:$D$379,Raw_Census!$A$5:$A$379,$B13&"|"&F$4) -> 997 | G13: =SUMIFS(Raw_Census!$D$5:$D$379,Raw_Census!$A$5:$A$379,$B13&"|"&G$4) -> 358 | H13: =SUMIFS(Raw_Census!$D$5:$D$379,Raw_Census!$A$5:$A$379,$B13&"|"&H$4) -> 295 | I13: =SUM(D13:H13) -> 6425 | J13: =SUMIFS(Raw_Census!$D$5:$D$379,Raw_Census!$A$5:$A$379,$B13&"|0-4")+SUMIFS(Raw_Census!$D$5:$D$379,Raw_Census!$A$5:$A$379,$B13&"|5-9")+SUMIFS(Raw_Census!$D$5:$D$379,Raw_Census!$A$5:$A$379,$B13&"|10-19") -> 12231 | K13: =SUMIFS(Raw_Census!$D$5:$D$379,Raw_Census!$A$5:$A$379,$B13&"|FY") -> 18656 | L13: =SUMIFS(Raw_Census!$F$5:$F$379,Raw_Census!$A$5:$A$379,$B13&"|FY") -> 21352 | M13: =IFERROR(L13/K13,0) -> 1.1445111
A14: B. Industrial Manufacturing | B14: 335 | C14: Electrical Equipment, Appliance & Component Manufacturing | D14: =SUMIFS(Raw_Census!$D$5:$D$379,Raw_Census!$A$5:$A$379,$B14&"|"&D$4) -> 775 | E14: =SUMIFS(Raw_Census!$D$5:$D$379,Raw_Census!$A$5:$A$379,$B14&"|"&E$4) -> 422 | F14: =SUMIFS(Raw_Census!$D$5:$D$379,Raw_Census!$A$5:$A$379,$B14&"|"&F$4) -> 288 | G14: =SUMIFS(Raw_Census!$D$5:$D$379,Raw_Census!$A$5:$A$379,$B14&"|"&G$4) -> 108 | H14: =SUMIFS(Raw_Census!$D$5:$D$379,Raw_Census!$A$5:$A$379,$B14&"|"&H$4) -> 129 | I14: =SUM(D14:H14) -> 1722 | J14: =SUMIFS(Raw_Census!$D$5:$D$379,Raw_Census!$A$5:$A$379,$B14&"|0-4")+SUMIFS(Raw_Census!$D$5:$D$379,Raw_Census!$A$5:$A$379,$B14&"|5-9")+SUMIFS(Raw_Census!$D$5:$D$379,Raw_Census!$A$5:$A$379,$B14&"|10-19") -> 2792 | K14: =SUMIFS(Raw_Census!$D$5:$D$379,Raw_Census!$A$5:$A$379,$B14&"|FY") -> 4514 | L14: =SUMIFS(Raw_Census!$F$5:$F$379,Raw_Census!$A$5:$A$379,$B14&"|FY") -> 5270 | M14: =IFERROR(L14/K14,0) -> 1.167479
A15: B. Industrial Manufacturing — subtotal (before de-dup) | D15: =SUM(D11:D14) -> 13329 | E15: =SUM(E11:E14) -> 5891 | F15: =SUM(F11:F14) -> 3730 | G15: =SUM(G11:G14) -> 1202 | H15: =SUM(H11:H14) -> 979 | I15: =SUM(I11:I14) -> 25131 | J15: =SUM(J11:J14) -> 55670 | K15: =SUM(K11:K14) -> 80801 | L15: =SUM(L11:L14) -> 91880 | M15: =IFERROR(L15/K15,0) -> 1.1371146
A17: C. B2B Professional Services | B17: 5413 | C17: Architectural, Engineering & Related Services | D17: =SUMIFS(Raw_Census!$D$5:$D$379,Raw_Census!$A$5:$A$379,$B17&"|"&D$4) -> 5930 | E17: =SUMIFS(Raw_Census!$D$5:$D$379,Raw_Census!$A$5:$A$379,$B17&"|"&E$4) -> 2104 | F17: =SUMIFS(Raw_Census!$D$5:$D$379,Raw_Census!$A$5:$A$379,$B17&"|"&F$4) -> 1251 | G17: =SUMIFS(Raw_Census!$D$5:$D$379,Raw_Census!$A$5:$A$379,$B17&"|"&G$4) -> 429 | H17: =SUMIFS(Raw_Census!$D$5:$D$379,Raw_Census!$A$5:$A$379,$B17&"|"&H$4) -> 387 | I17: =SUM(D17:H17) -> 10101 | J17: =SUMIFS(Raw_Census!$D$5:$D$379,Raw_Census!$A$5:$A$379,$B17&"|0-4")+SUMIFS(Raw_Census!$D$5:$D$379,Raw_Census!$A$5:$A$379,$B17&"|5-9")+SUMIFS(Raw_Census!$D$5:$D$379,Raw_Census!$A$5:$A$379,$B17&"|10-19") -> 70489 | K17: =SUMIFS(Raw_Census!$D$5:$D$379,Raw_Census!$A$5:$A$379,$B17&"|FY") -> 80590 | L17: =SUMIFS(Raw_Census!$F$5:$F$379,Raw_Census!$A$5:$A$379,$B17&"|FY") -> 102514 | M17: =IFERROR(L17/K17,0) -> 1.2720437
A18: C. B2B Professional Services | B18: 5415 | C18: Computer Systems Design & Related Services | D18: =SUMIFS(Raw_Census!$D$5:$D$379,Raw_Census!$A$5:$A$379,$B18&"|"&D$4) -> 5831 | E18: =SUMIFS(Raw_Census!$D$5:$D$379,Raw_Census!$A$5:$A$379,$B18&"|"&E$4) -> 2359 | F18: =SUMIFS(Raw_Census!$D$5:$D$379,Raw_Census!$A$5:$A$379,$B18&"|"&F$4) -> 1581 | G18: =SUMIFS(Raw_Census!$D$5:$D$379,Raw_Census!$A$5:$A$379,$B18&"|"&G$4) -> 561 | H18: =SUMIFS(Raw_Census!$D$5:$D$379,Raw_Census!$A$5:$A$379,$B18&"|"&H$4) -> 447 | I18: =SUM(D18:H18) -> 10779 | J18: =SUMIFS(Raw_Census!$D$5:$D$379,Raw_Census!$A$5:$A$379,$B18&"|0-4")+SUMIFS(Raw_Census!$D$5:$D$379,Raw_Census!$A$5:$A$379,$B18&"|5-9")+SUMIFS(Raw_Census!$D$5:$D$379,Raw_Census!$A$5:$A$379,$B18&"|10-19") -> 83509 | K18: =SUMIFS(Raw_Census!$D$5:$D$379,Raw_Census!$A$5:$A$379,$B18&"|FY") -> 94288 | L18: =SUMIFS(Raw_Census!$F$5:$F$379,Raw_Census!$A$5:$A$379,$B18&"|FY") -> 110473 | M18: =IFERROR(L18/K18,0) -> 1.1716549
A19: C. B2B Professional Services | B19: 5416 | C19: Management, Scientific & Technical Consulting | D19: =SUMIFS(Raw_Census!$D$5:$D$379,Raw_Census!$A$5:$A$379,$B19&"|"&D$4) -> 5789 | E19: =SUMIFS(Raw_Census!$D$5:$D$379,Raw_Census!$A$5:$A$379,$B19&"|"&E$4) -> 2151 | F19: =SUMIFS(Raw_Census!$D$5:$D$379,Raw_Census!$A$5:$A$379,$B19&"|"&F$4) -> 1244 | G19: =SUMIFS(Raw_Census!$D$5:$D$379,Raw_Census!$A$5:$A$379,$B19&"|"&G$4) -> 430 | H19: =SUMIFS(Raw_Census!$D$5:$D$379,Raw_Census!$A$5:$A$379,$B19&"|"&H$4) -> 339 | I19: =SUM(D19:H19) -> 9953 | J19: =SUMIFS(Raw_Census!$D$5:$D$379,Raw_Census!$A$5:$A$379,$B19&"|0-4")+SUMIFS(Raw_Census!$D$5:$D$379,Raw_Census!$A$5:$A$379,$B19&"|5-9")+SUMIFS(Raw_Census!$D$5:$D$379,Raw_Census!$A$5:$A$379,$B19&"|10-19") -> 139134 | K19: =SUMIFS(Raw_Census!$D$5:$D$379,Raw_Census!$A$5:$A$379,$B19&"|FY") -> 149087 | L19: =SUMIFS(Raw_Census!$F$5:$F$379,Raw_Census!$A$5:$A$379,$B19&"|FY") -> 160268 | M19: =IFERROR(L19/K19,0) -> 1.0749965
A20: C. B2B Professional Services | B20: 5418 | C20: Advertising, PR & Related Services | D20: =SUMIFS(Raw_Census!$D$5:$D$379,Raw_Census!$A$5:$A$379,$B20&"|"&D$4) -> 1655 | E20: =SUMIFS(Raw_Census!$D$5:$D$379,Raw_Census!$A$5:$A$379,$B20&"|"&E$4) -> 584 | F20: =SUMIFS(Raw_Census!$D$5:$D$379,Raw_Census!$A$5:$A$379,$B20&"|"&F$4) -> 371 | G20: =SUMIFS(Raw_Census!$D$5:$D$379,Raw_Census!$A$5:$A$379,$B20&"|"&G$4) -> 132 | H20: =SUMIFS(Raw_Census!$D$5:$D$379,Raw_Census!$A$5:$A$379,$B20&"|"&H$4) -> 102 | I20: =SUM(D20:H20) -> 2844 | J20: =SUMIFS(Raw_Census!$D$5:$D$379,Raw_Census!$A$5:$A$379,$B20&"|0-4")+SUMIFS(Raw_Census!$D$5:$D$379,Raw_Census!$A$5:$A$379,$B20&"|5-9")+SUMIFS(Raw_Census!$D$5:$D$379,Raw_Census!$A$5:$A$379,$B20&"|10-19") -> 24892 | K20: =SUMIFS(Raw_Census!$D$5:$D$379,Raw_Census!$A$5:$A$379,$B20&"|FY") -> 27736 | L20: =SUMIFS(Raw_Census!$F$5:$F$379,Raw_Census!$A$5:$A$379,$B20&"|FY") -> 31557 | M20: =IFERROR(L20/K20,0) -> 1.1377632
A21: C. B2B Professional Services — subtotal (before de-dup) | D21: =SUM(D17:D20) -> 19205 | E21: =SUM(E17:E20) -> 7198 | F21: =SUM(F17:F20) -> 4447 | G21: =SUM(G17:G20) -> 1552 | H21: =SUM(H17:H20) -> 1275 | I21: =SUM(I17:I20) -> 33677 | J21: =SUM(J17:J20) -> 318024 | K21: =SUM(K17:K20) -> 351701 | L21: =SUM(L17:L20) -> 404812 | M21: =IFERROR(L21/K21,0) -> 1.1510118
A23: Block 2 — Imputation of Census-suppressed cells (NAICS 4235, firms with 50–499 employees)
A24: 4235 firms operated full year (FY) | D24: =SUMIFS(Raw_Census!$D$5:$D$379,Raw_Census!$A$5:$A$379,"4235|FY") -> 5827
A25: less: reported bands (0–4, 5–9, 10–19, 20–49, 500+) | D25: =SUMIFS(Raw_Census!$D$5:$D$379,Raw_Census!$A$5:$A$379,"4235|0-4")+SUMIFS(Raw_Census!$D$5:$D$379,Raw_Census!$A$5:$A$379,"4235|5-9")+SUMIFS(Raw_Census!$D$5:$D$379,Raw_Census!$A$5:$A$379,"4235|10-19")+SUMIFS(Raw_Census!$D$5:$D$379,Raw_Census!$A$5:$A$379,"4235|20-49")+SUMIFS(Raw_Census!$D$5:$D$379,Raw_Census!$A$5:$A$379,"4235|500+") -> 5352
A26: Suppressed residual (firms with 50–499 employees) [C] | D26: =D24-D25 -> 475 | E26: 50-99 | F26: 100-249 | G26: 250-499
A27: Allocation key: parent NAICS 423 firm mix across 50–99 / 100–249 / 250–499 | E27: =SUMIFS(Raw_Census!$D$5:$D$379,Raw_Census!$A$5:$A$379,"423|50-99")/(SUMIFS(Raw_Census!$D$5:$D$379,Raw_Census!$A$5:$A$379,"423|50-99")+SUMIFS(Raw_Census!$D$5:$D$379,Raw_Census!$A$5:$A$379,"423|100-249")+SUMIFS(Raw_Census!$D$5:$D$379,Raw_Census!$A$5:$A$379,"423|250-499")) -> 0.55296393 | F27: =SUMIFS(Raw_Census!$D$5:$D$379,Raw_Census!$A$5:$A$379,"423|100-249")/(SUMIFS(Raw_Census!$D$5:$D$379,Raw_Census!$A$5:$A$379,"423|50-99")+SUMIFS(Raw_Census!$D$5:$D$379,Raw_Census!$A$5:$A$379,"423|100-249")+SUMIFS(Raw_Census!$D$5:$D$379,Raw_Census!$A$5:$A$379,"423|250-499")) -> 0.33962908 | G27: =SUMIFS(Raw_Census!$D$5:$D$379,Raw_Census!$A$5:$A$379,"423|250-499")/(SUMIFS(Raw_Census!$D$5:$D$379,Raw_Census!$A$5:$A$379,"423|50-99")+SUMIFS(Raw_Census!$D$5:$D$379,Raw_Census!$A$5:$A$379,"423|100-249")+SUMIFS(Raw_Census!$D$5:$D$379,Raw_Census!$A$5:$A$379,"423|250-499")) -> 0.10740699
A28: Imputed 4235 firms by band (feeds yellow cells above) | E28: =$D$26*E27 -> 262.65787 | F28: =$D$26*F27 -> 161.32381 | G28: =$D$26*G27 -> 51.018318
A31: Block 3 — De-duplication: a firm with establishments in several sub-industries is counted in each. Factor = MIN(1, sector firms ÷ Σ reported sub-industry firms), per band.
A32: Parent sector | C32: Measure | D32: 20-49 | E32: 50-99 | F32: 100-249 | G32: 250-499 | H32: 500+
A33: 423 | C33: Sector firms (parent) | D33: =SUMIFS(Raw_Census!$D$5:$D$379,Raw_Census!$A$5:$A$379,$A33&"|"&D$32) -> 13339 | E33: =SUMIFS(Raw_Census!$D$5:$D$379,Raw_Census!$A$5:$A$379,$A33&"|"&E$32) -> 4860 | F33: =SUMIFS(Raw_Census!$D$5:$D$379,Raw_Census!$A$5:$A$379,$A33&"|"&F$32) -> 2985 | G33: =SUMIFS(Raw_Census!$D$5:$D$379,Raw_Census!$A$5:$A$379,$A33&"|"&G$32) -> 944 | H33: =SUMIFS(Raw_Census!$D$5:$D$379,Raw_Census!$A$5:$A$379,$A33&"|"&H$32) -> 802
A34: 423 | C34: Σ reported sub-industry firms | D34: =SUMIFS(Raw_Census!$D$5:$D$379,Raw_Census!$I$5:$I$379,$A34,Raw_Census!$C$5:$C$379,D$32) -> 13706 | E34: =SUMIFS(Raw_Census!$D$5:$D$379,Raw_Census!$I$5:$I$379,$A34,Raw_Census!$C$5:$C$379,E$32) -> 4212 | F34: =SUMIFS(Raw_Census!$D$5:$D$379,Raw_Census!$I$5:$I$379,$A34,Raw_Census!$C$5:$C$379,F$32) -> 2574 | G34: =SUMIFS(Raw_Census!$D$5:$D$379,Raw_Census!$I$5:$I$379,$A34,Raw_Census!$C$5:$C$379,G$32) -> 858 | H34: =SUMIFS(Raw_Census!$D$5:$D$379,Raw_Census!$I$5:$I$379,$A34,Raw_Census!$C$5:$C$379,H$32) -> 798
A35: 423 | C35: Implied overlap | D35: =IFERROR(D34/D33-1,0) -> 0.027513307 | E35: =IFERROR(E34/E33-1,0) -> -0.13333333 | F35: =IFERROR(F34/F33-1,0) -> -0.13768844 | G35: =IFERROR(G34/G33-1,0) -> -0.091101695 | H35: =IFERROR(H34/H33-1,0) -> -0.0049875312
A36: 423 | C36: De-dup factor applied [C] | D36: =IFERROR(MIN(1,D33/D34),1) -> 0.97322341 | E36: =IFERROR(MIN(1,E33/E34),1) -> 1 | F36: =IFERROR(MIN(1,F33/F34),1) -> 1 | G36: =IFERROR(MIN(1,G33/G34),1) -> 1 | H36: =IFERROR(MIN(1,H33/H34),1) -> 1
A38: 31-33 | C38: Sector firms (parent) | D38: =SUMIFS(Raw_Census!$D$5:$D$379,Raw_Census!$A$5:$A$379,$A38&"|"&D$32) -> 32323 | E38: =SUMIFS(Raw_Census!$D$5:$D$379,Raw_Census!$A$5:$A$379,$A38&"|"&E$32) -> 13573 | F38: =SUMIFS(Raw_Census!$D$5:$D$379,Raw_Census!$A$5:$A$379,$A38&"|"&F$32) -> 8859 | G38: =SUMIFS(Raw_Census!$D$5:$D$379,Raw_Census!$A$5:$A$379,$A38&"|"&G$32) -> 3013 | H38: =SUMIFS(Raw_Census!$D$5:$D$379,Raw_Census!$A$5:$A$379,$A38&"|"&H$32) -> 2942
A39: 31-33 | C39: Σ reported sub-industry firms | D39: =SUMIFS(Raw_Census!$D$5:$D$379,Raw_Census!$I$5:$I$379,$A39,Raw_Census!$C$5:$C$379,D$32) -> 33325 | E39: =SUMIFS(Raw_Census!$D$5:$D$379,Raw_Census!$I$5:$I$379,$A39,Raw_Census!$C$5:$C$379,E$32) -> 14501 | F39: =SUMIFS(Raw_Census!$D$5:$D$379,Raw_Census!$I$5:$I$379,$A39,Raw_Census!$C$5:$C$379,F$32) -> 9840 | G39: =SUMIFS(Raw_Census!$D$5:$D$379,Raw_Census!$I$5:$I$379,$A39,Raw_Census!$C$5:$C$379,G$32) -> 3320 | H39: =SUMIFS(Raw_Census!$D$5:$D$379,Raw_Census!$I$5:$I$379,$A39,Raw_Census!$C$5:$C$379,H$32) -> 3224
A40: 31-33 | C40: Implied overlap | D40: =IFERROR(D39/D38-1,0) -> 0.030999598 | E40: =IFERROR(E39/E38-1,0) -> 0.068371031 | F40: =IFERROR(F39/F38-1,0) -> 0.11073485 | G40: =IFERROR(G39/G38-1,0) -> 0.1018918 | H40: =IFERROR(H39/H38-1,0) -> 0.095853161
A41: 31-33 | C41: De-dup factor applied [C] | D41: =IFERROR(MIN(1,D38/D39),1) -> 0.96993248 | E41: =IFERROR(MIN(1,E38/E39),1) -> 0.93600441 | F41: =IFERROR(MIN(1,F38/F39),1) -> 0.90030488 | G41: =IFERROR(MIN(1,G38/G39),1) -> 0.90753012 | H41: =IFERROR(MIN(1,H38/H39),1) -> 0.91253102
A43: 54 | C43: Sector firms (parent) | D43: =SUMIFS(Raw_Census!$D$5:$D$379,Raw_Census!$A$5:$A$379,$A43&"|"&D$32) -> 35049 | E43: =SUMIFS(Raw_Census!$D$5:$D$379,Raw_Census!$A$5:$A$379,$A43&"|"&E$32) -> 11416 | F43: =SUMIFS(Raw_Census!$D$5:$D$379,Raw_Census!$A$5:$A$379,$A43&"|"&F$32) -> 6827 | G43: =SUMIFS(Raw_Census!$D$5:$D$379,Raw_Census!$A$5:$A$379,$A43&"|"&G$32) -> 2304 | H43: =SUMIFS(Raw_Census!$D$5:$D$379,Raw_Census!$A$5:$A$379,$A43&"|"&H$32) -> 2069
A44: 54 | C44: Σ reported sub-industry firms | D44: =SUMIFS(Raw_Census!$D$5:$D$379,Raw_Census!$I$5:$I$379,$A44,Raw_Census!$C$5:$C$379,D$32) -> 35475 | E44: =SUMIFS(Raw_Census!$D$5:$D$379,Raw_Census!$I$5:$I$379,$A44,Raw_Census!$C$5:$C$379,E$32) -> 11662 | F44: =SUMIFS(Raw_Census!$D$5:$D$379,Raw_Census!$I$5:$I$379,$A44,Raw_Census!$C$5:$C$379,F$32) -> 7061 | G44: =SUMIFS(Raw_Census!$D$5:$D$379,Raw_Census!$I$5:$I$379,$A44,Raw_Census!$C$5:$C$379,G$32) -> 2423 | H44: =SUMIFS(Raw_Census!$D$5:$D$379,Raw_Census!$I$5:$I$379,$A44,Raw_Census!$C$5:$C$379,H$32) -> 2129
A45: 54 | C45: Implied overlap | D45: =IFERROR(D44/D43-1,0) -> 0.012154412 | E45: =IFERROR(E44/E43-1,0) -> 0.021548704 | F45: =IFERROR(F44/F43-1,0) -> 0.03427567 | G45: =IFERROR(G44/G43-1,0) -> 0.051649306 | H45: =IFERROR(H44/H43-1,0) -> 0.028999517
A46: 54 | C46: De-dup factor applied [C] | D46: =IFERROR(MIN(1,D43/D44),1) -> 0.98799154 | E46: =IFERROR(MIN(1,E43/E44),1) -> 0.97890585 | F46: =IFERROR(MIN(1,F43/F44),1) -> 0.96686022 | G46: =IFERROR(MIN(1,G43/G44),1) -> 0.95088733 | H46: =IFERROR(MIN(1,H43/H44),1) -> 0.97181775
A48: Reading: overlap is small in distribution (~1–3%) and professional services (~1–5%) but material in mid-size/large manufacturing (~7–11%), where multi-plant firms span subsectors. Where some sub-industry cells are suppressed, the reported sum is a lower bound, so the factor is conservative (removes less overlap than exists).
A50: Block 4 — Unique firms by segment (de-duplicated) [C]
...

Sheet Segment_Profile
A1: Segment profile — structure, sales intensity and 'builder capacity'
A2: Census metrics use the core NAICS codes; OEWS metrics use the closest BLS industry groupings (distribution proxy 4230A1 also includes 4232/4233/4239). Ratios are [C] derived from [A] data.
A4: Metric | B4: A. Industrial Distribution | C4: B. Industrial Manufacturing | D4: C. B2B Professional Services | E4: Ref: Software Publishers (Clay core proxy) | F4: Ref: All industries | G4: Unit / source | H4: What it indicates
A5: Structure (2022 Economic Census, S14)
A6: Unique firms, 20+ employees | B6: =Firm_Counts!D61 -> 11493.544 | C6: =Firm_Counts!E61 -> 23784.588 | D6: =Firm_Counts!F61 -> 33035.014 | E6: =SUMIFS(Raw_Census!$D$5:$D$379,Raw_Census!$A$5:$A$379,"5132|20-49")+SUMIFS(Raw_Census!$D$5:$D$379,Raw_Census!$A$5:$A$379,"5132|50-99")+SUMIFS(Raw_Census!$D$5:$D$379,Raw_Census!$A$5:$A$379,"5132|100-249")+SUMIFS(Raw_Census!$D$5:$D$379,Raw_Census!$A$5:$A$379,"5132|250-499")+SUMIFS(Raw_Census!$D$5:$D$379,Raw_Census!$A$5:$A$379,"5132|500+") -> 3274 | G6: firms [C] | H6: Size of the reachable firm universe (de-duplicated).
A7: Establishments per firm (all FY firms) | B7: =(SUMIFS(Raw_Census!$F$5:$F$379,Raw_Census!$A$5:$A$379,"4235|FY")+SUMIFS(Raw_Census!$F$5:$F$379,Raw_Census!$A$5:$A$379,"4236|FY")+SUMIFS(Raw_Census!$F$5:$F$379,Raw_Census!$A$5:$A$379,"4237|FY")+SUMIFS(Raw_Census!$F$5:$F$379,Raw_Census!$A$5:$A$379,"4238|FY"))/(SUMIFS(Raw_Census!$D$5:$D$379,Raw_Census!$A$5:$A$379,"4235|FY")+SUMIFS(Raw_Census!$D$5:$D$379,Raw_Census!$A$5:$A$379,"4236|FY")+SUMIFS(Raw_Census!$D$5:$D$379,Raw_Census!$A$5:$A$379,"4237|FY")+SUMIFS(Raw_Census!$D$5:$D$379,Raw_Census!$A$5:$A$379,"4238|FY")) -> 1.6637085 | C7: =(SUMIFS(Raw_Census!$F$5:$F$379,Raw_Census!$A$5:$A$379,"326|FY")+SUMIFS(Raw_Census!$F$5:$F$379,Raw_Census!$A$5:$A$379,"332|FY")+SUMIFS(Raw_Census!$F$5:$F$379,Raw_Census!$A$5:$A$379,"333|FY")+SUMIFS(Raw_Census!$F$5:$F$379,Raw_Census!$A$5:$A$379,"335|FY"))/(SUMIFS(Raw_Census!$D$5:$D$379,Raw_Census!$A$5:$A$379,"326|FY")+SUMIFS(Raw_Census!$D$5:$D$379,Raw_Census!$A$5:$A$379,"332|FY")+SUMIFS(Raw_Census!$D$5:$D$379,Raw_Census!$A$5:$A$379,"333|FY")+SUMIFS(Raw_Census!$D$5:$D$379,Raw_Census!$A$5:$A$379,"335|FY")) -> 1.1371146 | D7: =(SUMIFS(Raw_Census!$F$5:$F$379,Raw_Census!$A$5:$A$379,"5413|FY")+SUMIFS(Raw_Census!$F$5:$F$379,Raw_Census!$A$5:$A$379,"5415|FY")+SUMIFS(Raw_Census!$F$5:$F$379,Raw_Census!$A$5:$A$379,"5416|FY")+SUMIFS(Raw_Census!$F$5:$F$379,Raw_Census!$A$5:$A$379,"5418|FY"))/(SUMIFS(Raw_Census!$D$5:$D$379,Raw_Census!$A$5:$A$379,"5413|FY")+SUMIFS(Raw_Census!$D$5:$D$379,Raw_Census!$A$5:$A$379,"5415|FY")+SUMIFS(Raw_Census!$D$5:$D$379,Raw_Census!$A$5:$A$379,"5416|FY")+SUMIFS(Raw_Census!$D$5:$D$379,Raw_Census!$A$5:$A$379,"5418|FY")) -> 1.1510118 | E7: =(SUMIFS(Raw_Census!$F$5:$F$379,Raw_Census!$A$5:$A$379,"5132|FY"))/(SUMIFS(Raw_Census!$D$5:$D$379,Raw_Census!$A$5:$A$379,"5132|FY")) -> 1.3082948 | G7: ratio [C] | H7: Branch intensity. >1.5 means multi-branch networks → territory planning and branch-level account mapping matter.
A8: Avg receipts per firm, 20+ firms ($M) | B8: =(SUMIFS(Raw_Census!$H$5:$H$379,Raw_Census!$A$5:$A$379,"4235|20-49")+SUMIFS(Raw_Census!$H$5:$H$379,Raw_Census!$A$5:$A$379,"4235|50-99")+SUMIFS(Raw_Census!$H$5:$H$379,Raw_Census!$A$5:$A$379,"4235|100-249")+SUMIFS(Raw_Census!$H$5:$H$379,Raw_Census!$A$5:$A$379,"4235|250-499")+SUMIFS(Raw_Census!$H$5:$H$379,Raw_Census!$A$5:$A$379,"4235|500+")+SUMIFS(Raw_Census!$H$5:$H$379,Raw_Census!$A$5:$A$379,"4236|20-49")+SUMIFS(Raw_Census!$H$5:$H$379,Raw_Census!$A$5:$A$379,"4236|50-99")+SUMIFS(Raw_Census!$H$5:$H$379,Raw_Census!$A$5:$A$379,"4236|100-249")+SUMIFS(Raw_Census!$H$5:$H$379,Raw_Census!$A$5:$A$379,"4236|250-499")+SUMIFS(Raw_Census!$H$5:$H$379,Raw_Census!$A$5:$A$379,"4236|500+")+SUMIFS(Raw_Census!$H$5:$H$379,Raw_Census!$A$5:$A$379,"4237|20-49")+SUMIFS(Raw_Census!$H$5:$H$379,Raw_Census!$A$5:$A$379,"4237|50-99")+SUMIFS(Raw_Census!$H$5:$H$379,Raw_Census!$A$5:$A$379,"4237|100-249")+SUMIFS(Raw_Census!$H$5:$H$379,Raw_Census!$A$5:$A$379,"4237|250-499")+SUMIFS(Raw_Census!$H$5:$H$379,Raw_Census!$A$5:$A$379,"4237|500+")+SUMIFS(Raw_Census!$H$5:$H$379,Raw_Census!$A$5:$A$379,"4238|20-49")+SUMIFS(Raw_Census!$H$5:$H$379,Raw_Census!$A$5:$A$379,"4238|50-99")+SUMIFS(Raw_Census!$H$5:$H$379,Raw_Census!$A$5:$A$379,"4238|100-249")+SUMIFS(Raw_Census!$H$5:$H$379,Raw_Census!$A$5:$A$379,"4238|250-499")+SUMIFS(Raw_Census!$H$5:$H$379,Raw_Census!$A$5:$A$379,"4238|500+"))/(IF(SUMIFS(Raw_Census!$H$5:$H$379,Raw_Census!$A$5:$A$379,"4235|20-49")>0,SUMIFS(Raw_Census!$D$5:$D$379,Raw_Census!$A$5:$A$379,"4235|20-49"),0)+IF(SUMIFS(Raw_Census!$H$5:$H$379,Raw_Census!$A$5:$A$379,"4235|50-99")>0,SUMIFS(Raw_Census!$D$5:$D$379,Raw_Census!$A$5:$A$379,"4235|50-99"),0)+IF(SUMIFS(Raw_Census!$H$5:$H$379,Raw_Census!$A$5:$A$379,"4235|100-249")>0,SUMIFS(Raw_Census!$D$5:$D$379,Raw_Census!$A$5:$A$379,"4235|100-249"),0)+IF(SUMIFS(Raw_Census!$H$5:$H$379,Raw_Census!$A$5:$A$379,"4235|250-499")>0,SUMIFS(Raw_Census!$D$5:$D$379,Raw_Census!$A$5:$A$379,"4235|250-499"),0)+IF(SUMIFS(Raw_Census!$H$5:$H$379,Raw_Census!$A$5:$A$379,"4235|500+")>0,SUMIFS(Raw_Census!$D$5:$D$379,Raw_Census!$A$5:$A$379,"4235|500+"),0)+IF(SUMIFS(Raw_Census!$H$5:$H$379,Raw_Census!$A$5:$A$379,"4236|20-49")>0,SUMIFS(Raw_Census!$D$5:$D$379,Raw_Census!$A$5:$A$379,"4236|20-49"),0)+IF(SUMIFS(Raw_Census!$H$5:$H$379,Raw_Census!$A$5:$A$379,"4236|50-99")>0,SUMIFS(Raw_Census!$D$5:$D$379,Raw_Census!$A$5:$A$379,"4236|50-99"),0)+IF(SUMIFS(Raw_Census!$H$5:$H$379,Raw_Census!$A$5:$A$379,"4236|100-249")>0,SUMIFS(Raw_Census!$D$5:$D$379,Raw_Census!$A$5:$A$379,"4236|100-249"),0)+IF(SUMIFS(Raw_Census!$H$5:$H$379,Raw_Census!$A$5:$A$379,"4236|250-499")>0,SUMIFS(Raw_Census!$D$5:$D$379,Raw_Census!$A$5:$A$379,"4236|250-499"),0)+IF(SUMIFS(Raw_Census!$H$5:$H$379,Raw_Census!$A$5:$A$379,"4236|500+")>0,SUMIFS(Raw_Census!$D$5:$D$379,Raw_Census!$A$5:$A$379,"4236|500+"),0)+IF(SUMIFS(Raw_Census!$H$5:$H$379,Raw_Census!$A$5:$A$379,"4237|20-49")>0,SUMIFS(Raw_Census!$D$5:$D$379,Raw_Census!$A$5:$A$379,"4237|20-49"),0)+IF(SUMIFS(Raw_Census!$H$5:$H$379,Raw_Census!$A$5:$A$379,"4237|50-99")>0,SUMIFS(Raw_Census!$D$5:$D$379,Raw_Census!$A$5:$A$379,"4237|50-99"),0)+IF(SUMIFS(Raw_Census!$H$5:$H$379,Raw_Census!$A$5:$A$379,"4237|100-249")>0,SUMIFS(Raw_Census!$D$5:$D$379,Raw_Census!$A$5:$A$379,"4237|100-249"),0)+IF(SUMIFS(Raw_Census!$H$5:$H$379,Raw_Census!$A$5:$A$379,"4237|250-499")>0,SUMIFS(Raw_Census!$D$5:$D$379,Raw_Census!$A$5:$A$379,"4237|250-499"),0)+IF(SUMIFS(Raw_Census!$H$5:$H$379,Raw_Census!$A$5:$A$379,"4237|500+")>0,SUMIFS(Raw_Census!$D$5:$D$379,Raw_Census!$A$5:$A$379,"4237|500+"),0)+IF(SUMIFS(Raw_Census!$H$5:$H$379,Raw_Census!$A$5:$A$379,"4238|20-49")>0,SUMIFS(Raw_Census!$D$5:$D$379,Raw_Census!$A$5:$A$379,"4238|20-49"),0)+IF(SUMIFS(Raw_Census!$H$5:$H$379,Raw_Census!$A$5:$A$379,"4238|50-99")>0,SUMIFS(Raw_Census!$D$5:$D$379,Raw_Census!$A$5:$A$379,"4238|50-99"),0)+IF(SUMIFS(Raw_Census!$H$5:$H$379,Raw_Census!$A$5:$A$379,"4238|100-249")>0,SUMIFS(Raw_Census!$D$5:$D$379,Raw_Census!$A$5:$A$379,"4238|100-249"),0)+IF(SUMIFS(Raw_Census!$H$5:$H$379,Raw_Census!$A$5:$A$379,"4238|250-499")>0,SUMIFS(Raw_Census!$D$5:$D$379,Raw_Census!$A$5:$A$379,"4238|250-499"),0)+IF(SUMIFS(Raw_Census!$H$5:$H$379,Raw_Census!$A$5:$A$379,"4238|500+")>0,SUMIFS(Raw_Census!$D$5:$D$379,Raw_Census!$A$5:$A$379,"4238|500+"),0))/1000 -> 166.04619 | C8: =(SUMIFS(Raw_Census!$H$5:$H$379,Raw_Census!$A$5:$A$379,"326|20-49")+SUMIFS(Raw_Census!$H$5:$H$379,Raw_Census!$A$5:$A$379,"326|50-99")+SUMIFS(Raw_Census!$H$5:$H$379,Raw_Census!$A$5:$A$379,"326|100-249")+SUMIFS(Raw_Census!$H$5:$H$379,Raw_Census!$A$5:$A$379,"326|250-499")+SUMIFS(Raw_Census!$H$5:$H$379,Raw_Census!$A$5:$A$379,"326|500+")+SUMIFS(Raw_Census!$H$5:$H$379,Raw_Census!$A$5:$A$379,"332|20-49")+SUMIFS(Raw_Census!$H$5:$H$379,Raw_Census!$A$5:$A$379,"332|50-99")+SUMIFS(Raw_Census!$H$5:$H$379,Raw_Census!$A$5:$A$379,"332|100-249")+SUMIFS(Raw_Census!$H$5:$H$379,Raw_Census!$A$5:$A$379,"332|250-499")+SUMIFS(Raw_Census!$H$5:$H$379,Raw_Census!$A$5:$A$379,"332|500+")+SUMIFS(Raw_Census!$H$5:$H$379,Raw_Census!$A$5:$A$379,"333|20-49")+SUMIFS(Raw_Census!$H$5:$H$379,Raw_Census!$A$5:$A$379,"333|50-99")+SUMIFS(Raw_Census!$H$5:$H$379,Raw_Census!$A$5:$A$379,"333|100-249")+SUMIFS(Raw_Census!$H$5:$H$379,Raw_Census!$A$5:$A$379,"333|250-499")+SUMIFS(Raw_Census!$H$5:$H$379,Raw_Census!$A$5:$A$379,"333|500+")+SUMIFS(Raw_Census!$H$5:$H$379,Raw_Census!$A$5:$A$379,"335|20-49")+SUMIFS(Raw_Census!$H$5:$H$379,Raw_Census!$A$5:$A$379,"335|50-99")+SUMIFS(Raw_Census!$H$5:$H$379,Raw_Census!$A$5:$A$379,"335|100-249")+SUMIFS(Raw_Census!$H$5:$H$379,Raw_Census!$A$5:$A$379,"335|250-499")+SUMIFS(Raw_Census!$H$5:$H$379,Raw_Census!$A$5:$A$379,"335|500+"))/(IF(SUMIFS(Raw_Census!$H$5:$H$379,Raw_Census!$A$5:$A$379,"326|20-49")>0,SUMIFS(Raw_Census!$D$5:$D$379,Raw_Census!$A$5:$A$379,"326|20-49"),0)+IF(SUMIFS(Raw_Census!$H$5:$H$379,Raw_Census!$A$5:$A$379,"326|50-99")>0,SUMIFS(Raw_Census!$D$5:$D$379,Raw_Census!$A$5:$A$379,"326|50-99"),0)+IF(SUMIFS(Raw_Census!$H$5:$H$379,Raw_Census!$A$5:$A$379,"326|100-249")>0,SUMIFS(Raw_Census!$D$5:$D$379,Raw_Census!$A$5:$A$379,"326|100-249"),0)+IF(SUMIFS(Raw_Census!$H$5:$H$379,Raw_Census!$A$5:$A$379,"326|250-499")>0,SUMIFS(Raw_Census!$D$5:$D$379,Raw_Census!$A$5:$A$379,"326|250-499"),0)+IF(SUMIFS(Raw_Census!$H$5:$H$379,Raw_Census!$A$5:$A$379,"326|500+")>0,SUMIFS(Raw_Census!$D$5:$D$379,Raw_Census!$A$5:$A$379,"326|500+"),0)+IF(SUMIFS(Raw_Census!$H$5:$H$379,Raw_Census!$A$5:$A$379,"332|20-49")>0,SUMIFS(Raw_Census!$D$5:$D$379,Raw_Census!$A$5:$A$379,"332|20-49"),0)+IF(SUMIFS(Raw_Census!$H$5:$H$379,Raw_Census!$A$5:$A$379,"332|50-99")>0,SUMIFS(Raw_Census!$D$5:$D$379,Raw_Census!$A$5:$A$379,"332|50-99"),0)+IF(SUMIFS(Raw_Census!$H$5:$H$379,Raw_Census!$A$5:$A$379,"332|100-249")>0,SUMIFS(Raw_Census!$D$5:$D$379,Raw_Census!$A$5:$A$379,"332|100-249"),0)+IF(SUMIFS(Raw_Census!$H$5:$H$379,Raw_Census!$A$5:$A$379,"332|250-499")>0,SUMIFS(Raw_Census!$D$5:$D$379,Raw_Census!$A$5:$A$379,"332|250-499"),0)+IF(SUMIFS(Raw_Census!$H$5:$H$379,Raw_Census!$A$5:$A$379,"332|500+")>0,SUMIFS(Raw_Census!$D$5:$D$379,Raw_Census!$A$5:$A$379,"332|500+"),0)+IF(SUMIFS(Raw_Census!$H$5:$H$379,Raw_Census!$A$5:$A$379,"333|20-49")>0,SUMIFS(Raw_Census!$D$5:$D$379,Raw_Census!$A$5:$A$379,"333|20-49"),0)+IF(SUMIFS(Raw_Census!$H$5:$H$379,Raw_Census!$A$5:$A$379,"333|50-99")>0,SUMIFS(Raw_Census!$D$5:$D$379,Raw_Census!$A$5:$A$379,"333|50-99"),0)+IF(SUMIFS(Raw_Census!$H$5:$H$379,Raw_Census!$A$5:$A$379,"333|100-249")>0,SUMIFS(Raw_Census!$D$5:$D$379,Raw_Census!$A$5:$A$379,"333|100-249"),0)+IF(SUMIFS(Raw_Census!$H$5:$H$379,Raw_Census!$A$5:$A$379,"333|250-499")>0,SUMIFS(Raw_Census!$D$5:$D$379,Raw_Census!$A$5:$A$379,"333|250-499"),0)+IF(SUMIFS(Raw_Census!$H$5:$H$379,Raw_Census!$A$5:$A$379,"333|500+")>0,SUMIFS(Raw_Census!$D$5:$D$379,Raw_Census!$A$5:$A$379,"333|500+"),0)+IF(SUMIFS(Raw_Census!$H$5:$H$379,Raw_Census!$A$5:$A$379,"335|20-49")>0,SUMIFS(Raw_Census!$D$5:$D$379,Raw_Census!$A$5:$A$379,"335|20-49"),0)+IF(SUMIFS(Raw_Census!$H$5:$H$379,Raw_Census!$A$5:$A$379,"335|50-99")>0,SUMIFS(Raw_Census!$D$5:$D$379,Raw_Census!$A$5:$A$379,"335|50-99"),0)+IF(SUMIFS(Raw_Census!$H$5:$H$379,Raw_Census!$A$5:$A$379,"335|100-249")>0,SUMIFS(Raw_Census!$D$5:$D$379,Raw_Census!$A$5:$A$379,"335|100-249"),0)+IF(SUMIFS(Raw_Census!$H$5:$H$379,Raw_Census!$A$5:$A$379,"335|250-499")>0,SUMIFS(Raw_Census!$D$5:$D$379,Raw_Census!$A$5:$A$379,"335|250-499"),0)+IF(SUMIFS(Raw_Census!$H$5:$H$379,Raw_Census!$A$5:$A$379,"335|500+")>0,SUMIFS(Raw_Census!$D$5:$D$379,Raw_Census!$A$5:$A$379,"335|500+"),0))/1000 -> 51.937391 | D8: =(SUMIFS(Raw_Census!$H$5:$H$379,Raw_Census!$A$5:$A$379,"5413|20-49")+SUMIFS(Raw_Census!$H$5:$H$379,Raw_Census!$A$5:$A$379,"5413|50-99")+SUMIFS(Raw_Census!$H$5:$H$379,Raw_Census!$A$5:$A$379,"5413|100-249")+SUMIFS(Raw_Census!$H$5:$H$379,Raw_Census!$A$5:$A$379,"5413|250-499")+SUMIFS(Raw_Census!$H$5:$H$379,Raw_Census!$A$5:$A$379,"5413|500+")+SUMIFS(Raw_Census!$H$5:$H$379,Raw_Census!$A$5:$A$379,"5415|20-49")+SUMIFS(Raw_Census!$H$5:$H$379,Raw_Census!$A$5:$A$379,"5415|50-99")+SUMIFS(Raw_Census!$H$5:$H$379,Raw_Census!$A$5:$A$379,"5415|100-249")+SUMIFS(Raw_Census!$H$5:$H$379,Raw_Census!$A$5:$A$379,"5415|250-499")+SUMIFS(Raw_Census!$H$5:$H$379,Raw_Census!$A$5:$A$379,"5415|500+")+SUMIFS(Raw_Census!$H$5:$H$379,Raw_Census!$A$5:$A$379,"5416|20-49")+SUMIFS(Raw_Census!$H$5:$H$379,Raw_Census!$A$5:$A$379,"5416|50-99")+SUMIFS(Raw_Census!$H$5:$H$379,Raw_Census!$A$5:$A$379,"5416|100-249")+SUMIFS(Raw_Census!$H$5:$H$379,Raw_Census!$A$5:$A$379,"5416|250-499")+SUMIFS(Raw_Census!$H$5:$H$379,Raw_Census!$A$5:$A$379,"5416|500+")+SUMIFS(Raw_Census!$H$5:$H$379,Raw_Census!$A$5:$A$379,"5418|20-49")+SUMIFS(Raw_Census!$H$5:$H$379,Raw_Census!$A$5:$A$379,"5418|50-99")+SUMIFS(Raw_Census!$H$5:$H$379,Raw_Census!$A$5:$A$379,"5418|100-249")+SUMIFS(Raw_Census!$H$5:$H$379,Raw_Census!$A$5:$A$379,"5418|250-499")+SUMIFS(Raw_Census!$H$5:$H$379,Raw_Census!$A$5:$A$379,"5418|500+"))/(IF(SUMIFS(Raw_Census!$H$5:$H$379,Raw_Census!$A$5:$A$379,"5413|20-49")>0,SUMIFS(Raw_Census!$D$5:$D$379,Raw_Census!$A$5:$A$379,"5413|20-49"),0)+IF(SUMIFS(Raw_Census!$H$5:$H$379,Raw_Census!$A$5:$A$379,"5413|50-99")>0,SUMIFS(Raw_Census!$D$5:$D$379,Raw_Census!$A$5:$A$379,"5413|50-99"),0)+IF(SUMIFS(Raw_Census!$H$5:$H$379,Raw_Census!$A$5:$A$379,"5413|100-249")>0,SUMIFS(Raw_Census!$D$5:$D$379,Raw_Census!$A$5:$A$379,"5413|100-249"),0)+IF(SUMIFS(Raw_Census!$H$5:$H$379,Raw_Census!$A$5:$A$379,"5413|250-499")>0,SUMIFS(Raw_Census!$D$5:$D$379,Raw_Census!$A$5:$A$379,"5413|250-499"),0)+IF(SUMIFS(Raw_Census!$H$5:$H$379,Raw_Census!$A$5:$A$379,"5413|500+")>0,SUMIFS(Raw_Census!$D$5:$D$379,Raw_Census!$A$5:$A$379,"5413|500+"),0)+IF(SUMIFS(Raw_Census!$H$5:$H$379,Raw_Census!$A$5:$A$379,"5415|20-49")>0,SUMIFS(Raw_Census!$D$5:$D$379,Raw_Census!$A$5:$A$379,"5415|20-49"),0)+IF(SUMIFS(Raw_Census!$H$5:$H$379,Raw_Census!$A$5:$A$379,"5415|50-99")>0,SUMIFS(Raw_Census!$D$5:$D$379,Raw_Census!$A$5:$A$379,"5415|50-99"),0)+IF(SUMIFS(Raw_Census!$H$5:$H$379,Raw_Census!$A$5:$A$379,"5415|100-249")>0,SUMIFS(Raw_Census!$D$5:$D$379,Raw_Census!$A$5:$A$379,"5415|100-249"),0)+IF(SUMIFS(Raw_Census!$H$5:$H$379,Raw_Census!$A$5:$A$379,"5415|250-499")>0,SUMIFS(Raw_Census!$D$5:$D$379,Raw_Census!$A$5:$A$379,"5415|250-499"),0)+IF(SUMIFS(Raw_Census!$H$5:$H$379,Raw_Census!$A$5:$A$379,"5415|500+")>0,SUMIFS(Raw_Census!$D$5:$D$379,Raw_Census!$A$5:$A$379,"5415|500+"),0)+IF(SUMIFS(Raw_Census!$H$5:$H$379,Raw_Census!$A$5:$A$379,"5416|20-49")>0,SUMIFS(Raw_Census!$D$5:$D$379,Raw_Census!$A$5:$A$379,"5416|20-49"),0)+IF(SUMIFS(Raw_Census!$H$5:$H$379,Raw_Census!$A$5:$A$379,"5416|50-99")>0,SUMIFS(Raw_Census!$D$5:$D$379,Raw_Census!$A$5:$A$379,"5416|50-99"),0)+IF(SUMIFS(Raw_Census!$H$5:$H$379,Raw_Census!$A$5:$A$379,"5416|100-249")>0,SUMIFS(Raw_Census!$D$5:$D$379,Raw_Census!$A$5:$A$379,"5416|100-249"),0)+IF(SUMIFS(Raw_Census!$H$5:$H$379,Raw_Census!$A$5:$A$379,"5416|250-499")>0,SUMIFS(Raw_Census!$D$5:$D$379,Raw_Census!$A$5:$A$379,"5416|250-499"),0)+IF(SUMIFS(Raw_Census!$H$5:$H$379,Raw_Census!$A$5:$A$379,"5416|500+")>0,SUMIFS(Raw_Census!$D$5:$D$379,Raw_Census!$A$5:$A$379,"5416|500+"),0)+IF(SUMIFS(Raw_Census!$H$5:$H$379,Raw_Census!$A$5:$A$379,"5418|20-49")>0,SUMIFS(Raw_Census!$D$5:$D$379,Raw_Census!$A$5:$A$379,"5418|20-49"),0)+IF(SUMIFS(Raw_Census!$H$5:$H$379,Raw_Census!$A$5:$A$379,"5418|50-99")>0,SUMIFS(Raw_Census!$D$5:$D$379,Raw_Census!$A$5:$A$379,"5418|50-99"),0)+IF(SUMIFS(Raw_Census!$H$5:$H$379,Raw_Census!$A$5:$A$379,"5418|100-249")>0,SUMIFS(Raw_Census!$D$5:$D$379,Raw_Census!$A$5:$A$379,"5418|100-249"),0)+IF(SUMIFS(Raw_Census!$H$5:$H$379,Raw_Census!$A$5:$A$379,"5418|250-499")>0,SUMIFS(Raw_Census!$D$5:$D$379,Raw_Census!$A$5:$A$379,"5418|250-499"),0)+IF(SUMIFS(Raw_Census!$H$5:$H$379,Raw_Census!$A$5:$A$379,"5418|500+")>0,SUMIFS(Raw_Census!$D$5:$D$379,Raw_Census!$A$5:$A$379,"5418|500+"),0))/1000 -> 38.089748 | E8: =(SUMIFS(Raw_Census!$H$5:$H$379,Raw_Census!$A$5:$A$379,"5132|20-49")+SUMIFS(Raw_Census!$H$5:$H$379,Raw_Census!$A$5:$A$379,"5132|50-99")+SUMIFS(Raw_Census!$H$5:$H$379,Raw_Census!$A$5:$A$379,"5132|100-249")+SUMIFS(Raw_Census!$H$5:$H$379,Raw_Census!$A$5:$A$379,"5132|250-499")+SUMIFS(Raw_Census!$H$5:$H$379,Raw_Census!$A$5:$A$379,"5132|500+"))/(IF(SUMIFS(Raw_Census!$H$5:$H$379,Raw_Census!$A$5:$A$379,"5132|20-49")>0,SUMIFS(Raw_Census!$D$5:$D$379,Raw_Census!$A$5:$A$379,"5132|20-49"),0)+IF(SUMIFS(Raw_Census!$H$5:$H$379,Raw_Census!$A$5:$A$379,"5132|50-99")>0,SUMIFS(Raw_Census!$D$5:$D$379,Raw_Census!$A$5:$A$379,"5132|50-99"),0)+IF(SUMIFS(Raw_Census!$H$5:$H$379,Raw_Census!$A$5:$A$379,"5132|100-249")>0,SUMIFS(Raw_Census!$D$5:$D$379,Raw_Census!$A$5:$A$379,"5132|100-249"),0)+IF(SUMIFS(Raw_Census!$H$5:$H$379,Raw_Census!$A$5:$A$379,"5132|250-499")>0,SUMIFS(Raw_Census!$D$5:$D$379,Raw_Census!$A$5:$A$379,"5132|250-499"),0)+IF(SUMIFS(Raw_Census!$H$5:$H$379,Raw_Census!$A$5:$A$379,"5132|500+")>0,SUMIFS(Raw_Census!$D$5:$D$379,Raw_Census!$A$5:$A$379,"5132|500+"),0))/1000 -> 144.17364 | G8: $M per firm [C] | H8: Ability to pay. Denominator excludes cells whose receipts are suppressed.
A9: Avg receipts per firm, 20–99 employees ($M) | B9: =(SUMIFS(Raw_Census!$H$5:$H$379,Raw_Census!$A$5:$A$379,"4235|20-49")+SUMIFS(Raw_Census!$H$5:$H$379,Raw_Census!$A$5:$A$379,"4235|50-99")+SUMIFS(Raw_Census!$H$5:$H$379,Raw_Census!$A$5:$A$379,"4236|20-49")+SUMIFS(Raw_Census!$H$5:$H$379,Raw_Census!$A$5:$A$379,"4236|50-99")+SUMIFS(Raw_Census!$H$5:$H$379,Raw_Census!$A$5:$A$379,"4237|20-49")+SUMIFS(Raw_Census!$H$5:$H$379,Raw_Census!$A$5:$A$379,"4237|50-99")+SUMIFS(Raw_Census!$H$5:$H$379,Raw_Census!$A$5:$A$379,"4238|20-49")+SUMIFS(Raw_Census!$H$5:$H$379,Raw_Census!$A$5:$A$379,"4238|50-99"))/(IF(SUMIFS(Raw_Census!$H$5:$H$379,Raw_Census!$A$5:$A$379,"4235|20-49")>0,SUMIFS(Raw_Census!$D$5:$D$379,Raw_Census!$A$5:$A$379,"4235|20-49"),0)+IF(SUMIFS(Raw_Census!$H$5:$H$379,Raw_Census!$A$5:$A$379,"4235|50-99")>0,SUMIFS(Raw_Census!$D$5:$D$379,Raw_Census!$A$5:$A$379,"4235|50-99"),0)+IF(SUMIFS(Raw_Census!$H$5:$H$379,Raw_Census!$A$5:$A$379,"4236|20-49")>0,SUMIFS(Raw_Census!$D$5:$D$379,Raw_Census!$A$5:$A$379,"4236|20-49"),0)+IF(SUMIFS(Raw_Census!$H$5:$H$379,Raw_Census!$A$5:$A$379,"4236|50-99")>0,SUMIFS(Raw_Census!$D$5:$D$379,Raw_Census!$A$5:$A$379,"4236|50-99"),0)+IF(SUMIFS(Raw_Census!$H$5:$H$379,Raw_Census!$A$5:$A$379,"4237|20-49")>0,SUMIFS(Raw_Census!$D$5:$D$379,Raw_Census!$A$5:$A$379,"4237|20-49"),0)+IF(SUMIFS(Raw_Census!$H$5:$H$379,Raw_Census!$A$5:$A$379,"4237|50-99")>0,SUMIFS(Raw_Census!$D$5:$D$379,Raw_Census!$A$5:$A$379,"4237|50-99"),0)+IF(SUMIFS(Raw_Census!$H$5:$H$379,Raw_Census!$A$5:$A$379,"4238|20-49")>0,SUMIFS(Raw_Census!$D$5:$D$379,Raw_Census!$A$5:$A$379,"4238|20-49"),0)+IF(SUMIFS(Raw_Census!$H$5:$H$379,Raw_Census!$A$5:$A$379,"4238|50-99")>0,SUMIFS(Raw_Census!$D$5:$D$379,Raw_Census!$A$5:$A$379,"4238|50-99"),0))/1000 -> 40.572669 | C9: =(SUMIFS(Raw_Census!$H$5:$H$379,Raw_Census!$A$5:$A$379,"326|20-49")+SUMIFS(Raw_Census!$H$5:$H$379,Raw_Census!$A$5:$A$379,"326|50-99")+SUMIFS(Raw_Census!$H$5:$H$379,Raw_Census!$A$5:$A$379,"332|20-49")+SUMIFS(Raw_Census!$H$5:$H$379,Raw_Census!$A$5:$A$379,"332|50-99")+SUMIFS(Raw_Census!$H$5:$H$379,Raw_Census!$A$5:$A$379,"333|20-49")+SUMIFS(Raw_Census!$H$5:$H$379,Raw_Census!$A$5:$A$379,"333|50-99")+SUMIFS(Raw_Census!$H$5:$H$379,Raw_Census!$A$5:$A$379,"335|20-49")+SUMIFS(Raw_Census!$H$5:$H$379,Raw_Census!$A$5:$A$379,"335|50-99"))/(IF(SUMIFS(Raw_Census!$H$5:$H$379,Raw_Census!$A$5:$A$379,"326|20-49")>0,SUMIFS(Raw_Census!$D$5:$D$379,Raw_Census!$A$5:$A$379,"326|20-49"),0)+IF(SUMIFS(Raw_Census!$H$5:$H$379,Raw_Census!$A$5:$A$379,"326|50-99")>0,SUMIFS(Raw_Census!$D$5:$D$379,Raw_Census!$A$5:$A$379,"326|50-99"),0)+IF(SUMIFS(Raw_Census!$H$5:$H$379,Raw_Census!$A$5:$A$379,"332|20-49")>0,SUMIFS(Raw_Census!$D$5:$D$379,Raw_Census!$A$5:$A$379,"332|20-49"),0)+IF(SUMIFS(Raw_Census!$H$5:$H$379,Raw_Census!$A$5:$A$379,"332|50-99")>0,SUMIFS(Raw_Census!$D$5:$D$379,Raw_Census!$A$5:$A$379,"332|50-99"),0)+IF(SUMIFS(Raw_Census!$H$5:$H$379,Raw_Census!$A$5:$A$379,"333|20-49")>0,SUMIFS(Raw_Census!$D$5:$D$379,Raw_Census!$A$5:$A$379,"333|20-49"),0)+IF(SUMIFS(Raw_Census!$H$5:$H$379,Raw_Census!$A$5:$A$379,"333|50-99")>0,SUMIFS(Raw_Census!$D$5:$D$379,Raw_Census!$A$5:$A$379,"333|50-99"),0)+IF(SUMIFS(Raw_Census!$H$5:$H$379,Raw_Census!$A$5:$A$379,"335|20-49")>0,SUMIFS(Raw_Census!$D$5:$D$379,Raw_Census!$A$5:$A$379,"335|20-49"),0)+IF(SUMIFS(Raw_Census!$H$5:$H$379,Raw_Census!$A$5:$A$379,"335|50-99")>0,SUMIFS(Raw_Census!$D$5:$D$379,Raw_Census!$A$5:$A$379,"335|50-99"),0))/1000 -> 11.748174 | D9: =(SUMIFS(Raw_Census!$H$5:$H$379,Raw_Census!$A$5:$A$379,"5413|20-49")+SUMIFS(Raw_Census!$H$5:$H$379,Raw_Census!$A$5:$A$379,"5413|50-99")+SUMIFS(Raw_Census!$H$5:$H$379,Raw_Census!$A$5:$A$379,"5415|20-49")+SUMIFS(Raw_Census!$H$5:$H$379,Raw_Census!$A$5:$A$379,"5415|50-99")+SUMIFS(Raw_Census!$H$5:$H$379,Raw_Census!$A$5:$A$379,"5416|20-49")+SUMIFS(Raw_Census!$H$5:$H$379,Raw_Census!$A$5:$A$379,"5416|50-99")+SUMIFS(Raw_Census!$H$5:$H$379,Raw_Census!$A$5:$A$379,"5418|20-49")+SUMIFS(Raw_Census!$H$5:$H$379,Raw_Census!$A$5:$A$379,"5418|50-99"))/(IF(SUMIFS(Raw_Census!$H$5:$H$379,Raw_Census!$A$5:$A$379,"5413|20-49")>0,SUMIFS(Raw_Census!$D$5:$D$379,Raw_Census!$A$5:$A$379,"5413|20-49"),0)+IF(SUMIFS(Raw_Census!$H$5:$H$379,Raw_Census!$A$5:$A$379,"5413|50-99")>0,SUMIFS(Raw_Census!$D$5:$D$379,Raw_Census!$A$5:$A$379,"5413|50-99"),0)+IF(SUMIFS(Raw_Census!$H$5:$H$379,Raw_Census!$A$5:$A$379,"5415|20-49")>0,SUMIFS(Raw_Census!$D$5:$D$379,Raw_Census!$A$5:$A$379,"5415|20-49"),0)+IF(SUMIFS(Raw_Census!$H$5:$H$379,Raw_Census!$A$5:$A$379,"5415|50-99")>0,SUMIFS(Raw_Census!$D$5:$D$379,Raw_Census!$A$5:$A$379,"5415|50-99"),0)+IF(SUMIFS(Raw_Census!$H$5:$H$379,Raw_Census!$A$5:$A$379,"5416|20-49")>0,SUMIFS(Raw_Census!$D$5:$D$379,Raw_Census!$A$5:$A$379,"5416|20-49"),0)+IF(SUMIFS(Raw_Census!$H$5:$H$379,Raw_Census!$A$5:$A$379,"5416|50-99")>0,SUMIFS(Raw_Census!$D$5:$D$379,Raw_Census!$A$5:$A$379,"5416|50-99"),0)+IF(SUMIFS(Raw_Census!$H$5:$H$379,Raw_Census!$A$5:$A$379,"5418|20-49")>0,SUMIFS(Raw_Census!$D$5:$D$379,Raw_Census!$A$5:$A$379,"5418|20-49"),0)+IF(SUMIFS(Raw_Census!$H$5:$H$379,Raw_Census!$A$5:$A$379,"5418|50-99")>0,SUMIFS(Raw_Census!$D$5:$D$379,Raw_Census!$A$5:$A$379,"5418|50-99"),0))/1000 -> 10.091837 | E9: =(SUMIFS(Raw_Census!$H$5:$H$379,Raw_Census!$A$5:$A$379,"5132|20-49")+SUMIFS(Raw_Census!$H$5:$H$379,Raw_Census!$A$5:$A$379,"5132|50-99"))/(IF(SUMIFS(Raw_Census!$H$5:$H$379,Raw_Census!$A$5:$A$379,"5132|20-49")>0,SUMIFS(Raw_Census!$D$5:$D$379,Raw_Census!$A$5:$A$379,"5132|20-49"),0)+IF(SUMIFS(Raw_Census!$H$5:$H$379,Raw_Census!$A$5:$A$379,"5132|50-99")>0,SUMIFS(Raw_Census!$D$5:$D$379,Raw_Census!$A$5:$A$379,"5132|50-99"),0))/1000 -> 13.638612 | G9: $M per firm [C] | H9: Same metric for the SMB band only — removes the skew from very large firms.
