Workbook

Sheet Cover
A1: 06 — Segment Prioritization: Which vertical deserves Clay's next GTM dollar?
A2: Independent portfolio case study by Zhuoran (Zora) Wang · Not commissioned by or affiliated with Clay Labs Inc. · Research reference date: 2026-10-18
A4: Decision | B4: Rank three candidate U.S. verticals for incremental go-to-market investment and choose how to enter: no vertical bet, full vertical build, or staged pilot.
A5: Framework | B5: Six criteria with the suggested weights (Market Attractiveness 20%, Customer Need 20%, Product-Market Fit 20%, Revenue Potential 15%, Competitive Position 15%, Ease of Execution 10%). The weights are analytical assumptions, not management preferences.
A6: Scoring rule | B6: Quantitative metrics → 1–5 by ratio-to-max: score = 1 + 4 × value ÷ max(value across segments). This preserves proportional gaps; a min-max alternative is tested on Stress_Tests. Judgment scores (PMF, and Competitive Position / Ease from Phase 2) carry written evidence.
A7: Inputs | B7: Copied from 02_Market_Sizing.xlsx and 04_Competitive_Analysis.xlsx (cell references noted) so this file recalculates on its own. Blue = input · black = formula · yellow = judgment score or assumption.
A8: Robustness | B8: Five alternative weight sets; break-even weight per criterion; 2 × 1,000 random weight vectors (seeded, stored as values); 11 input stress tests; scoring-rule test.
A9: Not a forecast | B9: Scores rank options under stated assumptions. Revenue figures are scenario outputs from Phase 1, not Clay forecasts. No Clay internal data or interviews were used.
A10: Tabs | B10: Executive_Summary → Weights → Inputs → Scorecard → Weight_Sensitivity → Random_Weights → Stress_Tests → Subsegment_Drilldown → Options_Tradeoffs → Change_Conditions → Sources

Sheet Executive_Summary
A1: Executive summary — Phase 3 segment prioritization
A2: All figures link to the analysis tabs.
A4: Metric | B4: A. Industrial Distribution | C4: B. Industrial Manufacturing | D4: C. B2B Prof. Services | E4: Note
A5: Market Attractiveness (weight 20%) | B5: =Scorecard!C18 -> 3.9197132 | C5: =Scorecard!D18 -> 4.023328 | D5: =Scorecard!E18 -> 3.5 | E5: Score 1–5
A6: Customer Need (weight 20%) | B6: =Scorecard!C19 -> 5 | C6: =Scorecard!D19 -> 2.5298196 | D6: =Scorecard!E19 -> 2.8045819 | E6: Score 1–5
A7: Product-Market Fit (weight 20%) | B7: =Scorecard!C20 -> 4 | C7: =Scorecard!D20 -> 2 | D7: =Scorecard!E20 -> 4 | E7: Score 1–5
A8: Revenue Potential (weight 15%) | B8: =Scorecard!C21 -> 3.8922494 | C8: =Scorecard!D21 -> 2.2922718 | D8: =Scorecard!E21 -> 3.6729242 | E8: Score 1–5
A9: Competitive Position (weight 15%) | B9: =Scorecard!C22 -> 4 | C9: =Scorecard!D22 -> 3.3333 | D9: =Scorecard!E22 -> 2.3333 | E9: Score 1–5
A10: Ease of Execution (weight 10%) | B10: =Scorecard!C23 -> 2 | C10: =Scorecard!D23 -> 1.5 | D10: =Scorecard!E23 -> 4.5 | E10: Score 1–5
A11: Weighted total (base weights) | B11: =Scorecard!C24 -> 3.9677801 | C11: =Scorecard!D24 -> 2.7044653 | D11: =Scorecard!E24 -> 3.41185
A12: Rank | B12: =Scorecard!C25 -> 1 | C12: =Scorecard!D25 -> 3 | D12: =Scorecard!E25 -> 2
A14: Robustness
A15: Wins across 6 named weight sets | B15: =COUNTIF(Weight_Sensitivity!$E$5:$E$10,"A. Industrial Distribution") -> 5 | C15: =COUNTIF(Weight_Sensitivity!$E$5:$E$10,"B. Industrial Manufacturing") -> 0 | D15: =COUNTIF(Weight_Sensitivity!$E$5:$E$10,"C. B2B Prof. Services") -> 1 | E15: Weight_Sensitivity Block A
A16: Share of 1,000 flat random weightings won | B16: =Weight_Sensitivity!B26 -> 0.74 | C16: =Weight_Sensitivity!C26 -> 0 | D16: =Weight_Sensitivity!D26 -> 0.26 | E16: Any weighting equally likely
A17: Share of 1,000 weightings centered on base won | B17: =Weight_Sensitivity!B27 -> 0.989 | C17: =Weight_Sensitivity!C27 -> 0 | D17: =Weight_Sensitivity!D27 -> 0.011 | E17: Disagreement around base weights
A18: Wins across 12 input stress tests (incl. base) | B18: =COUNTIF(Stress_Tests!$F$5:$F$16,"A. Industrial Distribution") -> 11 | C18: =COUNTIF(Stress_Tests!$F$5:$F$16,"B. Industrial Manufacturing") -> 0 | D18: =COUNTIF(Stress_Tests!$F$5:$F$16,"C. B2B Prof. Services") -> 1 | E18: Stress_Tests
A19: Ease-of-Execution weight at which C overtakes A | B19: =Weight_Sensitivity!E20 -> 0.2637266 | E19: Base weight 10%; only criterion that can flip the result
A20: Distribution beachhead (highest-scoring sub-industry) | B20: =INDEX(Subsegment_Drilldown!$C$4:$F$4,MATCH(1,Subsegment_Drilldown!$C$18:$F$18,0)) -> 4236 Electrical & electronic | E20: Subsegment_Drilldown
A22: Recommendation [E] and rationale
A23: 1. Prioritize U.S. industrial distribution, entering through a staged, partner-led pilot (Option 4) rather than a full vertical build. Beachhead: electrical distributors (NAICS 4236); expansion: PHVAC (4237), then machinery/MRO (4238).
A24: 2. Why distribution: it wins on customer need (5.0), competitive position (4.0) and product fit (4.0), the three things a vertical program can't buy later. It ranks first in 5 of 6 named weight sets (all except 'Execution first'), ~74% of agnostic random weightings, ~99% of weightings near the brief's weights, and 11 of 12 input stress tests. The margin is thin only when several distribution downsides combine (T7: +0.05) or when headroom is ignored (T10: +0.04).
A25: 3. Why not professional services: it is larger and much easier to sell, but Clay already serves it through the horizontal motion and agency ecosystem. A dedicated program mostly re-buys existing demand, and its differentiation vs Apollo and internal builds is weakest. It wins only if ease of execution carries ≳26% of the weight.
A26: 4. Why not manufacturing: last under every weighting. Its selling runs through distributors and reps, so it is best reached indirectly through the distribution beachhead.
A27: 5. The pilot must answer the one question the scores can't: can templates plus partners raise distribution's ease of execution from 2.0 toward ~3.5 (T1)? Phase 4 sizes whether the resulting economics pay back.

Sheet Weights
A1: Criteria weights — analytical assumptions, not management preferences
A2: Base = suggested weights from the project brief. Alternative sets are used on Weight_Sensitivity. Each column must sum to 100%.
A4: Criterion | B4: Base (brief) | C4: Equal | D4: Market-size first | E4: Execution first | F4: Differentiation first | G4: Near-term revenue | H4: What the criterion asks
A5: Market Attractiveness | B5: 0.2 | C5: 0.16666667 | D5: 0.3 | E5: 0.15 | F5: 0.15 | G5: 0.15 | H5: How large and reachable is the segment, and how much of it is still unpenetrated by Clay?
A6: Customer Need | B6: 0.2 | C6: 0.16666667 | D6: 0.15 | E6: 0.15 | F6: 0.2 | G6: 0.1 | H6: How intense is the GTM pain, and how badly do standard tools serve it?
A7: Product-Market Fit | B7: 0.2 | C7: 0.16666667 | D7: 0.15 | E7: 0.2 | F7: 0.15 | G7: 0.2 | H7: How well does Clay's current product solve the core jobs without major new build?
A8: Revenue Potential | B8: 0.15 | C8: 0.16666667 | D8: 0.25 | E8: 0.1 | F8: 0.1 | G8: 0.3 | H8: How much ARR could Clay realistically capture, and how large can each account become?
A9: Competitive Position | B9: 0.15 | C9: 0.16666667 | D9: 0.1 | E9: 0.1 | F9: 0.3 | G9: 0.1 | H9: Can Clay win against incumbents and alternatives, and keep winning?
A10: Ease of Execution | B10: 0.1 | C10: 0.16666667 | D10: 0.05 | E10: 0.3 | F10: 0.1 | G10: 0.15 | H10: How easily can customers adopt Clay and can Clay sell and deliver into the segment?
A11: Check: sum | B11: =SUM(B5:B10) -> 1 | C11: =SUM(C5:C10) -> 1 | D11: =SUM(D5:D10) -> 1 | E11: =SUM(E5:E10) -> 1 | F11: =SUM(F5:F10) -> 1 | G11: =SUM(G5:G10) -> 1
A13: Sub-weights inside composite criteria
A14: Market Attractiveness: share on SAM size (rest on incremental headroom) | G14: 0.5
A15: Customer Need: share on sales intensity (rest on data-coverage gap) | G15: 0.5
A16: Revenue Potential: share on SOM ARR (rest on seller density / account expansion) | G16: 0.5

Sheet Inputs
A1: Metric inputs carried from Phases 1–2
A2: Blue values are copied from the named source cells so this workbook recalculates independently. Change them only if the upstream workbooks change.
A4: ID | B4: Metric | C4: Criterion | D4: A. Industrial Distribution | E4: B. Industrial Manufacturing | F4: C. B2B Prof. Services | G4: Unit | H4: Class | I4: Source (file › tab › cells)
A5: M1 | B5: SAM, Base case | C5: Market Attractiveness | D5: 68163347 | E5: 75842617 | F5: 1.4822739e+08 | G5: $ / yr | H5: C/D | I5: 02_Market_Sizing › Executive_Summary › B10:D10
A6: M2 | B6: Incremental headroom flag (5 = largely unpenetrated by Clay) | C6: Market Attractiveness | D6: 5 | E6: 5 | F6: 2 | G6: 1–5 | H6: C | I6: 04_Competitive_Analysis › Segment_Scoring › F6 row
A7: M3 | B7: Sales intensity index (sales occupations share ÷ all industries) | C7: Customer Need | D7: 2.54356 | E7: 0.31725 | F7: 0.71487 | G7: index | H7: C from A | I7: 02_Market_Sizing › Segment_Profile › B22:D22
A8: M4 | B8: Customer-persona LinkedIn coverage index vs Prof. services | C8: Customer Need | D8: 0.62124 | E8: 0.97041 | F8: 1 | G8: index | H8: C | I8: 04_Competitive_Analysis › Summary › B9:D9
A9: M5 | B9: Product-market fit (judgment; see Scorecard evidence) | C9: Product-Market Fit | D9: 4 | E9: 2 | F9: 4 | G9: 1–5 | H9: C | I9: This workbook › Scorecard (pain-to-capability map in 05_Customer_Needs_Assessment §3)
A10: M6 | B10: SOM — year-3 ARR potential, Base case | C10: Revenue Potential | D10: 1864123.6 | E10: 2149272.5 | F10: 4178480.9 | G10: $ / yr | H10: D | I10: 02_Market_Sizing › Executive_Summary › B11:D11
A11: M7 | B11: Implied sales staff per 20+ firm (usage / expansion driver) | C11: Revenue Potential | D11: 27.7 | E11: 3.65 | F11: 9.32 | G11: people | H11: C from A | I11: 02_Market_Sizing › Segment_Profile › B19:D19
A12: M8 | B12: Competitive position score | C12: Competitive Position | D12: 4 | E12: 3.3333 | F12: 2.3333 | G12: 1–5 | H12: C | I12: 04_Competitive_Analysis › Summary › B5:D5
A13: M9 | B13: Adoption / execution fit score | C13: Ease of Execution | D13: 2 | E13: 1.5 | F13: 4.5 | G13: 1–5 | H13: C | I13: 04_Competitive_Analysis › Summary › B6:D6
A15: M4 enters inversely: a lower coverage index means a larger data gap, so data-gap score = 1 + 4 × MIN(M4) ÷ M4. M2 headroom, M5, M8 and M9 are already on the 1–5 scale and enter directly.

Sheet Scorecard
A1: Scorecard — base weights, evidence for every score
A2: Scores 1–5 (5 = most attractive for Clay). Columns C–E = segments. Evidence for each criterion is in column G.
A4: Item | B4: Type | C4: A. Industrial Distribution | D4: B. Industrial Manufacturing | E4: C. B2B Prof. Services | G4: Evidence (why these scores)
A5: Base case (suggested weights)
A6: M1 SAM, Base case | B6: input | C6: =Inputs!D5 -> 68163347 | D6: =Inputs!E5 -> 75842617 | E6: =Inputs!F5 -> 1.4822739e+08
A7: M2 Incremental headroom flag (5 = largely unpenetrated by Clay) | B7: input | C7: =Inputs!D6 -> 5 | D7: =Inputs!E6 -> 5 | E7: =Inputs!F6 -> 2
A8: M3 Sales intensity index (sales occupations share ÷ all industries) | B8: input | C8: =Inputs!D7 -> 2.54356 | D8: =Inputs!E7 -> 0.31725 | E8: =Inputs!F7 -> 0.71487
A9: M4 Customer-persona LinkedIn coverage index vs Prof. services | B9: input | C9: =Inputs!D8 -> 0.62124 | D9: =Inputs!E8 -> 0.97041 | E9: =Inputs!F8 -> 1
A10: M5 Product-market fit (judgment; see Scorecard evidence) | B10: input | C10: =Inputs!D9 -> 4 | D10: =Inputs!E9 -> 2 | E10: =Inputs!F9 -> 4
A11: M6 SOM — year-3 ARR potential, Base case | B11: input | C11: =Inputs!D10 -> 1864123.6 | D11: =Inputs!E10 -> 2149272.5 | E11: =Inputs!F10 -> 4178480.9
A12: M7 Implied sales staff per 20+ firm (usage / expansion driver) | B12: input | C12: =Inputs!D11 -> 27.7 | D12: =Inputs!E11 -> 3.65 | E12: =Inputs!F11 -> 9.32
A13: M8 Competitive position score | B13: input | C13: =Inputs!D12 -> 4 | D13: =Inputs!E12 -> 3.3333 | E13: =Inputs!F12 -> 2.3333
A14: M9 Adoption / execution fit score | B14: input | C14: =Inputs!D13 -> 2 | D14: =Inputs!E13 -> 1.5 | E14: =Inputs!F13 -> 4.5
A15: Sub-weight: Market Attractiveness (share on SAM size) | B15: sub-weight | C15: =Weights!$G$14 -> 0.5
A16: Sub-weight: Customer Need (share on sales intensity) | B16: sub-weight | C16: =Weights!$G$15 -> 0.5
A17: Sub-weight: Revenue Potential (share on SOM ARR) | B17: sub-weight | C17: =Weights!$G$16 -> 0.5
A18: Score — Market Attractiveness | B18: 1–5 | C18: =$C$15*(1+4*C6/MAX($C$6:$E$6))+(1-$C$15)*C7 -> 3.9197132 | D18: =$C$15*(1+4*D6/MAX($C$6:$E$6))+(1-$C$15)*D7 -> 4.023328 | E18: =$C$15*(1+4*E6/MAX($C$6:$E$6))+(1-$C$15)*E7 -> 3.5 | G18: Prof. services has the largest SAM ($148M vs $68–76M, 02_Market_Sizing) but the least incremental headroom: agencies and consultancies are already Clay customers and partners (S32, S34). The two industrial segments are largely unpenetrated: no industrial industry in the top 5 of Clay's detected users (S32); the Sep 2026 marketplace expansion skipped industrials (S09). The two effects nearly offset.
A19: Score — Customer Need | B19: 1–5 | C19: =$C$16*(1+4*C8/MAX($C$8:$E$8))+(1-$C$16)*(1+4*MIN($C$9:$E$9)/C9) -> 5 | D19: =$C$16*(1+4*D8/MAX($C$8:$E$8))+(1-$C$16)*(1+4*MIN($C$9:$E$9)/D9) -> 2.5298196 | E19: =$C$16*(1+4*E8/MAX($C$8:$E$8))+(1-$C$16)*(1+4*MIN($C$9:$E$9)/E9) -> 2.8045819 | G19: Distribution: sales occupations are 22% of employment (2.5× average) and 39% of surveyed distributors prioritize new-customer growth (S25). Its customers' personas have ~0.62× the estimated LinkedIn coverage of prof.-services buyers, and Regency reports ZoomInfo and Apollo failed to find contractors (S07). Manufacturing sells indirectly (0.32× sales intensity) and has no data gap. Prof. services has a moderate sales function and no data gap.
A20: Score — Product-Market Fit | B20: 1–5 | C20: =C10 -> 4 | D20: =D10 -> 2 | E20: =E10 -> 4 | G20: Judgment from the pain-to-capability map (05 §3). Distribution has 4 strong fits (contractor sourcing via Google Maps and Shovels, territory scoring, CRM completeness, e-commerce vetting; all shown in the Regency case) but a gap on ERP-based cross-sell, so 4. Manufacturing: its core jobs (channel management, sourcing-platform demand such as Thomasnet with no API) are weak fits, so 2. Prof. services: account research, pursuit prep and targeted outbound are proven Clay use cases (OpenAI pre-call prep, agency usage), so 4.
A21: Score — Revenue Potential | B21: 1–5 | C21: =$C$17*(1+4*C11/MAX($C$11:$E$11))+(1-$C$17)*(1+4*C12/MAX($C$12:$E$12)) -> 3.8922494 | D21: =$C$17*(1+4*D11/MAX($C$11:$E$11))+(1-$C$17)*(1+4*D12/MAX($C$12:$E$12)) -> 2.2922718 | E21: =$C$17*(1+4*E11/MAX($C$11:$E$11))+(1-$C$17)*(1+4*E12/MAX($C$12:$E$12)) -> 3.6729242 | G21: Half on Phase 1 SOM ARR (prof. services ~2.2× distribution) and half on seller density: ~28 sales staff per distributor vs ~9 in prof. services and ~4 in manufacturing (OEWS × Census). Clay's usage pricing scales with records and seats, and enterprise NRR is >200% (S02).
A22: Score — Competitive Position | B22: 1–5 | C22: =C13 -> 4 | D22: =D13 -> 3.3333 | E22: =E13 -> 2.3333 | G22: Phase 2 Segment_Scoring: data-differentiation relevance, incumbent saturation, vertical-specialist threat. Distribution 4.0 (real data gap; thin incumbents: 68% of distributors use spreadsheets, S25). Prof. services 2.3 (well-covered personas, Apollo/ZoomInfo and internal builds entrenched).
A23: Score — Ease of Execution | B23: 1–5 | C23: =C14 -> 2 | D23: =D14 -> 1.5 | E23: =E14 -> 4.5 | G23: Phase 2 adoption fit: builder capacity (computer-occupation index 0.69 / 0.45 / 7.15) and existing references/partners (one distribution case study; no industrial partners found; prof. services has its own case-study filter). Prof. services is far easier to sell into and deliver.
A24: Weighted total score | B24: 1–5 | C24: =SUMPRODUCT(Weights!$B$5:$B$10,C18:C23) -> 3.9677801 | D24: =SUMPRODUCT(Weights!$B$5:$B$10,D18:D23) -> 2.7044653 | E24: =SUMPRODUCT(Weights!$B$5:$B$10,E18:E23) -> 3.41185
A25: Rank | C25: =RANK(C24,$C$24:$E$24) -> 1 | D25: =RANK(D24,$C$24:$E$24) -> 3 | E25: =RANK(E24,$C$24:$E$24) -> 2
A26: Winner / margin over runner-up | C26: =INDEX($C$4:$E$4,MATCH(MAX(C24:E24),C24:E24,0)) -> A. Industrial Distribution | D26: =MAX(C24:E24)-LARGE(C24:E24,2) -> 0.55593004
A28: Weighted contribution by criterion (base weights)
A29: Market Attractiveness | B29: =Weights!$B$5 -> 0.2 | C29: =$B29*C18 -> 0.78394265 | D29: =$B29*D18 -> 0.80466559 | E29: =$B29*E18 -> 0.7
A30: Customer Need | B30: =Weights!$B$6 -> 0.2 | C30: =$B30*C19 -> 1 | D30: =$B30*D19 -> 0.50596391 | E30: =$B30*E19 -> 0.56091639
A31: Product-Market Fit | B31: =Weights!$B$7 -> 0.2 | C31: =$B31*C20 -> 0.8 | D31: =$B31*D20 -> 0.4 | E31: =$B31*E20 -> 0.8
A32: Revenue Potential | B32: =Weights!$B$8 -> 0.15 | C32: =$B32*C21 -> 0.58383741 | D32: =$B32*D21 -> 0.34384077 | E32: =$B32*E21 -> 0.55093863
A33: Competitive Position | B33: =Weights!$B$9 -> 0.15 | C33: =$B33*C22 -> 0.6 | D33: =$B33*D22 -> 0.499995 | E33: =$B33*E22 -> 0.349995
A34: Ease of Execution | B34: =Weights!$B$10 -> 0.1 | C34: =$B34*C23 -> 0.2 | D34: =$B34*D23 -> 0.15 | E34: =$B34*E23 -> 0.45
A35: Total (= weighted total above) | C35: =SUM(C29:C34) -> 3.9677801 | D35: =SUM(D29:D34) -> 2.7044653 | E35: =SUM(E29:E34) -> 3.41185
A36: Check: contribution total − weighted total (should be 0) | C36: =ROUND(SUM(C35:E35)-SUM(C24:E24),6) -> 0

Sheet Weight_Sensitivity
A1: Weight sensitivity — does the ranking survive different priorities?
A2: Block A: alternative weight sets. Block B: break-even weight per criterion (others rescaled proportionally). Block C: random-weight simulation summary (detail on Random_Weights).
A4: Weight set | B4: A. Industrial Distribution | C4: B. Industrial Manufacturing | D4: C. B2B Prof. Services | E4: Winner | F4: Margin | G4: Ranking (1st > 2nd > 3rd)
A5: Base (brief) | B5: =SUMPRODUCT(Weights!$B$5:$B$10,Scorecard!C$18:C$23) -> 3.9677801 | C5: =SUMPRODUCT(Weights!$B$5:$B$10,Scorecard!D$18:D$23) -> 2.7044653 | D5: =SUMPRODUCT(Weights!$B$5:$B$10,Scorecard!E$18:E$23) -> 3.41185 | E5: =INDEX($B$4:$D$4,MATCH(MAX(B5:D5),B5:D5,0)) -> A. Industrial Distribution | F5: =MAX(B5:D5)-LARGE(B5:D5,2) -> 0.55593004 | G5: =INDEX($B$4:$D$4,MATCH(LARGE(B5:D5,1),B5:D5,0))&" > "&INDEX($B$4:$D$4,MATCH(LARGE(B5:D5,2),B5:D5,0))&" > "&INDEX($B$4:$D$4,MATCH(LARGE(B5:D5,3),B5:D5,0)) -> A. Industrial Distribution > C. B2B Prof. Services > B. Industrial Manufacturing
A6: Equal | B6: =SUMPRODUCT(Weights!$C$5:$C$10,Scorecard!C$18:C$23) -> 3.8019938 | C6: =SUMPRODUCT(Weights!$C$5:$C$10,Scorecard!D$18:D$23) -> 2.6131199 | D6: =SUMPRODUCT(Weights!$C$5:$C$10,Scorecard!E$18:E$23) -> 3.4684677 | E6: =INDEX($B$4:$D$4,MATCH(MAX(B6:D6),B6:D6,0)) -> A. Industrial Distribution | F6: =MAX(B6:D6)-LARGE(B6:D6,2) -> 0.33352609 | G6: =INDEX($B$4:$D$4,MATCH(LARGE(B6:D6,1),B6:D6,0))&" > "&INDEX($B$4:$D$4,MATCH(LARGE(B6:D6,2),B6:D6,0))&" > "&INDEX($B$4:$D$4,MATCH(LARGE(B6:D6,3),B6:D6,0)) -> A. Industrial Distribution > C. B2B Prof. Services > B. Industrial Manufacturing
A7: Market-size first | B7: =SUMPRODUCT(Weights!$D$5:$D$10,Scorecard!C$18:C$23) -> 3.9989763 | C7: =SUMPRODUCT(Weights!$D$5:$D$10,Scorecard!D$18:D$23) -> 2.8678693 | D7: =SUMPRODUCT(Weights!$D$5:$D$10,Scorecard!E$18:E$23) -> 3.4472483 | E7: =INDEX($B$4:$D$4,MATCH(MAX(B7:D7),B7:D7,0)) -> A. Industrial Distribution | F7: =MAX(B7:D7)-LARGE(B7:D7,2) -> 0.55172798 | G7: =INDEX($B$4:$D$4,MATCH(LARGE(B7:D7,1),B7:D7,0))&" > "&INDEX($B$4:$D$4,MATCH(LARGE(B7:D7,2),B7:D7,0))&" > "&INDEX($B$4:$D$4,MATCH(LARGE(B7:D7,3),B7:D7,0)) -> A. Industrial Distribution > C. B2B Prof. Services > B. Industrial Manufacturing
A8: Execution first | B8: =SUMPRODUCT(Weights!$E$5:$E$10,Scorecard!C$18:C$23) -> 3.5271819 | C8: =SUMPRODUCT(Weights!$E$5:$E$10,Scorecard!D$18:D$23) -> 2.3955293 | D8: =SUMPRODUCT(Weights!$E$5:$E$10,Scorecard!E$18:E$23) -> 3.6963097 | E8: =INDEX($B$4:$D$4,MATCH(MAX(B8:D8),B8:D8,0)) -> C. B2B Prof. Services | F8: =MAX(B8:D8)-LARGE(B8:D8,2) -> 0.16912778 | G8: =INDEX($B$4:$D$4,MATCH(LARGE(B8:D8,1),B8:D8,0))&" > "&INDEX($B$4:$D$4,MATCH(LARGE(B8:D8,2),B8:D8,0))&" > "&INDEX($B$4:$D$4,MATCH(LARGE(B8:D8,3),B8:D8,0)) -> C. B2B Prof. Services > A. Industrial Distribution > B. Industrial Manufacturing
A9: Differentiation first | B9: =SUMPRODUCT(Weights!$F$5:$F$10,Scorecard!C$18:C$23) -> 3.9771819 | C9: =SUMPRODUCT(Weights!$F$5:$F$10,Scorecard!D$18:D$23) -> 2.7886803 | D9: =SUMPRODUCT(Weights!$F$5:$F$10,Scorecard!E$18:E$23) -> 3.2031988 | E9: =INDEX($B$4:$D$4,MATCH(MAX(B9:D9),B9:D9,0)) -> A. Industrial Distribution | F9: =MAX(B9:D9)-LARGE(B9:D9,2) -> 0.77398312 | G9: =INDEX($B$4:$D$4,MATCH(LARGE(B9:D9,1),B9:D9,0))&" > "&INDEX($B$4:$D$4,MATCH(LARGE(B9:D9,2),B9:D9,0))&" > "&INDEX($B$4:$D$4,MATCH(LARGE(B9:D9,3),B9:D9,0)) -> A. Industrial Distribution > C. B2B Prof. Services > B. Industrial Manufacturing
A10: Near-term revenue | B10: =SUMPRODUCT(Weights!$G$5:$G$10,Scorecard!C$18:C$23) -> 3.7556318 | C10: =SUMPRODUCT(Weights!$G$5:$G$10,Scorecard!D$18:D$23) -> 2.5024927 | D10: =SUMPRODUCT(Weights!$G$5:$G$10,Scorecard!E$18:E$23) -> 3.6156654 | E10: =INDEX($B$4:$D$4,MATCH(MAX(B10:D10),B10:D10,0)) -> A. Industrial Distribution | F10: =MAX(B10:D10)-LARGE(B10:D10,2) -> 0.13996636 | G10: =INDEX($B$4:$D$4,MATCH(LARGE(B10:D10,1),B10:D10,0))&" > "&INDEX($B$4:$D$4,MATCH(LARGE(B10:D10,2),B10:D10,0))&" > "&INDEX($B$4:$D$4,MATCH(LARGE(B10:D10,3),B10:D10,0)) -> A. Industrial Distribution > C. B2B Prof. Services > B. Industrial Manufacturing
A13: Block B — Break-even weight: how much weight on one criterion (others rescaled pro rata) flips the base winner (A) vs each rival?
A14: Criterion | B14: Base weight | C14: Score gap A − C (this criterion) | D14: A − C gap from other criteria (rescaled) | E14: Break-even weight vs C | F14: Break-even weight vs B | G14: Interpretation
A15: Market Attractiveness | B15: =Weights!$B$5 -> 0.2 | C15: =Scorecard!C18-Scorecard!E18 -> 0.41971323 | D15: =(SUMPRODUCT(Weights!$B$5:$B$10,Scorecard!$C$18:$C$23)-SUMPRODUCT(Weights!$B$5:$B$10,Scorecard!$E$18:$E$23)-B15*C15)/(1-B15) -> 0.58998425 | E15: =IF(AND(D15>0,C15<0),D15/(D15-C15),"No flip") -> No flip | F15: =IF(AND(((SUMPRODUCT(Weights!$B$5:$B$10,Scorecard!$C$18:$C$23)-SUMPRODUCT(Weights!$B$5:$B$10,Scorecard!$D$18:$D$23)-B15*(Scorecard!C18-Scorecard!D18))/(1-B15))>0,(Scorecard!C18-Scorecard!D18)<0),((SUMPRODUCT(Weights!$B$5:$B$10,Scorecard!$C$18:$C$23)-SUMPRODUCT(Weights!$B$5:$B$10,Scorecard!$D$18:$D$23)-B15*(Scorecard!C18-Scorecard!D18))/(1-B15))/(((SUMPRODUCT(Weights!$B$5:$B$10,Scorecard!$C$18:$C$23)-SUMPRODUCT(Weights!$B$5:$B$10,Scorecard!$D$18:$D$23)-B15*(Scorecard!C18-Scorecard!D18))/(1-B15))-(Scorecard!C18-Scorecard!D18)),"No flip") -> 0.93935914 | G15: =IF(ISNUMBER(E15),"C overtakes A if this weight exceeds "&TEXT(E15,"0%")&" (base "&TEXT(B15,"0%")&")","A stays ahead of C at any weight on this criterion") -> A stays ahead of C at any weight on this criterion
A16: Customer Need | B16: =Weights!$B$6 -> 0.2 | C16: =Scorecard!C19-Scorecard!E19 -> 2.1954181 | D16: =(SUMPRODUCT(Weights!$B$5:$B$10,Scorecard!$C$18:$C$23)-SUMPRODUCT(Weights!$B$5:$B$10,Scorecard!$E$18:$E$23)-B16*C16)/(1-B16) -> 0.14605804 | E16: =IF(AND(D16>0,C16<0),D16/(D16-C16),"No flip") -> No flip | F16: =IF(AND(((SUMPRODUCT(Weights!$B$5:$B$10,Scorecard!$C$18:$C$23)-SUMPRODUCT(Weights!$B$5:$B$10,Scorecard!$D$18:$D$23)-B16*(Scorecard!C19-Scorecard!D19))/(1-B16))>0,(Scorecard!C19-Scorecard!D19)<0),((SUMPRODUCT(Weights!$B$5:$B$10,Scorecard!$C$18:$C$23)-SUMPRODUCT(Weights!$B$5:$B$10,Scorecard!$D$18:$D$23)-B16*(Scorecard!C19-Scorecard!D19))/(1-B16))/(((SUMPRODUCT(Weights!$B$5:$B$10,Scorecard!$C$18:$C$23)-SUMPRODUCT(Weights!$B$5:$B$10,Scorecard!$D$18:$D$23)-B16*(Scorecard!C19-Scorecard!D19))/(1-B16))-(Scorecard!C19-Scorecard!D19)),"No flip") -> No flip | G16: =IF(ISNUMBER(E16),"C overtakes A if this weight exceeds "&TEXT(E16,"0%")&" (base "&TEXT(B16,"0%")&")","A stays ahead of C at any weight on this criterion") -> A stays ahead of C at any weight on this criterion
A17: Product-Market Fit | B17: =Weights!$B$7 -> 0.2 | C17: =Scorecard!C20-Scorecard!E20 -> 0 | D17: =(SUMPRODUCT(Weights!$B$5:$B$10,Scorecard!$C$18:$C$23)-SUMPRODUCT(Weights!$B$5:$B$10,Scorecard!$E$18:$E$23)-B17*C17)/(1-B17) -> 0.69491255 | E17: =IF(AND(D17>0,C17<0),D17/(D17-C17),"No flip") -> No flip | F17: =IF(AND(((SUMPRODUCT(Weights!$B$5:$B$10,Scorecard!$C$18:$C$23)-SUMPRODUCT(Weights!$B$5:$B$10,Scorecard!$D$18:$D$23)-B17*(Scorecard!C20-Scorecard!D20))/(1-B17))>0,(Scorecard!C20-Scorecard!D20)<0),((SUMPRODUCT(Weights!$B$5:$B$10,Scorecard!$C$18:$C$23)-SUMPRODUCT(Weights!$B$5:$B$10,Scorecard!$D$18:$D$23)-B17*(Scorecard!C20-Scorecard!D20))/(1-B17))/(((SUMPRODUCT(Weights!$B$5:$B$10,Scorecard!$C$18:$C$23)-SUMPRODUCT(Weights!$B$5:$B$10,Scorecard!$D$18:$D$23)-B17*(Scorecard!C20-Scorecard!D20))/(1-B17))-(Scorecard!C20-Scorecard!D20)),"No flip") -> No flip | G17: =IF(ISNUMBER(E17),"C overtakes A if this weight exceeds "&TEXT(E17,"0%")&" (base "&TEXT(B17,"0%")&")","A stays ahead of C at any weight on this criterion") -> A stays ahead of C at any weight on this criterion
A18: Revenue Potential | B18: =Weights!$B$8 -> 0.15 | C18: =Scorecard!C21-Scorecard!E21 -> 0.21932523 | D18: =(SUMPRODUCT(Weights!$B$5:$B$10,Scorecard!$C$18:$C$23)-SUMPRODUCT(Weights!$B$5:$B$10,Scorecard!$E$18:$E$23)-B18*C18)/(1-B18) -> 0.61533089 | E18: =IF(AND(D18>0,C18<0),D18/(D18-C18),"No flip") -> No flip | F18: =IF(AND(((SUMPRODUCT(Weights!$B$5:$B$10,Scorecard!$C$18:$C$23)-SUMPRODUCT(Weights!$B$5:$B$10,Scorecard!$D$18:$D$23)-B18*(Scorecard!C21-Scorecard!D21))/(1-B18))>0,(Scorecard!C21-Scorecard!D21)<0),((SUMPRODUCT(Weights!$B$5:$B$10,Scorecard!$C$18:$C$23)-SUMPRODUCT(Weights!$B$5:$B$10,Scorecard!$D$18:$D$23)-B18*(Scorecard!C21-Scorecard!D21))/(1-B18))/(((SUMPRODUCT(Weights!$B$5:$B$10,Scorecard!$C$18:$C$23)-SUMPRODUCT(Weights!$B$5:$B$10,Scorecard!$D$18:$D$23)-B18*(Scorecard!C21-Scorecard!D21))/(1-B18))-(Scorecard!C21-Scorecard!D21)),"No flip") -> No flip | G18: =IF(ISNUMBER(E18),"C overtakes A if this weight exceeds "&TEXT(E18,"0%")&" (base "&TEXT(B18,"0%")&")","A stays ahead of C at any weight on this criterion") -> A stays ahead of C at any weight on this criterion
A19: Competitive Position | B19: =Weights!$B$9 -> 0.15 | C19: =Scorecard!C22-Scorecard!E22 -> 1.6667 | D19: =(SUMPRODUCT(Weights!$B$5:$B$10,Scorecard!$C$18:$C$23)-SUMPRODUCT(Weights!$B$5:$B$10,Scorecard!$E$18:$E$23)-B19*C19)/(1-B19) -> 0.35991181 | E19: =IF(AND(D19>0,C19<0),D19/(D19-C19),"No flip") -> No flip | F19: =IF(AND(((SUMPRODUCT(Weights!$B$5:$B$10,Scorecard!$C$18:$C$23)-SUMPRODUCT(Weights!$B$5:$B$10,Scorecard!$D$18:$D$23)-B19*(Scorecard!C22-Scorecard!D22))/(1-B19))>0,(Scorecard!C22-Scorecard!D22)<0),((SUMPRODUCT(Weights!$B$5:$B$10,Scorecard!$C$18:$C$23)-SUMPRODUCT(Weights!$B$5:$B$10,Scorecard!$D$18:$D$23)-B19*(Scorecard!C22-Scorecard!D22))/(1-B19))/(((SUMPRODUCT(Weights!$B$5:$B$10,Scorecard!$C$18:$C$23)-SUMPRODUCT(Weights!$B$5:$B$10,Scorecard!$D$18:$D$23)-B19*(Scorecard!C22-Scorecard!D22))/(1-B19))-(Scorecard!C22-Scorecard!D22)),"No flip") -> No flip | G19: =IF(ISNUMBER(E19),"C overtakes A if this weight exceeds "&TEXT(E19,"0%")&" (base "&TEXT(B19,"0%")&")","A stays ahead of C at any weight on this criterion") -> A stays ahead of C at any weight on this criterion
A20: Ease of Execution | B20: =Weights!$B$10 -> 0.1 | C20: =Scorecard!C23-Scorecard!E23 -> -2.5 | D20: =(SUMPRODUCT(Weights!$B$5:$B$10,Scorecard!$C$18:$C$23)-SUMPRODUCT(Weights!$B$5:$B$10,Scorecard!$E$18:$E$23)-B20*C20)/(1-B20) -> 0.89547782 | E20: =IF(AND(D20>0,C20<0),D20/(D20-C20),"No flip") -> 0.2637266 | F20: =IF(AND(((SUMPRODUCT(Weights!$B$5:$B$10,Scorecard!$C$18:$C$23)-SUMPRODUCT(Weights!$B$5:$B$10,Scorecard!$D$18:$D$23)-B20*(Scorecard!C23-Scorecard!D23))/(1-B20))>0,(Scorecard!C23-Scorecard!D23)<0),((SUMPRODUCT(Weights!$B$5:$B$10,Scorecard!$C$18:$C$23)-SUMPRODUCT(Weights!$B$5:$B$10,Scorecard!$D$18:$D$23)-B20*(Scorecard!C23-Scorecard!D23))/(1-B20))/(((SUMPRODUCT(Weights!$B$5:$B$10,Scorecard!$C$18:$C$23)-SUMPRODUCT(Weights!$B$5:$B$10,Scorecard!$D$18:$D$23)-B20*(Scorecard!C23-Scorecard!D23))/(1-B20))-(Scorecard!C23-Scorecard!D23)),"No flip") -> No flip | G20: =IF(ISNUMBER(E20),"C overtakes A if this weight exceeds "&TEXT(E20,"0%")&" (base "&TEXT(B20,"0%")&")","A stays ahead of C at any weight on this criterion") -> C overtakes A if this weight exceeds 26% (base 10%)
A22: Reading: Ease of Execution is the only criterion whose weight can flip the result. Prof. services overtakes distribution once Ease carries roughly 26% or more of the total weight (base 10%). Manufacturing never overtakes distribution.
A24: Block C — Random-weight simulation (1,000 draws each; stored values, seed 42)
A25: Weight distribution | B25: A wins | C25: B wins | D25: C wins | E25: Draws | G25: What it represents
A26: Flat Dirichlet(1,…,1) — any weighting equally likely | B26: =COUNTIF(Random_Weights!D$6:D$1005,"A. Distribution")/COUNTA(Random_Weights!D$6:D$1005) -> 0.74 | C26: =COUNTIF(Random_Weights!D$6:D$1005,"B. Manufacturing")/COUNTA(Random_Weights!D$6:D$1005) -> 0 | D26: =COUNTIF(Random_Weights!D$6:D$1005,"C. Prof. services")/COUNTA(Random_Weights!D$6:D$1005) -> 0.26 | E26: =COUNTA(Random_Weights!D$6:D$1005) -> 1000 | G26: Agnostic: no view on which criteria matter
A27: Centered Dirichlet(30 × base weights) | B27: =COUNTIF(Random_Weights!M$6:M$1005,"A. Distribution")/COUNTA(Random_Weights!M$6:M$1005) -> 0.989 | C27: =COUNTIF(Random_Weights!M$6:M$1005,"B. Manufacturing")/COUNTA(Random_Weights!M$6:M$1005) -> 0 | D27: =COUNTIF(Random_Weights!M$6:M$1005,"C. Prof. services")/COUNTA(Random_Weights!M$6:M$1005) -> 0.011 | E27: =COUNTA(Random_Weights!M$6:M$1005) -> 1000 | G27: Reasonable disagreement around the brief's weights

Sheet Random_Weights
A1: Random weight vectors — generated in Python (numpy, seed 42) and stored as values for reproducibility
A2: Columns A–F flat Dirichlet weights; G–I scores; D-col winner. Right block: centered Dirichlet. Scores use Scorecard criterion scores (live).
A5: Draw | B5: Flat score A | C5: Flat score B | D5: Flat winner | E5: w MA | F5: w Need | G5: w PMF | H5: w Rev | I5: w CP | J5: w Ease | K5: Flat score C | M5: Centered winner | N5: w MA | O5: w Need | P5: w PMF | Q5: w Rev | R5: w CP | S5: w Ease | T5: Centered score A | U5: Centered score B | V5: Centered score C
A6: 1 | B6: =E6*Scorecard!$C$18+F6*Scorecard!$C$19+G6*Scorecard!$C$20+H6*Scorecard!$C$21+I6*Scorecard!$C$22+J6*Scorecard!$C$23 -> 3.9114154 | C6: =E6*Scorecard!$D$18+F6*Scorecard!$D$19+G6*Scorecard!$D$20+H6*Scorecard!$D$21+I6*Scorecard!$D$22+J6*Scorecard!$D$23 -> 2.6230906 | D6: =IF(AND(B6>=C6,B6>=K6),"A. Distribution",IF(C6>=K6,"B. Manufacturing","C. Prof. services")) -> A. Distribution | E6: 0.26880532 | F6: 0.26120038 | G6: 0.26663096 | H6: 0.031282724 | I6: 0.0096642333 | J6: 0.16241639 | K6: =E6*Scorecard!$E$18+F6*Scorecard!$E$19+G6*Scorecard!$E$20+H6*Scorecard!$E$21+I6*Scorecard!$E$22+J6*Scorecard!$E$23 -> 3.6082227 | M6: =IF(AND(T6>=U6,T6>=V6),"A. Distribution",IF(U6>=V6,"B. Manufacturing","C. Prof. services")) -> A. Distribution | N6: 0.18665161 | O6: 0.14055922 | P6: 0.29040633 | Q6: 0.23790264 | R6: 0.065231681 | S6: 0.079248522 | T6: =N6*Scorecard!$C$18+O6*Scorecard!$C$19+P6*Scorecard!$C$20+Q6*Scorecard!$C$21+R6*Scorecard!$C$22+S6*Scorecard!$C$23 -> 3.9414424 | U6: =N6*Scorecard!$D$18+O6*Scorecard!$D$19+P6*Scorecard!$D$20+Q6*Scorecard!$D$21+R6*Scorecard!$D$22+S6*Scorecard!$D$23 -> 2.5690098 | V6: =N6*Scorecard!$E$18+O6*Scorecard!$E$19+P6*Scorecard!$E$20+Q6*Scorecard!$E$21+R6*Scorecard!$E$22+S6*Scorecard!$E$23 -> 3.5917376
A7: 2 | B7: =E7*Scorecard!$C$18+F7*Scorecard!$C$19+G7*Scorecard!$C$20+H7*Scorecard!$C$21+I7*Scorecard!$C$22+J7*Scorecard!$C$23 -> 4.1056195 | C7: =E7*Scorecard!$D$18+F7*Scorecard!$D$19+G7*Scorecard!$D$20+H7*Scorecard!$D$21+I7*Scorecard!$D$22+J7*Scorecard!$D$23 -> 2.639836 | D7: =IF(AND(B7>=C7,B7>=K7),"A. Distribution",IF(C7>=K7,"B. Manufacturing","C. Prof. services")) -> A. Distribution | E7: 0.20675209 | F7: 0.45813669 | G7: 0.011627445 | H7: 0.15346431 | I7: 0.010328553 | J7: 0.15969091 | K7: =E7*Scorecard!$E$18+F7*Scorecard!$E$19+G7*Scorecard!$E$20+H7*Scorecard!$E$21+I7*Scorecard!$E$22+J7*Scorecard!$E$23 -> 3.3613955 | M7: =IF(AND(T7>=U7,T7>=V7),"A. Distribution",IF(U7>=V7,"B. Manufacturing","C. Prof. services")) -> A. Distribution | N7: 0.10220869 | O7: 0.22710911 | P7: 0.32827074 | Q7: 0.13608774 | R7: 0.10345904 | S7: 0.10286469 | T7: =N7*Scorecard!$C$18+O7*Scorecard!$C$19+P7*Scorecard!$C$20+Q7*Scorecard!$C$21+R7*Scorecard!$C$22+S7*Scorecard!$C$23 -> 3.9985102 | U7: =N7*Scorecard!$D$18+O7*Scorecard!$D$19+P7*Scorecard!$D$20+Q7*Scorecard!$D$21+R7*Scorecard!$D$22+S7*Scorecard!$D$23 -> 2.4534127 | V7: =N7*Scorecard!$E$18+O7*Scorecard!$E$19+P7*Scorecard!$E$20+Q7*Scorecard!$E$21+R7*Scorecard!$E$22+S7*Scorecard!$E$23 -> 3.5118915
A8: 3 | B8: =E8*Scorecard!$C$18+F8*Scorecard!$C$19+G8*Scorecard!$C$20+H8*Scorecard!$C$21+I8*Scorecard!$C$22+J8*Scorecard!$C$23 -> 3.8979537 | C8: =E8*Scorecard!$D$18+F8*Scorecard!$D$19+G8*Scorecard!$D$20+H8*Scorecard!$D$21+I8*Scorecard!$D$22+J8*Scorecard!$D$23 -> 2.9506804 | D8: =IF(AND(B8>=C8,B8>=K8),"A. Distribution",IF(C8>=K8,"B. Manufacturing","C. Prof. services")) -> A. Distribution | E8: 0.44275649 | F8: 0.098941541 | G8: 0.31495635 | H8: 0.039324803 | I8: 0.023419274 | J8: 0.080601533 | K8: =E8*Scorecard!$E$18+F8*Scorecard!$E$19+G8*Scorecard!$E$20+H8*Scorecard!$E$21+I8*Scorecard!$E$22+J8*Scorecard!$E$23 -> 3.6487509 | M8: =IF(AND(T8>=U8,T8>=V8),"A. Distribution",IF(U8>=V8,"B. Manufacturing","C. Prof. services")) -> A. Distribution | N8: 0.26232953 | O8: 0.26304641 | P8: 0.1544982 | Q8: 0.097961868 | R8: 0.15128926 | S8: 0.070874724 | T8: =N8*Scorecard!$C$18+O8*Scorecard!$C$19+P8*Scorecard!$C$20+Q8*Scorecard!$C$21+R8*Scorecard!$C$22+S8*Scorecard!$C$23 -> 4.0896799 | U8: =N8*Scorecard!$D$18+O8*Scorecard!$D$19+P8*Scorecard!$D$20+Q8*Scorecard!$D$21+R8*Scorecard!$D$22+S8*Scorecard!$D$23 -> 2.8650539 | V8: =N8*Scorecard!$E$18+O8*Scorecard!$E$19+P8*Scorecard!$E$20+Q8*Scorecard!$E$21+R8*Scorecard!$E$22+S8*Scorecard!$E$23 -> 3.3056274
A9: 4 | B9: =E9*Scorecard!$C$18+F9*Scorecard!$C$19+G9*Scorecard!$C$20+H9*Scorecard!$C$21+I9*Scorecard!$C$22+J9*Scorecard!$C$23 -> 3.6346056 | C9: =E9*Scorecard!$D$18+F9*Scorecard!$D$19+G9*Scorecard!$D$20+H9*Scorecard!$D$21+I9*Scorecard!$D$22+J9*Scorecard!$D$23 -> 2.6742667 | D9: =IF(AND(B9>=C9,B9>=K9),"A. Distribution",IF(C9>=K9,"B. Manufacturing","C. Prof. services")) -> A. Distribution | E9: 0.15404581 | F9: 0.070593333 | G9: 0.21322097 | H9: 0.038216857 | I9: 0.31417205 | J9: 0.20975099 | K9: =E9*Scorecard!$E$18+F9*Scorecard!$E$19+G9*Scorecard!$E$20+H9*Scorecard!$E$21+I9*Scorecard!$E$22+J9*Scorecard!$E$23 -> 3.4073337 | M9: =IF(AND(T9>=U9,T9>=V9),"A. Distribution",IF(U9>=V9,"B. Manufacturing","C. Prof. services")) -> A. Distribution | N9: 0.31741622 | O9: 0.17063324 | P9: 0.20384882 | Q9: 0.17361758 | R9: 0.068365804 | S9: 0.066118349 | T9: =N9*Scorecard!$C$18+O9*Scorecard!$C$19+P9*Scorecard!$C$20+Q9*Scorecard!$C$21+R9*Scorecard!$C$22+S9*Scorecard!$C$23 -> 3.9942048 | U9: =N9*Scorecard!$D$18+O9*Scorecard!$D$19+P9*Scorecard!$D$20+Q9*Scorecard!$D$21+R9*Scorecard!$D$22+S9*Scorecard!$D$23 -> 2.8414784 | V9: =N9*Scorecard!$E$18+O9*Scorecard!$E$19+P9*Scorecard!$E$20+Q9*Scorecard!$E$21+R9*Scorecard!$E$22+S9*Scorecard!$E$23 -> 3.4996416
A10: 5 | B10: =E10*Scorecard!$C$18+F10*Scorecard!$C$19+G10*Scorecard!$C$20+H10*Scorecard!$C$21+I10*Scorecard!$C$22+J10*Scorecard!$C$23 -> 3.5889726 | C10: =E10*Scorecard!$D$18+F10*Scorecard!$D$19+G10*Scorecard!$D$20+H10*Scorecard!$D$21+I10*Scorecard!$D$22+J10*Scorecard!$D$23 -> 2.5944506 | D10: =IF(AND(B10>=C10,B10>=K10),"A. Distribution",IF(C10>=K10,"B. Manufacturing","C. Prof. services")) -> C. Prof. services | E10: 0.26569465 | F10: 0.16898194 | G10: 0.18366167 | H10: 0.03122767 | I10: 0.072777691 | J10: 0.27765637 | K10: =E10*Scorecard!$E$18+F10*Scorecard!$E$19+G10*Scorecard!$E$20+H10*Scorecard!$E$21+I10*Scorecard!$E$22+J10*Scorecard!$E$23 -> 3.6724644 | M10: =IF(AND(T10>=U10,T10>=V10),"A. Distribution",IF(U10>=V10,"B. Manufacturing","C. Prof. services")) -> A. Distribution | N10: 0.29034756 | O10: 0.20102762 | P10: 0.12250079 | Q10: 0.14603025 | R10: 0.18041383 | S10: 0.059679951 | T10: =N10*Scorecard!$C$18+O10*Scorecard!$C$19+P10*Scorecard!$C$20+Q10*Scorecard!$C$21+R10*Scorecard!$C$22+S10*Scorecard!$C$23 -> 4.0426218 | U10: =N10*Scorecard!$D$18+O10*Scorecard!$D$19+P10*Scorecard!$D$20+Q10*Scorecard!$D$21+R10*Scorecard!$D$22+S10*Scorecard!$D$23 -> 2.947363 | V10: =N10*Scorecard!$E$18+O10*Scorecard!$E$19+P10*Scorecard!$E$20+Q10*Scorecard!$E$21+R10*Scorecard!$E$22+S10*Scorecard!$E$23 -> 3.2958955
A11: 6 | B11: =E11*Scorecard!$C$18+F11*Scorecard!$C$19+G11*Scorecard!$C$20+H11*Scorecard!$C$21+I11*Scorecard!$C$22+J11*Scorecard!$C$23 -> 3.9795379 | C11: =E11*Scorecard!$D$18+F11*Scorecard!$D$19+G11*Scorecard!$D$20+H11*Scorecard!$D$21+I11*Scorecard!$D$22+J11*Scorecard!$D$23 -> 2.4915676 | D11: =IF(AND(B11>=C11,B11>=K11),"A. Distribution",IF(C11>=K11,"B. Manufacturing","C. Prof. services")) -> A. Distribution | E11: 0.1049933 | F11: 0.3414973 | G11: 0.19138295 | H11: 0.064271473 | I11: 0.12455273 | J11: 0.17330225 | K11: =E11*Scorecard!$E$18+F11*Scorecard!$E$19+G11*Scorecard!$E$20+H11*Scorecard!$E$21+I11*Scorecard!$E$22+J11*Scorecard!$E$23 -> 3.3973088 | M11: =IF(AND(T11>=U11,T11>=V11),"A. Distribution",IF(U11>=V11,"B. Manufacturing","C. Prof. services")) -> A. Distribution | N11: 0.20683211 | O11: 0.19502688 | P11: 0.08979259 | Q11: 0.099858159 | R11: 0.22065779 | S11: 0.18783248 | T11: =N11*Scorecard!$C$18+O11*Scorecard!$C$19+P11*Scorecard!$C$20+Q11*Scorecard!$C$21+R11*Scorecard!$C$22+S11*Scorecard!$C$23 -> 3.7919963 | U11: =N11*Scorecard!$D$18+O11*Scorecard!$D$19+P11*Scorecard!$D$20+Q11*Scorecard!$D$21+R11*Scorecard!$D$22+S11*Scorecard!$D$23 -> 2.7512908 | V11: =N11*Scorecard!$E$18+O11*Scorecard!$E$19+P11*Scorecard!$E$20+Q11*Scorecard!$E$21+R11*Scorecard!$E$22+S11*Scorecard!$E$23 -> 3.35693
A12: 7 | B12: =E12*Scorecard!$C$18+F12*Scorecard!$C$19+G12*Scorecard!$C$20+H12*Scorecard!$C$21+I12*Scorecard!$C$22+J12*Scorecard!$C$23 -> 3.4482429 | C12: =E12*Scorecard!$D$18+F12*Scorecard!$D$19+G12*Scorecard!$D$20+H12*Scorecard!$D$21+I12*Scorecard!$D$22+J12*Scorecard!$D$23 -> 2.4458494 | D12: =IF(AND(B12>=C12,B12>=K12),"A. Distribution",IF(C12>=K12,"B. Manufacturing","C. Prof. services")) -> C. Prof. services | E12: 0.075300119 | F12: 0.070499131 | G12: 0.19248388 | H12: 0.065031968 | I12: 0.29208321 | J12: 0.30460169 | K12: =E12*Scorecard!$E$18+F12*Scorecard!$E$19+G12*Scorecard!$E$20+H12*Scorecard!$E$21+I12*Scorecard!$E$22+J12*Scorecard!$E$23 -> 3.5222894 | M12: =IF(AND(T12>=U12,T12>=V12),"A. Distribution",IF(U12>=V12,"B. Manufacturing","C. Prof. services")) -> A. Distribution | N12: 0.30896046 | O12: 0.16951686 | P12: 0.07640421 | Q12: 0.11191901 | R12: 0.082079583 | S12: 0.25111988 | T12: =N12*Scorecard!$C$18+O12*Scorecard!$C$19+P12*Scorecard!$C$20+Q12*Scorecard!$C$21+R12*Scorecard!$C$22+S12*Scorecard!$C$23 -> 3.6304123 | U12: =N12*Scorecard!$D$18+O12*Scorecard!$D$19+P12*Scorecard!$D$20+Q12*Scorecard!$D$21+R12*Scorecard!$D$22+S12*Scorecard!$D$23 -> 2.7315292 | V12: =N12*Scorecard!$E$18+O12*Scorecard!$E$19+P12*Scorecard!$E$20+Q12*Scorecard!$E$21+R12*Scorecard!$E$22+S12*Scorecard!$E$23 -> 3.5950282
A13: 8 | B13: =E13*Scorecard!$C$18+F13*Scorecard!$C$19+G13*Scorecard!$C$20+H13*Scorecard!$C$21+I13*Scorecard!$C$22+J13*Scorecard!$C$23 -> 3.8573506 | C13: =E13*Scorecard!$D$18+F13*Scorecard!$D$19+G13*Scorecard!$D$20+H13*Scorecard!$D$21+I13*Scorecard!$D$22+J13*Scorecard!$D$23 -> 2.7892798 | D13: =IF(AND(B13>=C13,B13>=K13),"A. Distribution",IF(C13>=K13,"B. Manufacturing","C. Prof. services")) -> A. Distribution | E13: 0.21477172 | F13: 0.014467919 | G13: 0.22467435 | H13: 0.26831296 | I13: 0.22229147 | J13: 0.055481578 | K13: =E13*Scorecard!$E$18+F13*Scorecard!$E$19+G13*Scorecard!$E$20+H13*Scorecard!$E$21+I13*Scorecard!$E$22+J13*Scorecard!$E$23 -> 3.4448078 | M13: =IF(AND(T13>=U13,T13>=V13),"A. Distribution",IF(U13>=V13,"B. Manufacturing","C. Prof. services")) -> A. Distribution | N13: 0.087948822 | O13: 0.12168966 | P13: 0.21896484 | Q13: 0.14822487 | R13: 0.28867256 | S13: 0.13449925 | T13: =N13*Scorecard!$C$18+O13*Scorecard!$C$19+P13*Scorecard!$C$20+Q13*Scorecard!$C$21+R13*Scorecard!$C$22+S13*Scorecard!$C$23 -> 3.8296587 | U13: =N13*Scorecard!$D$18+O13*Scorecard!$D$19+P13*Scorecard!$D$20+Q13*Scorecard!$D$21+R13*Scorecard!$D$22+S13*Scorecard!$D$23 -> 2.6033823 | V13: =N13*Scorecard!$E$18+O13*Scorecard!$E$19+P13*Scorecard!$E$20+Q13*Scorecard!$E$21+R13*Scorecard!$E$22+S13*Scorecard!$E$23 -> 3.3481939
A14: 9 | B14: =E14*Scorecard!$C$18+F14*Scorecard!$C$19+G14*Scorecard!$C$20+H14*Scorecard!$C$21+I14*Scorecard!$C$22+J14*Scorecard!$C$23 -> 2.9369468 | C14: =E14*Scorecard!$D$18+F14*Scorecard!$D$19+G14*Scorecard!$D$20+H14*Scorecard!$D$21+I14*Scorecard!$D$22+J14*Scorecard!$D$23 -> 2.131774 | D14: =IF(AND(B14>=C14,B14>=K14),"A. Distribution",IF(C14>=K14,"B. Manufacturing","C. Prof. services")) -> C. Prof. services | E14: 0.1368838 | F14: 0.070688694 | G14: 0.15114102 | H14: 0.0090164033 | I14: 0.071379856 | J14: 0.56089023 | K14: =E14*Scorecard!$E$18+F14*Scorecard!$E$19+G14*Scorecard!$E$20+H14*Scorecard!$E$21+I14*Scorecard!$E$22+J14*Scorecard!$E$23 -> 4.0055828 | M14: =IF(AND(T14>=U14,T14>=V14),"A. Distribution",IF(U14>=V14,"B. Manufacturing","C. Prof. services")) -> A. Distribution | N14: 0.17381845 | O14: 0.2980282 | P14: 0.15626579 | Q14: 0.27532167 | R14: 0.087954229 | S14: 0.0086116572 | T14: =N14*Scorecard!$C$18+O14*Scorecard!$C$19+P14*Scorecard!$C$20+Q14*Scorecard!$C$21+R14*Scorecard!$C$22+S14*Scorecard!$C$23 -> 4.2371835 | U14: =N14*Scorecard!$D$18+O14*Scorecard!$D$19+P14*Scorecard!$D$20+Q14*Scorecard!$D$21+R14*Scorecard!$D$22+S14*Scorecard!$D$23 -> 2.7030252 | V14: =N14*Scorecard!$E$18+O14*Scorecard!$E$19+P14*Scorecard!$E$20+Q14*Scorecard!$E$21+R14*Scorecard!$E$22+S14*Scorecard!$E$23 -> 3.3244839
A15: 10 | B15: =E15*Scorecard!$C$18+F15*Scorecard!$C$19+G15*Scorecard!$C$20+H15*Scorecard!$C$21+I15*Scorecard!$C$22+J15*Scorecard!$C$23 -> 3.9896383 | C15: =E15*Scorecard!$D$18+F15*Scorecard!$D$19+G15*Scorecard!$D$20+H15*Scorecard!$D$21+I15*Scorecard!$D$22+J15*Scorecard!$D$23 -> 3.5555495 | D15: =IF(AND(B15>=C15,B15>=K15),"A. Distribution",IF(C15>=K15,"B. Manufacturing","C. Prof. services")) -> A. Distribution | E15: 0.6970883 | F15: 0.098313257 | G15: 0.049552761 | H15: 0.069391428 | I15: 0.063038739 | J15: 0.022615511 | K15: =E15*Scorecard!$E$18+F15*Scorecard!$E$19+G15*Scorecard!$E$20+H15*Scorecard!$E$21+I15*Scorecard!$E$22+J15*Scorecard!$E$23 -> 3.4174752 | M15: =IF(AND(T15>=U15,T15>=V15),"A. Distribution",IF(U15>=V15,"B. Manufacturing","C. Prof. services")) -> A. Distribution | N15: 0.17895079 | O15: 0.068043263 | P15: 0.26205798 | Q15: 0.14468831 | R15: 0.2717372 | S15: 0.074522457 | T15: =N15*Scorecard!$C$18+O15*Scorecard!$C$19+P15*Scorecard!$C$20+Q15*Scorecard!$C$21+R15*Scorecard!$C$22+S15*Scorecard!$C$23 -> 3.8890407 | U15: =N15*Scorecard!$D$18+O15*Scorecard!$D$19+P15*Scorecard!$D$20+Q15*Scorecard!$D$21+R15*Scorecard!$D$22+S15*Scorecard!$D$23 -> 2.7654611 | V15: =N15*Scorecard!$E$18+O15*Scorecard!$E$19+P15*Scorecard!$E$20+Q15*Scorecard!$E$21+R15*Scorecard!$E$22+S15*Scorecard!$E$23 -> 3.3662173
A16: 11 | B16: =E16*Scorecard!$C$18+F16*Scorecard!$C$19+G16*Scorecard!$C$20+H16*Scorecard!$C$21+I16*Scorecard!$C$22+J16*Scorecard!$C$23 -> 3.8025081 | C16: =E16*Scorecard!$D$18+F16*Scorecard!$D$19+G16*Scorecard!$D$20+H16*Scorecard!$D$21+I16*Scorecard!$D$22+J16*Scorecard!$D$23 -> 2.4957772 | D16: =IF(AND(B16>=C16,B16>=K16),"A. Distribution",IF(C16>=K16,"B. Manufacturing","C. Prof. services")) -> A. Distribution | E16: 0.083151101 | F16: 0.10560389 | G16: 0.11573256 | H16: 0.40756241 | I16: 0.16169764 | J16: 0.12625241 | K16: =E16*Scorecard!$E$18+F16*Scorecard!$E$19+G16*Scorecard!$E$20+H16*Scorecard!$E$21+I16*Scorecard!$E$22+J16*Scorecard!$E$23 -> 3.4925046 | M16: =IF(AND(T16>=U16,T16>=V16),"A. Distribution",IF(U16>=V16,"B. Manufacturing","C. Prof. services")) -> A. Distribution | N16: 0.10327881 | O16: 0.23733956 | P16: 0.15695874 | Q16: 0.20759181 | R16: 0.095117239 | S16: 0.19971385 | T16: =N16*Scorecard!$C$18+O16*Scorecard!$C$19+P16*Scorecard!$C$20+Q16*Scorecard!$C$21+R16*Scorecard!$C$22+S16*Scorecard!$C$23 -> 3.8072518 | U16: =N16*Scorecard!$D$18+O16*Scorecard!$D$19+P16*Scorecard!$D$20+Q16*Scorecard!$D$21+R16*Scorecard!$D$22+S16*Scorecard!$D$23 -> 2.4223502 | V16: =N16*Scorecard!$E$18+O16*Scorecard!$E$19+P16*Scorecard!$E$20+Q16*Scorecard!$E$21+R16*Scorecard!$E$22+S16*Scorecard!$E$23 -> 3.5380674
A17: 12 | B17: =E17*Scorecard!$C$18+F17*Scorecard!$C$19+G17*Scorecard!$C$20+H17*Scorecard!$C$21+I17*Scorecard!$C$22+J17*Scorecard!$C$23 -> 3.452366 | C17: =E17*Scorecard!$D$18+F17*Scorecard!$D$19+G17*Scorecard!$D$20+H17*Scorecard!$D$21+I17*Scorecard!$D$22+J17*Scorecard!$D$23 -> 2.5831118 | D17: =IF(AND(B17>=C17,B17>=K17),"A. Distribution",IF(C17>=K17,"B. Manufacturing","C. Prof. services")) -> C. Prof. services | E17: 0.21892579 | F17: 0.1243123 | G17: 0.0093264104 | H17: 0.20069643 | I17: 0.13036693 | J17: 0.31637214 | K17: =E17*Scorecard!$E$18+F17*Scorecard!$E$19+G17*Scorecard!$E$20+H17*Scorecard!$E$21+I17*Scorecard!$E$22+J17*Scorecard!$E$23 -> 3.6171925 | M17: =IF(AND(T17>=U17,T17>=V17),"A. Distribution",IF(U17>=V17,"B. Manufacturing","C. Prof. services")) -> A. Distribution | N17: 0.16928092 | O17: 0.15518283 | P17: 0.27369464 | Q17: 0.18650245 | R17: 0.084814438 | S17: 0.13052473 | T17: =N17*Scorecard!$C$18+O17*Scorecard!$C$19+P17*Scorecard!$C$20+Q17*Scorecard!$C$21+R17*Scorecard!$C$22+S17*Scorecard!$C$23 -> 3.8604466 | U17: =N17*Scorecard!$D$18+O17*Scorecard!$D$19+P17*Scorecard!$D$20+Q17*Scorecard!$D$21+R17*Scorecard!$D$22+S17*Scorecard!$D$23 -> 2.5270598 | V17: =N17*Scorecard!$E$18+O17*Scorecard!$E$19+P17*Scorecard!$E$20+Q17*Scorecard!$E$21+R17*Scorecard!$E$22+S17*Scorecard!$E$23 -> 3.5927529
... A1005: 1000 | B1005: =E1005*Scorecard!$C$18+F1005*Scorecard!$C$19+G1005*Scorecard!$C$20+H1005*Scorecard!$C$21+I1005*Scorecard!$C$22+J1005*Scorecard!$C$23 -> 3.9552017 | C1005: =E1005*Scorecard!$D$18+F1005*Scorecard!$D$19+G1005*Scorecard!$D$20+H1005*Scorecard!$D$21+I1005*Scorecard!$D$22+J1005*Scorecard!$D$23 -> 2.7914269 | D1005: =IF(AND(B1005>=C1005,B1005>=K1005),"A. Distribution",IF(C1005>=K1005,"B. Manufacturing","C. Prof. services")) -> A. Distribution | E1005: 0.27023297 | F1005: 0.3003591 | G1005: 0.072364428 | H1005: 0.099786185 | I1005: 0.10090268 | J1005: 0.15635464 | K1005: =E1005*Scorecard!$E$18+F1005*Scorecard!$E$19+G1005*Scorecard!$E$20+H1005*Scorecard!$E$21+I1005*Scorecard!$E$22+J1005*Scorecard!$E$23 -> 3.383194 | M1005: =IF(AND(T1005>=U1005,T1005>=V1005),"A. Distribution",IF(U1005>=V1005,"B. Manufacturing","C. Prof. services")) -> A. Distribution | N1005: 0.23173386 | O1005: 0.10688613 | P1005: 0.15149844 | Q1005: 0.24610113 | R1005: 0.22022994 | S1005: 0.043550508 | T1005: =N1005*Scorecard!$C$18+O1005*Scorecard!$C$19+P1005*Scorecard!$C$20+Q1005*Scorecard!$C$21+R1005*Scorecard!$C$22+S1005*Scorecard!$C$23 -> 3.9746624 | U1005: =N1005*Scorecard!$D$18+O1005*Scorecard!$D$19+P1005*Scorecard!$D$20+Q1005*Scorecard!$D$21+R1005*Scorecard!$D$22+S1005*Scorecard!$D$23 -> 2.8692897 | V1005: =N1005*Scorecard!$E$18+O1005*Scorecard!$E$19+P1005*Scorecard!$E$20+Q1005*Scorecard!$E$21+R1005*Scorecard!$E$22+S1005*Scorecard!$E$23 -> 3.3305837

Sheet Stress_Tests
A1: Stress tests — uncertain inputs and scoring choices (base weights)
A2: Each test changes the yellow input(s) only; everything else is linked to Inputs. Summary at top; full blocks below (metric rows are shown so every change is visible).
A4: Test | B4: What changes | C4: A. Industrial Distribution | D4: B. Industrial Manufacturing | E4: C. B2B Prof. Services | F4: Winner | G4: Margin
A5: T0 Base case | B5: Nothing (reproduces Scorecard) | C5: =C39 -> 3.9677801 | D5: =D39 -> 2.7044653 | E5: =E39 -> 3.41185 | F5: =INDEX($C$4:$E$4,MATCH(MAX(C5:E5),C5:E5,0)) -> A. Industrial Distribution | G5: =MAX(C5:E5)-LARGE(C5:E5,2) -> 0.55593004
A6: T1 Partner channel works | B6: Distribution ease of execution 2.0 → 3.5 (templates + partners close half the gap) | C6: =C63 -> 4.1177801 | D6: =D63 -> 2.7044653 | E6: =E63 -> 3.41185 | F6: =INDEX($C$4:$E$4,MATCH(MAX(C6:E6),C6:E6,0)) -> A. Industrial Distribution | G6: =MAX(C6:E6)-LARGE(C6:E6,2) -> 0.70593004
A7: T2 Prof. services headroom larger | B7: Prof. services headroom flag 2 → 4 (Clay less penetrated than assumed) | C7: =C87 -> 3.9677801 | D7: =D87 -> 2.7044653 | E7: =E87 -> 3.61185 | F7: =INDEX($C$4:$E$4,MATCH(MAX(C7:E7),C7:E7,0)) -> A. Industrial Distribution | G7: =MAX(C7:E7)-LARGE(C7:E7,2) -> 0.35593004
A8: T3 No data gap (H3 proxy wrong) | B8: Distribution persona coverage index 0.62 → 1.00 (standard databases cover contractors) | C8: =C111 -> 3.9559441 | D8: =D111 -> 2.8483921 | E8: =E111 -> 3.551518 | F8: =INDEX($C$4:$E$4,MATCH(MAX(C8:E8),C8:E8,0)) -> A. Industrial Distribution | G8: =MAX(C8:E8)-LARGE(C8:E8,2) -> 0.40442604
A9: T4 Seller density doesn't lift ACV | B9: Revenue Potential = 100% SOM ARR (no account-expansion credit) | C9: =C135 -> 3.8016175 | D9: =D135 -> 2.8192447 | E9: =E135 -> 3.6109114 | F9: =INDEX($C$4:$E$4,MATCH(MAX(C9:E9),C9:E9,0)) -> A. Industrial Distribution | G9: =MAX(C9:E9)-LARGE(C9:E9,2) -> 0.19070608
A10: T5 ERP gap binds | B10: Distribution PMF 4 → 3 | C10: =C159 -> 3.7677801 | D10: =D159 -> 2.7044653 | E10: =E159 -> 3.41185 | F10: =INDEX($C$4:$E$4,MATCH(MAX(C10:E10),C10:E10,0)) -> A. Industrial Distribution | G10: =MAX(C10:E10)-LARGE(C10:E10,2) -> 0.35593004
A11: T6 Apollo/HubSpot close local-data gap | B11: Distribution competitive position 4.0 → 3.0 | C11: =C183 -> 3.8177801 | D11: =D183 -> 2.7044653 | E11: =E183 -> 3.41185 | F11: =INDEX($C$4:$E$4,MATCH(MAX(C11:E11),C11:E11,0)) -> A. Industrial Distribution | G11: =MAX(C11:E11)-LARGE(C11:E11,2) -> 0.40593004
A12: T7 Distribution combined downside | B12: T3 + T5 + T6 together | C12: =C207 -> 3.6059441 | D12: =D207 -> 2.8483921 | E12: =E207 -> 3.551518 | F12: =INDEX($C$4:$E$4,MATCH(MAX(C12:E12),C12:E12,0)) -> A. Industrial Distribution | G12: =MAX(C12:E12)-LARGE(C12:E12,2) -> 0.054426042
A13: T8 Prof. services best case | B13: PS headroom 4, competitive position 3.0, ease 5.0 | C13: =C231 -> 3.9677801 | D13: =D231 -> 2.7044653 | E13: =E231 -> 3.761855 | F13: =INDEX($C$4:$E$4,MATCH(MAX(C13:E13),C13:E13,0)) -> A. Industrial Distribution | G13: =MAX(C13:E13)-LARGE(C13:E13,2) -> 0.20592504
A14: T9 Worst case for A + best case for C | B14: T7 + T8 together | C14: =C255 -> 3.6059441 | D14: =D255 -> 2.8483921 | E14: =E255 -> 3.901523 | F14: =INDEX($C$4:$E$4,MATCH(MAX(C14:E14),C14:E14,0)) -> C. B2B Prof. Services | G14: =MAX(C14:E14)-LARGE(C14:E14,2) -> 0.29557896
A15: T10 Market size only (no headroom) | B15: Market Attractiveness = 100% SAM | C15: =C279 -> 3.7517227 | D15: =D279 -> 2.5091309 | E15: =E279 -> 3.71185 | F15: =INDEX($C$4:$E$4,MATCH(MAX(C15:E15),C15:E15,0)) -> A. Industrial Distribution | G15: =MAX(C15:E15)-LARGE(C15:E15,2) -> 0.039872688
A16: T11 Min-max normalization | B16: Quantitative metrics scaled min-max instead of ratio-to-max (exaggerates gaps) | C16: =C303 -> 3.65 | D16: =D303 -> 2.0953285 | E16: =E303 -> 3.0921628 | F16: =INDEX($C$4:$E$4,MATCH(MAX(C16:E16),C16:E16,0)) -> A. Industrial Distribution | G16: =MAX(C16:E16)-LARGE(C16:E16,2) -> 0.55783716
A18: Detail blocks follow. In each block the winner formula reads segment names from row 4.
A20: T0 Base case — Nothing (reproduces Scorecard)
A21: M1 SAM, Base case | B21: input | C21: =Inputs!D5 -> 68163347 | D21: =Inputs!E5 -> 75842617 | E21: =Inputs!F5 -> 1.4822739e+08
A22: M2 Incremental headroom flag (5 = largely unpenetrated by Clay) | B22: input | C22: =Inputs!D6 -> 5 | D22: =Inputs!E6 -> 5 | E22: =Inputs!F6 -> 2
A23: M3 Sales intensity index (sales occupations share ÷ all industries) | B23: input | C23: =Inputs!D7 -> 2.54356 | D23: =Inputs!E7 -> 0.31725 | E23: =Inputs!F7 -> 0.71487
A24: M4 Customer-persona LinkedIn coverage index vs Prof. services | B24: input | C24: =Inputs!D8 -> 0.62124 | D24: =Inputs!E8 -> 0.97041 | E24: =Inputs!F8 -> 1
A25: M5 Product-market fit (judgment; see Scorecard evidence) | B25: input | C25: =Inputs!D9 -> 4 | D25: =Inputs!E9 -> 2 | E25: =Inputs!F9 -> 4
A26: M6 SOM — year-3 ARR potential, Base case | B26: input | C26: =Inputs!D10 -> 1864123.6 | D26: =Inputs!E10 -> 2149272.5 | E26: =Inputs!F10 -> 4178480.9
A27: M7 Implied sales staff per 20+ firm (usage / expansion driver) | B27: input | C27: =Inputs!D11 -> 27.7 | D27: =Inputs!E11 -> 3.65 | E27: =Inputs!F11 -> 9.32
A28: M8 Competitive position score | B28: input | C28: =Inputs!D12 -> 4 | D28: =Inputs!E12 -> 3.3333 | E28: =Inputs!F12 -> 2.3333
A29: M9 Adoption / execution fit score | B29: input | C29: =Inputs!D13 -> 2 | D29: =Inputs!E13 -> 1.5 | E29: =Inputs!F13 -> 4.5
A30: Sub-weight: Market Attractiveness (share on SAM size) | B30: sub-weight | C30: =Weights!$G$14 -> 0.5
A31: Sub-weight: Customer Need (share on sales intensity) | B31: sub-weight | C31: =Weights!$G$15 -> 0.5
A32: Sub-weight: Revenue Potential (share on SOM ARR) | B32: sub-weight | C32: =Weights!$G$16 -> 0.5
A33: Score — Market Attractiveness | B33: 1–5 | C33: =$C$30*(1+4*C21/MAX($C$21:$E$21))+(1-$C$30)*C22 -> 3.9197132 | D33: =$C$30*(1+4*D21/MAX($C$21:$E$21))+(1-$C$30)*D22 -> 4.023328 | E33: =$C$30*(1+4*E21/MAX($C$21:$E$21))+(1-$C$30)*E22 -> 3.5
A34: Score — Customer Need | B34: 1–5 | C34: =$C$31*(1+4*C23/MAX($C$23:$E$23))+(1-$C$31)*(1+4*MIN($C$24:$E$24)/C24) -> 5 | D34: =$C$31*(1+4*D23/MAX($C$23:$E$23))+(1-$C$31)*(1+4*MIN($C$24:$E$24)/D24) -> 2.5298196 | E34: =$C$31*(1+4*E23/MAX($C$23:$E$23))+(1-$C$31)*(1+4*MIN($C$24:$E$24)/E24) -> 2.8045819
A35: Score — Product-Market Fit | B35: 1–5 | C35: =C25 -> 4 | D35: =D25 -> 2 | E35: =E25 -> 4
A36: Score — Revenue Potential | B36: 1–5 | C36: =$C$32*(1+4*C26/MAX($C$26:$E$26))+(1-$C$32)*(1+4*C27/MAX($C$27:$E$27)) -> 3.8922494 | D36: =$C$32*(1+4*D26/MAX($C$26:$E$26))+(1-$C$32)*(1+4*D27/MAX($C$27:$E$27)) -> 2.2922718 | E36: =$C$32*(1+4*E26/MAX($C$26:$E$26))+(1-$C$32)*(1+4*E27/MAX($C$27:$E$27)) -> 3.6729242
A37: Score — Competitive Position | B37: 1–5 | C37: =C28 -> 4 | D37: =D28 -> 3.3333 | E37: =E28 -> 2.3333
A38: Score — Ease of Execution | B38: 1–5 | C38: =C29 -> 2 | D38: =D29 -> 1.5 | E38: =E29 -> 4.5
A39: Weighted total score | B39: 1–5 | C39: =SUMPRODUCT(Weights!$B$5:$B$10,C33:C38) -> 3.9677801 | D39: =SUMPRODUCT(Weights!$B$5:$B$10,D33:D38) -> 2.7044653 | E39: =SUMPRODUCT(Weights!$B$5:$B$10,E33:E38) -> 3.41185
A40: Rank | C40: =RANK(C39,$C$39:$E$39) -> 1 | D40: =RANK(D39,$C$39:$E$39) -> 3 | E40: =RANK(E39,$C$39:$E$39) -> 2
A41: Winner / margin over runner-up | C41: =INDEX($C$4:$E$4,MATCH(MAX(C39:E39),C39:E39,0)) -> A. Industrial Distribution | D41: =MAX(C39:E39)-LARGE(C39:E39,2) -> 0.55593004
A44: T1 Partner channel works — Distribution ease of execution 2.0 → 3.5 (templates + partners close half the gap)
A45: M1 SAM, Base case | B45: input | C45: =Inputs!D5 -> 68163347 | D45: =Inputs!E5 -> 75842617 | E45: =Inputs!F5 -> 1.4822739e+08
...

Sheet Subsegment_Drilldown
A1: Within distribution — which sub-industry is the beachhead?
A2: Census 2022 inputs [A] (Raw: appendix/raw_census_ecnsize_2022_firm_size.csv); judgment scores [C] in yellow. Same ratio-to-max scoring rule.
A4: Metric | B4: Weight | C4: 4235 Metals & minerals | D4: 4236 Electrical & electronic | E4: 4237 Hardware, plumbing & HVAC | F4: 4238 Machinery, equipment & supplies | G4: Basis
A5: Firms with 20+ employees (incl. imputed 4235 bands) | C5: 1268 | D5: 2578 | E5: 1821 | F5: 6009 | G5: 02_Market_Sizing › Firm_Counts (before cross-industry de-dup)
A6: Establishments per firm (all full-year firms) | C6: 1.423 | D6: 1.64 | E6: 2.213 | F6: 1.574 | G6: Census EC2200SIZEEMPFIRM (S14)
A7: Avg receipts per firm, 20–99 employees ($M) | C7: 87.6 | D7: 44.3 | E7: 32.2 | F7: 34.1 | G7: Census (S14); 4235 uses 20–49 band only (50–99 suppressed)
A8: Customer-persona data-gap relevance (judgment, 1–5) | C8: 2 | D8: 5 | E8: 5 | F8: 4 | G8: 4236/4237 sell to electrical and PHVAC contractors (est. ~19–22% LinkedIn use, 04 Persona_Coverage); 4238 mixes plant MRO (maintenance workers ~20%) with dealers; 4235 sells mainly to fabricators and manufacturers (white-collar purchasing)
A9: Published Clay reference in sub-industry (1 = none, 5 = yes) | C9: 1 | D9: 5 | E9: 1 | F9: 1 | G9: Regency Supply = commercial lighting & electrical distributor (S07)
A11: Score (1–5) | B11: Weight | C11: 4235 | D11: 4236 | E11: 4237 | F11: 4238 | G11: Rule
A12: Size | B12: 0.2 | C12: =1+4*C5/MAX($C$5:$F$5) -> 1.8440672 | D12: =1+4*D5/MAX($C$5:$F$5) -> 2.7160925 | E12: =1+4*E5/MAX($C$5:$F$5) -> 2.2121817 | F12: =1+4*F5/MAX($C$5:$F$5) -> 5 | G12: 1 + 4 × value ÷ max
A13: Branch / territory intensity | B13: 0.15 | C13: =1+4*C6/MAX($C$6:$F$6) -> 3.5720741 | D13: =1+4*D6/MAX($C$6:$F$6) -> 3.9643019 | E13: =1+4*E6/MAX($C$6:$F$6) -> 5 | F13: =1+4*F6/MAX($C$6:$F$6) -> 3.8450068 | G13: 1 + 4 × value ÷ max
A14: Ability to pay | B14: 0.15 | C14: =1+4*C7/MAX($C$7:$F$7) -> 5 | D14: =1+4*D7/MAX($C$7:$F$7) -> 3.0228311 | E14: =1+4*E7/MAX($C$7:$F$7) -> 2.4703196 | F14: =1+4*F7/MAX($C$7:$F$7) -> 2.5570776 | G14: 1 + 4 × value ÷ max
A15: Data-gap relevance (H3) | B15: 0.35 | C15: =C8 -> 2 | D15: =D8 -> 5 | E15: =E8 -> 5 | F15: =F8 -> 4 | G15: Judgment score used directly
A16: Reference proof | B16: 0.15 | C16: =C9 -> 1 | D16: =D9 -> 5 | E16: =E9 -> 1 | F16: =F9 -> 1 | G16: Judgment score used directly
A17: Weighted score | B17: =SUM(B12:B16) -> 1 | C17: =SUMPRODUCT($B$12:$B$16,C12:C16) -> 2.5046246 | D17: =SUMPRODUCT($B$12:$B$16,D12:D16) -> 4.0912884 | E17: =SUMPRODUCT($B$12:$B$16,E12:E16) -> 3.4629843 | F17: =SUMPRODUCT($B$12:$B$16,F12:F16) -> 3.5103127
A18: Rank | C18: =RANK(C17,$C$17:$F$17) -> 4 | D18: =RANK(D17,$C$17:$F$17) -> 1 | E18: =RANK(E17,$C$17:$F$17) -> 3 | F18: =RANK(F17,$C$17:$F$17) -> 2
A19: Rank without the Regency reference (reference weight → 0, rescaled) | C19: =SUMPRODUCT($B$12:$B$15,C12:C15)/SUM($B$12:$B$15) -> 2.7701465 | D19: =SUMPRODUCT($B$12:$B$15,D12:D15)/SUM($B$12:$B$15) -> 3.9309276 | E19: =SUMPRODUCT($B$12:$B$15,E12:E15)/SUM($B$12:$B$15) -> 3.8976286 | F19: =SUMPRODUCT($B$12:$B$15,F12:F15)/SUM($B$12:$B$15) -> 3.953309
A20: Rank (no-reference variant) | C20: =RANK(C19,$C$19:$F$19) -> 4 | D20: =RANK(D19,$C$19:$F$19) -> 2 | E20: =RANK(E19,$C$19:$F$19) -> 3 | F20: =RANK(F19,$C$19:$F$19) -> 1
A22: Reading: electrical distributors (4236) are the strongest beachhead. They combine contractor-facing buyers (largest data gap), multi-branch territories, healthy revenue per firm and the only published Clay proof point. PHVAC (4237) and machinery/MRO (4238) are the natural expansion waves. Without the Regency reference, 4236, 4237 and 4238 are close, so the beachhead choice partly rests on having a proof point to reuse. Metals service centers (4235) rank last because their buyers are white-collar purchasing teams already covered by standard data.

Sheet Options_Tradeoffs
A1: Strategic options — what we recommend, what we reject, and why
A2: Options from 01_Project_Charter §4. Recommendation is labeled [E]; Phase 4 tests its economics and Phase 5 designs it.
A4: # | B4: Option | C4: Score evidence | D4: Main upside | E4: Main risk / trade-off | F4: Reversibility | G4: Verdict
A5: 0 | B5: No vertical bet: keep horizontal, persona-led growth | C5: Comparison baseline. | D5: Zero incremental cost; focus stays on Clay's fast-growing core. | E5: Distribution's need does not get served: Clay's detected base is ~40% software, there are no industrial partners, and the marketplace expansion skipped industrials. The gap persists or a specialist fills it. | F5: Fully | G5: Rejected for distribution; retained for prof. services, which the horizontal motion already serves
