Workbook

Sheet Cover
A1: 07 — Financial Model: three-year business case for a U.S. industrial-distribution pilot
A2: Independent portfolio case study by Zhuoran (Zora) Wang · Not commissioned by or affiliated with Clay Labs Inc. · Research reference date: 2026-10-18
A4: Question | B4: Does the Phase 3 recommendation (enter industrial distribution through a staged, partner-led pilot) create value over 2027–2029, and how should it be sized and gated?
A5: Structure | B5: Assumptions → Market Sizing → ACV Build → GTM Funnel → Revenue Model → Unit Economics (live model, selectors on Assumptions D4:D5) → Scenarios and Sensitivity (full model copies on Engine Runs) → Executive Output.
A6: Time and units | B6: Quarterly, Q1 2027–Q4 2029; annual totals in columns P–R and 2027–29 in S. US$ nominal. ARR is end-of-quarter run-rate; recognized revenue = average ARR ÷ 4 (kept separate).
A7: Scope of costs | B7: Incremental to Clay only: vertical team, variable sales cost, programs, partner fees, enablement, onboarding subsidies, template/connector build, customer success. COGS via gross margin. No allocation of Clay's existing overhead.
A8: Evidence classes | B8: A = verified public fact · B = external benchmark · C = analyst estimate · D = scenario assumption · E = recommendation. Every input row on Assumptions carries its class and source.
A9: Color legend | B9: Blue = input · black = formula · green = link to another tab · yellow fill = judgment assumption · green fill = key output.
A10: Not a forecast | B10: Outputs are scenario-based estimates. They are not Clay forecasts and imply no access to Clay internal financials. Probability weights in the decision analysis are explicit judgments.

Sheet Executive Output
A1: Executive Output — three-year business case for the distribution pilot (2027–2029)
A2: Scenario outputs are illustrative estimates built from public data and labeled assumptions. They are not Clay forecasts and do not use Clay internal data.
A3: ="Live model currently set to: "&Assumptions!$E$4&" · "&Assumptions!$E$5&" (change on Assumptions D4:D5)" -> Live model currently set to: Base · Partner-led pilot (change on Assumptions D4:D5)
A5: Metric | B5: Partner-led: Downside | C5: Partner-led: Downside, gated | D5: Partner-led: Base | E5: Partner-led: Upside | F5: Partner-led: Upside + scale-up | G5: Sales-led team: Base | H5: Note
A6: Exit ARR, Q4 2029 | B6: =Scenarios!D5 -> 60533.792 | C6: =Scenarios!E5 -> 6382.4703 | D6: =Scenarios!F5 -> 861203.84 | E6: =Scenarios!G5 -> 4372033.9 | F6: =Scenarios!H5 -> 6013068.7 | G6: =Scenarios!I5 -> 861203.84
A7: New customers 2027–29 | B7: =Scenarios!D7 -> 5.4867647 | C7: =Scenarios!E7 -> 0.61705718 | D7: =Scenarios!F7 -> 57.63577 | E7: =Scenarios!G7 -> 193.95499 | F7: =Scenarios!H7 -> 257.63071 | G7: =Scenarios!I7 -> 57.63577
A8: Average first-year ACV | B8: =Scenarios!D9 -> 11019.558 | C8: =Scenarios!E9 -> 10372.816 | D8: =Scenarios!F9 -> 13800.744 | E8: =Scenarios!G9 -> 18213.149 | F8: =Scenarios!H9 -> 19363.117 | G8: =Scenarios!I9 -> 13800.744 | H8: Usage-based build
A9: CAC | B9: =Scenarios!D10 -> 331930.67 | C9: =Scenarios!E10 -> 819865.25 | D9: =Scenarios!F10 -> 41115.536 | E9: =Scenarios!G10 -> 18950.649 | F9: =Scenarios!H10 -> 17982.905 | G9: =Scenarios!I10 -> 119895.93 | H9: Sales & marketing ÷ new customers
A10: CAC payback, 2027–29 average (months) | B10: =Scenarios!D11 -> 657.20636 | C10: =Scenarios!E11 -> 1724.5046 | D10: =Scenarios!F11 -> 55.001095 | E10: =Scenarios!G11 -> 17.341545 | F10: =Scenarios!H11 -> 15.478659 | G10: =Scenarios!I11 -> 160.38725 | H10: Benchmark median: SMB 8–12, MM 14–18 (S47)
A11: CAC payback, 2029 cohort (months) | B11: =Scenarios!D12 -> 444.95536 | C11: =Scenarios!E12 -> 0 | D11: =Scenarios!F12 -> 36.566752 | E11: =Scenarios!G12 -> 14.839987 | F11: =Scenarios!H12 -> 12.321919 | G11: =Scenarios!I12 -> 108.09951 | H11: Steady-state view after launch costs
A12: LTV : CAC | B12: =Scenarios!D13 -> 0.091295526 | C12: =Scenarios!E13 -> 0.0347926 | D12: =Scenarios!F13 -> 1.0908874 | E12: =Scenarios!G13 -> 3.4598993 | F12: =Scenarios!H13 -> 3.8763047 | G12: =Scenarios!I13 -> 0.37409458 | H12: >3x is the usual bar [K]
A13: Total incremental cost 2027–29 | B13: =Scenarios!D14 -> 2537039 | C13: =Scenarios!E14 -> 984681.44 | D13: =Scenarios!F14 -> 3208602.2 | E13: =Scenarios!G14 -> 4886302 | F13: =Scenarios!H14 -> 5981245.9 | G13: =Scenarios!I14 -> 7749171.1
A14: Cumulative program P&L 2027–29 | B14: =Scenarios!D15 -> -2502632.2 | C14: =Scenarios!E15 -> -977016.28 | D14: =Scenarios!F15 -> -2684074.4 | E14: =Scenarios!G15 -> -1575275 | F14: =Scenarios!H15 -> -1902658.5 | G14: =Scenarios!I15 -> -7224643.2
A15: Peak investment required | B15: =Scenarios!D16 -> -2502632.2 | C15: =Scenarios!E16 -> -981728.03 | D15: =Scenarios!F16 -> -2684074.4 | E15: =Scenarios!G16 -> -2016342.7 | F15: =Scenarios!H16 -> -2446003.1 | G15: =Scenarios!I16 -> -7224643.2 | H15: Lowest cumulative P&L
A16: Q4 2029 program P&L, annualized | B16: =Scenarios!D18 -> -734894.69 | C16: =Scenarios!E18 -> 2538.4117 | D16: =Scenarios!F18 -> -670395.19 | E16: =Scenarios!G18 -> 962564.01 | F16: =Scenarios!H18 -> 1302973.5 | G16: =Scenarios!I18 -> -2520754.9 | H16: Exit run-rate
A17: Total value incl. embedded value of ARR base | B17: =Scenarios!D20 -> -2429124 | C17: =Scenarios!E20 -> -968557.16 | D17: =Scenarios!F20 -> -1041530 | E17: =Scenarios!G20 -> 9851170.9 | F17: =Scenarios!H20 -> 13729819 | G17: =Scenarios!I20 -> -5582098.9 | H17: Cumulative P&L + 5-yr GP of 2029 base
A19: Decision metrics
A20: Expected total value — staged pilot (probability-weighted) | B20: =Scenarios!G30 -> 1938280.2 | H20: Weights 35/45/20 (Assumptions, judgment)
A21: Expected total value — ungated | B21: =Scenarios!G29 -> 651352.27
A22: Expected cumulative P&L 2027–29 — staged (no post-2029 value) | B22: =Scenarios!G31 -> -1930320.9 | H22: Every scenario is cash-negative through 2029; value depends on the ARR base after 2029
A23: Break-even probability of Upside (staged EV = 0) | B23: =Scenarios!G33 -> 0.068496873 | H23: Pilot is worth running if P(Upside) exceeds this
A24: Sales-led team minus partner-led, Base cumulative P&L | B24: =Scenarios!G34 -> -4540568.9 | H24: Same ARR; extra cost only
A25: Lowest tested win rate for ≤ 24-month payback (2029 cohort, Base usage) | B25: =Sensitivity!E31 -> none tested | H25: Benchmarks: 21% avg; 31–39% opp→won
A26: Lowest tested win rate for total value ≥ 0 | B26: =Sensitivity!E32 -> 0.5
A27: Model checks (0 = pass) | B27: =ABS(Scenarios!D23)+ABS(Scenarios!D24) -> 0 | H27: Live model reconciles to engine runs
A29: What the model shows
A30: 1. The distribution vertical is demand-limited, not capacity-limited. A dedicated sales team produces the same ARR as the partner-led pilot in Base, at materially higher cost, so Option 1 is rejected on economics (H7 supported).
A31: 2. In the Base case the partner-led pilot does not pay back within 2027–29. The serviceable market is ~5,200 firms, and list-price ACVs are ~$5K (SMB), ~$10K (Mid-Market) and ~$62K (Enterprise).
A32: 3. The Upside case (higher win rates, usage and retention) pays back and is profitable at its 2029 exit run-rate; there, borrowed AE capacity binds from Q3 2028, which is the evidence-based trigger to hire two dedicated AEs. The pilot is therefore an option: a capped, gateable investment with an asymmetric payoff.
A33: 4. A Q4 2027 Go/No-Go gate cuts the Downside loss by more than half. The sensitivity is led by usage intensity (ACV), then funnel conversion (win rate, SQL→opportunity, qualification), gross margin and partner productivity; these become the gate metrics.
A34: 5. Implication for strategy: run the pilot lean (≈1 lead + 1 engineer + shared AEs + partners), focus on 100+ employee distributors, and do not hire a vertical sales team unless the gate metrics are met.

Sheet Assumptions
A1: Assumptions — every input in one place (Downside / Base / Upside)
A2: Change blue cells only. 'Live' feeds the main model (GTM Funnel → Revenue Model → Unit Economics) via the two selectors below. Scenarios/Sensitivity run their own copies of the model.
A4: Scenario selector (1 = Downside, 2 = Base, 3 = Upside) | D4: 2 | E4: =CHOOSE($D$4,"Downside","Base","Upside") -> Base
A5: Motion selector (1 = Partner-led pilot [Option 4], 2 = Sales-led vertical team [Option 1]) | D5: 1 | E5: =CHOOSE($D$5,"Partner-led pilot","Sales-led vertical team") -> Partner-led pilot
A7: ID | B7: Input | C7: Unit | D7: Downside | E7: Base | F7: Upside | G7: Live | H7: Class | I7: Source / rationale
A8: MARKET
A9: A1 | B9: SAM filter 1: share of firms with active outbound/territory motion | C9: % | D9: 0.65 | E9: 0.8 | F9: 0.9 | G9: =INDEX(D9:F9,1,Assumptions!$D$4) -> 0.8 | H9: D | I9: Phase 1 (02_Market_Sizing, Assumptions A4); sales occupations 22% of distribution employment (S15)
A10: A2 | B10: SAM filter 2: share CRM-ready (integrable today) | C10: % | D10: 0.52 | E10: 0.65 | F10: 0.76 | G10: =INDEX(D10:F10,1,Assumptions!$D$4) -> 0.65 | H10: B/D | I10: Phase 1 A7; DSG 2022 distributor CRM survey (S17)
A11: A3 | B11: Share of SAM already Clay customers (excluded) | C11: % | D11: 0.03 | E11: 0.03 | F11: 0.03 | G11: =INDEX(D11:F11,1,Assumptions!$D$4) -> 0.03 | H11: D | I11: No public data; small given ~40% software mix of detected Clay users (S32)
A12: A4 | B12: Wave 1 launch quarter — 4236 electrical distributors (1 = Q1 2027) | C12: quarter | D12: 1 | E12: 1 | F12: 1 | G12: =INDEX(D12:F12,1,Assumptions!$D$4) -> 1 | H12: E | I12: Beachhead from 06_Segment_Prioritization (Subsegment_Drilldown)
A13: A5 | B13: Wave 2 launch quarter — 4237 hardware, plumbing & HVAC | C13: quarter | D13: 7 | E13: 5 | F13: 4 | G13: =INDEX(D13:F13,1,Assumptions!$D$4) -> 5 | H13: D | I13: After first Go/No-Go gate; Downside delays
A14: A6 | B14: Wave 3 launch quarter — 4238 machinery & MRO (99 = never) | C14: quarter | D14: 99 | E14: 7 | F14: 6 | G14: =INDEX(D14:F14,1,Assumptions!$D$4) -> 7 | H14: D | I14: Downside never launches wave 3
A16: GTM FUNNEL
A17: A7 | B17: Outbound coverage: share of active SAM accounts sequenced per quarter | C17: % | D17: 0.3 | E17: 0.4 | F17: 0.5 | G17: =INDEX(D17:F17,1,Assumptions!$D$4) -> 0.4 | H17: D | I17: Clay-run outbound (Clay's own product); rotating coverage
A18: A8 | B18: Outbound meeting rate per account sequenced | C18: % | D18: 0.02 | E18: 0.03 | F18: 0.045 | G18: =INDEX(D18:F18,1,Assumptions!$D$4) -> 0.03 | H18: D | I18: Typical cold outbound meeting rates 1–5% [K]; 'lead lists/email' MQL→SQL are among the weakest sources (S49)
A19: A9 | B19: Inbound / template-led leads per quarter (% of active SAM) | C19: % | D19: 0.005 | E19: 0.01 | F19: 0.015 | G19: =INDEX(D19:F19,1,Assumptions!$D$4) -> 0.01 | H19: D | I19: Templates, trade associations, events, Clay community
A20: A10 | B20: Partners active at launch | C20: # | D20: 1 | E20: 2 | F20: 3 | G20: =INDEX(D20:F20,1,Assumptions!$D$4) -> 2 | H20: D | I20: No distribution-focused Clay partners visible today (S35) → recruitment is a pilot task
A21: A11 | B21: Partners added per quarter | C21: # | D21: 1 | E21: 1 | F21: 2 | G21: =INDEX(D21:F21,1,Assumptions!$D$4) -> 1 | H21: D
A22: A12 | B22: Partner network cap | C22: # | D22: 5 | E22: 10 | F22: 15 | G22: =INDEX(D22:F22,1,Assumptions!$D$4) -> 10 | H22: D
A23: A13 | B23: Leads per active partner per quarter | C23: # | D23: 2 | E23: 3 | F23: 4 | G23: =INDEX(D23:F23,1,Assumptions!$D$4) -> 3 | H23: D | I23: Warm introductions from implementers / distribution consultancies
A24: A14 | B24: Qualification rate — outbound & inbound leads → SQL | C24: % | D24: 0.35 | E24: 0.45 | F24: 0.55 | G24: =INDEX(D24:F24,1,Assumptions!$D$4) -> 0.45 | H24: B | I24: Norwest 2025 ~36% MQL→SQL; SMB/MM average 39% (S48, S49)
A25: A15 | B25: Qualification rate — partner leads → SQL | C25: % | D25: 0.5 | E25: 0.6 | F25: 0.7 | G25: =INDEX(D25:F25,1,Assumptions!$D$4) -> 0.6 | H25: D | I25: Warm, pre-vetted introductions
A26: A16 | B26: SQL → opportunity conversion | C26: % | D26: 0.35 | E26: 0.45 | F26: 0.55 | G26: =INDEX(D26:F26,1,Assumptions!$D$4) -> 0.45 | H26: B | I26: SMB/MM average 42% (S49)
A27: A17 | B27: Win rate (opportunity → closed-won) | C27: % | D27: 0.2 | E27: 0.28 | F27: 0.35 | G27: =INDEX(D27:F27,1,Assumptions!$D$4) -> 0.28 | H27: B | I27: HubSpot 2024 average 21%; opportunity→won 31–39% (S48, S49); ICP-matched deals win ~3.1× more (Ebsta, S48)
A28: A18 | B28: Sales cycle: quarters from opportunity to close (1 or 2) | C28: qtrs | D28: 2 | E28: 1 | F28: 1 | G28: =INDEX(D28:F28,1,Assumptions!$D$4) -> 1 | H28: B | I28: Deals < $25K: 2–3 months (Norwest 2025, S48)
A29: A19 | B29: Win mix — SMB (20–99 employees) | C29: % | D29: 0.5 | E29: 0.5 | F29: 0.5 | G29: =INDEX(D29:F29,1,Assumptions!$D$4) -> 0.5 | H29: E | I29: ICP prioritizes 100+ employee distributors where ACV is above the Growth floor (ACV Build)
A30: A20 | B30: Win mix — Mid-Market (100–499) | C30: % | D30: 0.38 | E30: 0.38 | F30: 0.38 | G30: =INDEX(D30:F30,1,Assumptions!$D$4) -> 0.38 | H30: E
A31: A21 | B31: Win mix — Enterprise (500+) | C31: % | D31: 0.12 | E31: 0.12 | F31: 0.12 | G31: =INDEX(D31:F31,1,Assumptions!$D$4) -> 0.12 | H31: E
A32: A22 | B32: Self-serve share of SMB wins (templates; no AE) | C32: % | D32: 0.15 | E32: 0.3 | F32: 0.4 | G32: =INDEX(D32:F32,1,Assumptions!$D$4) -> 0.3 | H32: D | I32: Low builder capacity limits self-serve (H4); templates raise it
A34: ACV BUILD (usage-based pricing)
A35: A23 | B35: Sales occupations share of employment (distribution) | C35: % | D35: 0.22 | E35: 0.22 | F35: 0.22 | G35: =INDEX(D35:F35,1,Assumptions!$D$4) -> 0.22 | H35: C | I35: OEWS May 2025 (S15) via 02_Market_Sizing Segment_Profile
A36: A24 | B36: Accounts tracked per seller | C36: # | D36: 150 | E36: 150 | F36: 150 | G36: =INDEX(D36:F36,1,Assumptions!$D$4) -> 150 | H36: D | I36: Territory book of business; outside reps cover contractor and plant accounts
A37: A25 | B37: Usage intensity factor (multiplies accounts tracked) | C37: x | D37: 0.75 | E37: 1 | F37: 1.5 | G37: =INDEX(D37:F37,1,Assumptions!$D$4) -> 1 | H37: D | I37: Range for workflow depth (signals, research, sourcing)
A38: A26 | B38: Contacts per account | C38: # | D38: 2 | E38: 2 | F38: 2 | G38: =INDEX(D38:F38,1,Assumptions!$D$4) -> 2 | H38: D
A39: A27 | B39: Contact refreshes per year | C39: # | D39: 2 | E39: 2 | F39: 2 | G39: =INDEX(D39:F39,1,Assumptions!$D$4) -> 2 | H39: D
A40: A28 | B40: Data credits per contact refresh (email + phone waterfall) | C40: credits | D40: 6 | E40: 6 | F40: 6 | G40: =INDEX(D40:F40,1,Assumptions!$D$4) -> 6 | H40: B/D | I40: Third-party: email lookups 1–5 credits per record depending on provider (S51)
A41: A29 | B41: AI research credits per account per year | C41: credits | D41: 4 | E41: 4 | F41: 4 | G41: =INDEX(D41:F41,1,Assumptions!$D$4) -> 4 | H41: D | I41: Fixed-price Claygent models (S01)
A42: A30 | B42: New accounts sourced per year (% of tracked) | C42: % | D42: 0.25 | E42: 0.25 | F42: 0.25 | G42: =INDEX(D42:F42,1,Assumptions!$D$4) -> 0.25 | H42: D | I42: Google Maps / permits sourcing of new contractors (S37, S26)
A43: A31 | B43: Data credits per new account sourced | C43: credits | D43: 8 | E43: 8 | F43: 8 | G43: =INDEX(D43:F43,1,Assumptions!$D$4) -> 8 | H43: D
A44: A32 | B44: Actions per row operation | C44: actions | D44: 6 | E44: 6 | F44: 6 | G44: =INDEX(D44:F44,1,Assumptions!$D$4) -> 6 | H44: D | I44: Actions 'cost less than a cent each' (S01)
...

Sheet Market Sizing
A1: Market Sizing — the addressable opportunity for the distribution pilot
A2: Unique firms with 20+ employees, 2022 Economic Census (S14). Wave 1 = electrical (4236), wave 2 = PHVAC (4237), wave 3 = machinery/MRO (4238). Metals (4235) excluded per Phase 3.
A4: NAICS | B4: Sub-industry | C4: Firms 20–49 | D4: Firms 50–99 | E4: Firms 100–249 | F4: Firms 250–499 | G4: Firms 500+ | H4: Emp. 20–49 | I4: Emp. 50–99 | J4: Emp. 100–249 | K4: Emp. 250–499 | L4: Emp. 500+
A5: 4236 | B5: Electrical & electronic goods (wave 1) | C5: 1408 | D5: 570 | E5: 350 | F5: 136 | G5: 114 | H5: 42698 | I5: 39297 | J5: 54183 | K5: 47492 | L5: 315093
A6: 4237 | B6: Hardware, plumbing & HVAC (wave 2) | C6: 1013 | D6: 424 | E6: 242 | F6: 85 | G6: 57 | H6: 31260 | I6: 29270 | J6: 36995 | K6: 29008 | L6: 116895
A7: 4238 | B7: Machinery, equipment & supplies (wave 3) | C7: 3622 | D7: 1218 | E7: 746 | F7: 240 | G7: 183 | H7: 110129 | I7: 83565 | J7: 115979 | K7: 83365 | L7: 220621
A9: De-duplication factor for 20–49 band (sector 423) | C9: 0.973 | D9: 02_Market_Sizing › Firm_Counts Block 3 (larger bands: no measurable overlap)
A11: Wave | B11: Sub-industry | C11: SMB 20–99 | D11: Mid-Market 100–499 | E11: Enterprise 500+ | F11: Firms 20+ total | G11: SAM firms (Live) | H11: SAM share
A12: W1 | B12: =B5 -> Electrical & electronic goods (wave 1) | C12: =C5*$C$9+D5 -> 1939.984 | D12: =E5+F5 -> 486 | E12: =G5 -> 114 | F12: =SUM(C12:E12) -> 2539.984 | G12: =F12*Assumptions!$G$9*Assumptions!$G$10*(1-Assumptions!$G$11) -> 1281.1679 | H12: =G12/F12 -> 0.5044
A13: W2 | B13: =B6 -> Hardware, plumbing & HVAC (wave 2) | C13: =C6*$C$9+D6 -> 1409.649 | D13: =E6+F6 -> 327 | E13: =G6 -> 57 | F13: =SUM(C13:E13) -> 1793.649 | G13: =F13*Assumptions!$G$9*Assumptions!$G$10*(1-Assumptions!$G$11) -> 904.71656 | H13: =G13/F13 -> 0.5044
A14: W3 | B14: =B7 -> Machinery, equipment & supplies (wave 3) | C14: =C7*$C$9+D7 -> 4742.206 | D14: =E7+F7 -> 986 | E14: =G7 -> 183 | F14: =SUM(C14:E14) -> 5911.206 | G14: =F14*Assumptions!$G$9*Assumptions!$G$10*(1-Assumptions!$G$11) -> 2981.6123 | H14: =G14/F14 -> 0.5044
A15: Total | C15: =SUM(C12:C14) -> 8091.839 | D15: =SUM(D12:D14) -> 1799 | E15: =SUM(E12:E14) -> 354 | F15: =SUM(F12:F14) -> 10244.839 | G15: =SUM(G12:G14) -> 5167.4968 | H15: =G15/F15 -> 0.5044
A17: Band | C17: Firms (3 waves) | D17: Employees | E17: Avg employees per firm
A18: SMB 20–99 | C18: =SUM(C5:C7)+SUM(D5:D7) -> 8255 | D18: =SUM(H5:H7)+SUM(I5:I7) -> 336219 | E18: =D18/C18 -> 40.729134
A19: Mid-Market 100–499 | C19: =SUM(E5:E7)+SUM(F5:F7) -> 1799 | D19: =SUM(J5:J7)+SUM(K5:K7) -> 367022 | E19: =D19/C19 -> 204.01445
A20: Enterprise 500+ | C20: =SUM(G5:G7) -> 354 | D20: =SUM(L5:L7) -> 652609 | E20: =D20/C20 -> 1843.5282
A22: Average employees per firm feed the ACV Build (sellers per firm = employees × sales share). The 20–49 band is not de-duplicated here because this is an average, not a count.
A24: Reconciliation to Phase 1 | C24: Phase 1 (02) | D24: Phase 4 (this model) | E24: Difference / reason
A25: Distribution SAM firms | C25: 5976.6 | D25: =G15 -> 5167.4968 | E25: Phase 4 excludes 4235 metals (Phase 3) and Clay's existing customers
A26: Base ACV — SMB | C26: 7500 | D26: =Assumptions!$E$111 -> 5352 | E26: Usage build: SMB usage sits below the Growth floor, so ACV = $5,352 list
A27: Base ACV — Mid-Market | C27: 20000 | D27: =Assumptions!$E$112 -> 9766.7201 | E27: Usage build: ~45 sellers × 150 accounts → ~$9.8K at list
A28: Base ACV — Enterprise | C28: 60000 | D28: =Assumptions!$E$113 -> 61778.256 | E28: Usage build after 30% discount ≈ Vendr median ($59,996)
A29: Year-3 ARR (Base, Phase 1 SOM vs Phase 4 exit ARR) | C29: 1864124 | D29: =Scenarios!$F$5 -> 861203.84 | E29: Funnel- and wave-based build with lower SMB/MM ACV

Sheet ACV Build
A1: ACV Build — what would a distributor actually spend on Clay?
A2: Bottom-up from sellers per firm × accounts tracked × Clay's usage meters (Data Credits and Actions) at published Growth-tier rates. SMB and Mid-Market are floored at the Growth plan (CRM sync requires Growth). Enterprise is floored at the Enterprise minimum, less discount.
A4: Step | B4: Formula | D4: Downside | E4: Base | F4: Upside | G4: Live
A5: Unit prices (from published plans)
A6: Price per data credit | D6: =Assumptions!$D$45*12/Assumptions!$D$46 -> 0.0435 | E6: =Assumptions!$E$45*12/Assumptions!$E$46 -> 0.0435 | F6: =Assumptions!$F$45*12/Assumptions!$F$46 -> 0.0435 | G6: =Assumptions!$G$45*12/Assumptions!$G$46 -> 0.0435
A7: Price per action | D7: =Assumptions!$D$47*12/Assumptions!$D$48 -> 0.004625 | E7: =Assumptions!$E$47*12/Assumptions!$E$48 -> 0.004625 | F7: =Assumptions!$F$47*12/Assumptions!$F$48 -> 0.004625 | G7: =Assumptions!$G$47*12/Assumptions!$G$48 -> 0.004625
A8: Growth plan floor (annual) | D8: =(Assumptions!$D$45+Assumptions!$D$47)*12 -> 5352 | E8: =(Assumptions!$E$45+Assumptions!$E$47)*12 -> 5352 | F8: =(Assumptions!$F$45+Assumptions!$F$47)*12 -> 5352 | G8: =(Assumptions!$G$45+Assumptions!$G$47)*12 -> 5352
A9: Enterprise minimum at list (annual) | D9: =Assumptions!$D$49*Assumptions!$D$45*12/Assumptions!$D$46+Assumptions!$D$50*Assumptions!$D$47*12/Assumptions!$D$48 -> 63300 | E9: =Assumptions!$E$49*Assumptions!$E$45*12/Assumptions!$E$46+Assumptions!$E$50*Assumptions!$E$47*12/Assumptions!$E$48 -> 63300 | F9: =Assumptions!$F$49*Assumptions!$F$45*12/Assumptions!$F$46+Assumptions!$F$50*Assumptions!$F$47*12/Assumptions!$F$48 -> 63300 | G9: =Assumptions!$G$49*Assumptions!$G$45*12/Assumptions!$G$46+Assumptions!$G$50*Assumptions!$G$47*12/Assumptions!$G$48 -> 63300
A11: SMB (20–99)
A12: Avg employees per firm | B12: Market Sizing | D12: ='Market Sizing'!$E$18 -> 40.729134 | E12: ='Market Sizing'!$E$18 -> 40.729134 | F12: ='Market Sizing'!$E$18 -> 40.729134 | G12: ='Market Sizing'!$E$18 -> 40.729134
A13: Sellers per firm | B13: employees × sales share | D13: =D12*Assumptions!$D$35 -> 8.9604094 | E13: =E12*Assumptions!$E$35 -> 8.9604094 | F13: =F12*Assumptions!$F$35 -> 8.9604094 | G13: =G12*Assumptions!$G$35 -> 8.9604094
A14: Accounts tracked | B14: sellers × accounts/seller × usage factor | D14: =D13*Assumptions!$D$36*Assumptions!$D$37 -> 1008.0461 | E14: =E13*Assumptions!$E$36*Assumptions!$E$37 -> 1344.0614 | F14: =F13*Assumptions!$F$36*Assumptions!$F$37 -> 2016.0921 | G14: =G13*Assumptions!$G$36*Assumptions!$G$37 -> 1344.0614
A15: Contacts tracked | B15: accounts × contacts/account | D15: =D14*Assumptions!$D$38 -> 2016.0921 | E15: =E14*Assumptions!$E$38 -> 2688.1228 | F15: =F14*Assumptions!$F$38 -> 4032.1843 | G15: =G14*Assumptions!$G$38 -> 2688.1228
A16: Data credits per year | B16: refreshes + AI research + new-account sourcing | D16: =D15*Assumptions!$D$39*Assumptions!$D$40+D14*Assumptions!$D$41+D14*Assumptions!$D$42*Assumptions!$D$43 -> 30241.382 | E16: =E15*Assumptions!$E$39*Assumptions!$E$40+E14*Assumptions!$E$41+E14*Assumptions!$E$42*Assumptions!$E$43 -> 40321.843 | F16: =F15*Assumptions!$F$39*Assumptions!$F$40+F14*Assumptions!$F$41+F14*Assumptions!$F$42*Assumptions!$F$43 -> 60482.764 | G16: =G15*Assumptions!$G$39*Assumptions!$G$40+G14*Assumptions!$G$41+G14*Assumptions!$G$42*Assumptions!$G$43 -> 40321.843
A17: Actions per year | B17: row operations × actions/op | D17: =(D15*Assumptions!$D$39+D14+D14*Assumptions!$D$42)*Assumptions!$D$44 -> 31753.451 | E17: =(E15*Assumptions!$E$39+E14+E14*Assumptions!$E$42)*Assumptions!$E$44 -> 42337.935 | F17: =(F15*Assumptions!$F$39+F14+F14*Assumptions!$F$42)*Assumptions!$F$44 -> 63506.902 | G17: =(G15*Assumptions!$G$39+G14+G14*Assumptions!$G$42)*Assumptions!$G$44 -> 42337.935
A18: Usage cost at list | B18: credits × price + actions × price | D18: =D16*Assumptions!$D$45*12/Assumptions!$D$46+D17*Assumptions!$D$47*12/Assumptions!$D$48 -> 1462.3598 | E18: =E16*Assumptions!$E$45*12/Assumptions!$E$46+E17*Assumptions!$E$47*12/Assumptions!$E$48 -> 1949.8131 | F18: =F16*Assumptions!$F$45*12/Assumptions!$F$46+F17*Assumptions!$F$47*12/Assumptions!$F$48 -> 2924.7196 | G18: =G16*Assumptions!$G$45*12/Assumptions!$G$46+G17*Assumptions!$G$47*12/Assumptions!$G$48 -> 1949.8131
A20: Mid-Market (100–499)
A21: Avg employees per firm | B21: Market Sizing | D21: ='Market Sizing'!$E$19 -> 204.01445 | E21: ='Market Sizing'!$E$19 -> 204.01445 | F21: ='Market Sizing'!$E$19 -> 204.01445 | G21: ='Market Sizing'!$E$19 -> 204.01445
A22: Sellers per firm | B22: employees × sales share | D22: =D21*Assumptions!$D$35 -> 44.88318 | E22: =E21*Assumptions!$E$35 -> 44.88318 | F22: =F21*Assumptions!$F$35 -> 44.88318 | G22: =G21*Assumptions!$G$35 -> 44.88318
A23: Accounts tracked | B23: sellers × accounts/seller × usage factor | D23: =D22*Assumptions!$D$36*Assumptions!$D$37 -> 5049.3577 | E23: =E22*Assumptions!$E$36*Assumptions!$E$37 -> 6732.4769 | F23: =F22*Assumptions!$F$36*Assumptions!$F$37 -> 10098.715 | G23: =G22*Assumptions!$G$36*Assumptions!$G$37 -> 6732.4769
A24: Contacts tracked | B24: accounts × contacts/account | D24: =D23*Assumptions!$D$38 -> 10098.715 | E24: =E23*Assumptions!$E$38 -> 13464.954 | F24: =F23*Assumptions!$F$38 -> 20197.431 | G24: =G23*Assumptions!$G$38 -> 13464.954
A25: Data credits per year | B25: refreshes + AI research + new-account sourcing | D25: =D24*Assumptions!$D$39*Assumptions!$D$40+D23*Assumptions!$D$41+D23*Assumptions!$D$42*Assumptions!$D$43 -> 151480.73 | E25: =E24*Assumptions!$E$39*Assumptions!$E$40+E23*Assumptions!$E$41+E23*Assumptions!$E$42*Assumptions!$E$43 -> 201974.31 | F25: =F24*Assumptions!$F$39*Assumptions!$F$40+F23*Assumptions!$F$41+F23*Assumptions!$F$42*Assumptions!$F$43 -> 302961.46 | G25: =G24*Assumptions!$G$39*Assumptions!$G$40+G23*Assumptions!$G$41+G23*Assumptions!$G$42*Assumptions!$G$43 -> 201974.31
A26: Actions per year | B26: row operations × actions/op | D26: =(D24*Assumptions!$D$39+D23+D23*Assumptions!$D$42)*Assumptions!$D$44 -> 159054.77 | E26: =(E24*Assumptions!$E$39+E23+E23*Assumptions!$E$42)*Assumptions!$E$44 -> 212073.02 | F26: =(F24*Assumptions!$F$39+F23+F23*Assumptions!$F$42)*Assumptions!$F$44 -> 318109.54 | G26: =(G24*Assumptions!$G$39+G23+G23*Assumptions!$G$42)*Assumptions!$G$44 -> 212073.02
A27: Usage cost at list | B27: credits × price + actions × price | D27: =D25*Assumptions!$D$45*12/Assumptions!$D$46+D26*Assumptions!$D$47*12/Assumptions!$D$48 -> 7325.0401 | E27: =E25*Assumptions!$E$45*12/Assumptions!$E$46+E26*Assumptions!$E$47*12/Assumptions!$E$48 -> 9766.7201 | F27: =F25*Assumptions!$F$45*12/Assumptions!$F$46+F26*Assumptions!$F$47*12/Assumptions!$F$48 -> 14650.08 | G27: =G25*Assumptions!$G$45*12/Assumptions!$G$46+G26*Assumptions!$G$47*12/Assumptions!$G$48 -> 9766.7201
A29: Enterprise (500+)
A30: Avg employees per firm | B30: Market Sizing | D30: ='Market Sizing'!$E$20 -> 1843.5282 | E30: ='Market Sizing'!$E$20 -> 1843.5282 | F30: ='Market Sizing'!$E$20 -> 1843.5282 | G30: ='Market Sizing'!$E$20 -> 1843.5282
A31: Sellers per firm | B31: employees × sales share | D31: =D30*Assumptions!$D$35 -> 405.57621 | E31: =E30*Assumptions!$E$35 -> 405.57621 | F31: =F30*Assumptions!$F$35 -> 405.57621 | G31: =G30*Assumptions!$G$35 -> 405.57621
A32: Accounts tracked | B32: sellers × accounts/seller × usage factor | D32: =D31*Assumptions!$D$36*Assumptions!$D$37 -> 45627.324 | E32: =E31*Assumptions!$E$36*Assumptions!$E$37 -> 60836.432 | F32: =F31*Assumptions!$F$36*Assumptions!$F$37 -> 91254.648 | G32: =G31*Assumptions!$G$36*Assumptions!$G$37 -> 60836.432
A33: Contacts tracked | B33: accounts × contacts/account | D33: =D32*Assumptions!$D$38 -> 91254.648 | E33: =E32*Assumptions!$E$38 -> 121672.86 | F33: =F32*Assumptions!$F$38 -> 182509.3 | G33: =G32*Assumptions!$G$38 -> 121672.86
A34: Data credits per year | B34: refreshes + AI research + new-account sourcing | D34: =D33*Assumptions!$D$39*Assumptions!$D$40+D32*Assumptions!$D$41+D32*Assumptions!$D$42*Assumptions!$D$43 -> 1368819.7 | E34: =E33*Assumptions!$E$39*Assumptions!$E$40+E32*Assumptions!$E$41+E32*Assumptions!$E$42*Assumptions!$E$43 -> 1825093 | F34: =F33*Assumptions!$F$39*Assumptions!$F$40+F32*Assumptions!$F$41+F32*Assumptions!$F$42*Assumptions!$F$43 -> 2737639.4 | G34: =G33*Assumptions!$G$39*Assumptions!$G$40+G32*Assumptions!$G$41+G32*Assumptions!$G$42*Assumptions!$G$43 -> 1825093
A35: Actions per year | B35: row operations × actions/op | D35: =(D33*Assumptions!$D$39+D32+D32*Assumptions!$D$42)*Assumptions!$D$44 -> 1437260.7 | E35: =(E33*Assumptions!$E$39+E32+E32*Assumptions!$E$42)*Assumptions!$E$44 -> 1916347.6 | F35: =(F33*Assumptions!$F$39+F32+F32*Assumptions!$F$42)*Assumptions!$F$44 -> 2874521.4 | G35: =(G33*Assumptions!$G$39+G32+G32*Assumptions!$G$42)*Assumptions!$G$44 -> 1916347.6
A36: Usage cost at list | B36: credits × price + actions × price | D36: =D34*Assumptions!$D$45*12/Assumptions!$D$46+D35*Assumptions!$D$47*12/Assumptions!$D$48 -> 66190.989 | E36: =E34*Assumptions!$E$45*12/Assumptions!$E$46+E35*Assumptions!$E$47*12/Assumptions!$E$48 -> 88254.652 | F36: =F34*Assumptions!$F$45*12/Assumptions!$F$46+F35*Assumptions!$F$47*12/Assumptions!$F$48 -> 132381.98 | G36: =G34*Assumptions!$G$45*12/Assumptions!$G$46+G35*Assumptions!$G$47*12/Assumptions!$G$48 -> 88254.652
A39: First-year ACV (feeds Assumptions)
A40: ACV — SMB (20–99) | B40: MAX(floor, usage) | D40: =MAX(((Assumptions!$D$45+Assumptions!$D$47)*12),(((('Market Sizing'!$E$18*Assumptions!$D$35*Assumptions!$D$36*Assumptions!$D$37)*Assumptions!$D$38)*Assumptions!$D$39*Assumptions!$D$40+('Market Sizing'!$E$18*Assumptions!$D$35*Assumptions!$D$36*Assumptions!$D$37)*Assumptions!$D$41+('Market Sizing'!$E$18*Assumptions!$D$35*Assumptions!$D$36*Assumptions!$D$37)*Assumptions!$D$42*Assumptions!$D$43)*(Assumptions!$D$45*12/Assumptions!$D$46)+((('Market Sizing'!$E$18*Assumptions!$D$35*Assumptions!$D$36*Assumptions!$D$37)*Assumptions!$D$38)*Assumptions!$D$39+('Market Sizing'!$E$18*Assumptions!$D$35*Assumptions!$D$36*Assumptions!$D$37)+('Market Sizing'!$E$18*Assumptions!$D$35*Assumptions!$D$36*Assumptions!$D$37)*Assumptions!$D$42)*Assumptions!$D$44*(Assumptions!$D$47*12/Assumptions!$D$48))) -> 5352 | E40: =MAX(((Assumptions!$E$45+Assumptions!$E$47)*12),(((('Market Sizing'!$E$18*Assumptions!$E$35*Assumptions!$E$36*Assumptions!$E$37)*Assumptions!$E$38)*Assumptions!$E$39*Assumptions!$E$40+('Market Sizing'!$E$18*Assumptions!$E$35*Assumptions!$E$36*Assumptions!$E$37)*Assumptions!$E$41+('Market Sizing'!$E$18*Assumptions!$E$35*Assumptions!$E$36*Assumptions!$E$37)*Assumptions!$E$42*Assumptions!$E$43)*(Assumptions!$E$45*12/Assumptions!$E$46)+((('Market Sizing'!$E$18*Assumptions!$E$35*Assumptions!$E$36*Assumptions!$E$37)*Assumptions!$E$38)*Assumptions!$E$39+('Market Sizing'!$E$18*Assumptions!$E$35*Assumptions!$E$36*Assumptions!$E$37)+('Market Sizing'!$E$18*Assumptions!$E$35*Assumptions!$E$36*Assumptions!$E$37)*Assumptions!$E$42)*Assumptions!$E$44*(Assumptions!$E$47*12/Assumptions!$E$48))) -> 5352 | F40: =MAX(((Assumptions!$F$45+Assumptions!$F$47)*12),(((('Market Sizing'!$E$18*Assumptions!$F$35*Assumptions!$F$36*Assumptions!$F$37)*Assumptions!$F$38)*Assumptions!$F$39*Assumptions!$F$40+('Market Sizing'!$E$18*Assumptions!$F$35*Assumptions!$F$36*Assumptions!$F$37)*Assumptions!$F$41+('Market Sizing'!$E$18*Assumptions!$F$35*Assumptions!$F$36*Assumptions!$F$37)*Assumptions!$F$42*Assumptions!$F$43)*(Assumptions!$F$45*12/Assumptions!$F$46)+((('Market Sizing'!$E$18*Assumptions!$F$35*Assumptions!$F$36*Assumptions!$F$37)*Assumptions!$F$38)*Assumptions!$F$39+('Market Sizing'!$E$18*Assumptions!$F$35*Assumptions!$F$36*Assumptions!$F$37)+('Market Sizing'!$E$18*Assumptions!$F$35*Assumptions!$F$36*Assumptions!$F$37)*Assumptions!$F$42)*Assumptions!$F$44*(Assumptions!$F$47*12/Assumptions!$F$48))) -> 5352 | G40: =MAX(((Assumptions!$G$45+Assumptions!$G$47)*12),(((('Market Sizing'!$E$18*Assumptions!$G$35*Assumptions!$G$36*Assumptions!$G$37)*Assumptions!$G$38)*Assumptions!$G$39*Assumptions!$G$40+('Market Sizing'!$E$18*Assumptions!$G$35*Assumptions!$G$36*Assumptions!$G$37)*Assumptions!$G$41+('Market Sizing'!$E$18*Assumptions!$G$35*Assumptions!$G$36*Assumptions!$G$37)*Assumptions!$G$42*Assumptions!$G$43)*(Assumptions!$G$45*12/Assumptions!$G$46)+((('Market Sizing'!$E$18*Assumptions!$G$35*Assumptions!$G$36*Assumptions!$G$37)*Assumptions!$G$38)*Assumptions!$G$39+('Market Sizing'!$E$18*Assumptions!$G$35*Assumptions!$G$36*Assumptions!$G$37)+('Market Sizing'!$E$18*Assumptions!$G$35*Assumptions!$G$36*Assumptions!$G$37)*Assumptions!$G$42)*Assumptions!$G$44*(Assumptions!$G$47*12/Assumptions!$G$48))) -> 5352
A41: ACV — Mid-Market (100–499) | B41: MAX(floor, usage) | D41: =MAX(((Assumptions!$D$45+Assumptions!$D$47)*12),(((('Market Sizing'!$E$19*Assumptions!$D$35*Assumptions!$D$36*Assumptions!$D$37)*Assumptions!$D$38)*Assumptions!$D$39*Assumptions!$D$40+('Market Sizing'!$E$19*Assumptions!$D$35*Assumptions!$D$36*Assumptions!$D$37)*Assumptions!$D$41+('Market Sizing'!$E$19*Assumptions!$D$35*Assumptions!$D$36*Assumptions!$D$37)*Assumptions!$D$42*Assumptions!$D$43)*(Assumptions!$D$45*12/Assumptions!$D$46)+((('Market Sizing'!$E$19*Assumptions!$D$35*Assumptions!$D$36*Assumptions!$D$37)*Assumptions!$D$38)*Assumptions!$D$39+('Market Sizing'!$E$19*Assumptions!$D$35*Assumptions!$D$36*Assumptions!$D$37)+('Market Sizing'!$E$19*Assumptions!$D$35*Assumptions!$D$36*Assumptions!$D$37)*Assumptions!$D$42)*Assumptions!$D$44*(Assumptions!$D$47*12/Assumptions!$D$48))) -> 7325.0401 | E41: =MAX(((Assumptions!$E$45+Assumptions!$E$47)*12),(((('Market Sizing'!$E$19*Assumptions!$E$35*Assumptions!$E$36*Assumptions!$E$37)*Assumptions!$E$38)*Assumptions!$E$39*Assumptions!$E$40+('Market Sizing'!$E$19*Assumptions!$E$35*Assumptions!$E$36*Assumptions!$E$37)*Assumptions!$E$41+('Market Sizing'!$E$19*Assumptions!$E$35*Assumptions!$E$36*Assumptions!$E$37)*Assumptions!$E$42*Assumptions!$E$43)*(Assumptions!$E$45*12/Assumptions!$E$46)+((('Market Sizing'!$E$19*Assumptions!$E$35*Assumptions!$E$36*Assumptions!$E$37)*Assumptions!$E$38)*Assumptions!$E$39+('Market Sizing'!$E$19*Assumptions!$E$35*Assumptions!$E$36*Assumptions!$E$37)+('Market Sizing'!$E$19*Assumptions!$E$35*Assumptions!$E$36*Assumptions!$E$37)*Assumptions!$E$42)*Assumptions!$E$44*(Assumptions!$E$47*12/Assumptions!$E$48))) -> 9766.7201 | F41: =MAX(((Assumptions!$F$45+Assumptions!$F$47)*12),(((('Market Sizing'!$E$19*Assumptions!$F$35*Assumptions!$F$36*Assumptions!$F$37)*Assumptions!$F$38)*Assumptions!$F$39*Assumptions!$F$40+('Market Sizing'!$E$19*Assumptions!$F$35*Assumptions!$F$36*Assumptions!$F$37)*Assumptions!$F$41+('Market Sizing'!$E$19*Assumptions!$F$35*Assumptions!$F$36*Assumptions!$F$37)*Assumptions!$F$42*Assumptions!$F$43)*(Assumptions!$F$45*12/Assumptions!$F$46)+((('Market Sizing'!$E$19*Assumptions!$F$35*Assumptions!$F$36*Assumptions!$F$37)*Assumptions!$F$38)*Assumptions!$F$39+('Market Sizing'!$E$19*Assumptions!$F$35*Assumptions!$F$36*Assumptions!$F$37)+('Market Sizing'!$E$19*Assumptions!$F$35*Assumptions!$F$36*Assumptions!$F$37)*Assumptions!$F$42)*Assumptions!$F$44*(Assumptions!$F$47*12/Assumptions!$F$48))) -> 14650.08 | G41: =MAX(((Assumptions!$G$45+Assumptions!$G$47)*12),(((('Market Sizing'!$E$19*Assumptions!$G$35*Assumptions!$G$36*Assumptions!$G$37)*Assumptions!$G$38)*Assumptions!$G$39*Assumptions!$G$40+('Market Sizing'!$E$19*Assumptions!$G$35*Assumptions!$G$36*Assumptions!$G$37)*Assumptions!$G$41+('Market Sizing'!$E$19*Assumptions!$G$35*Assumptions!$G$36*Assumptions!$G$37)*Assumptions!$G$42*Assumptions!$G$43)*(Assumptions!$G$45*12/Assumptions!$G$46)+((('Market Sizing'!$E$19*Assumptions!$G$35*Assumptions!$G$36*Assumptions!$G$37)*Assumptions!$G$38)*Assumptions!$G$39+('Market Sizing'!$E$19*Assumptions!$G$35*Assumptions!$G$36*Assumptions!$G$37)+('Market Sizing'!$E$19*Assumptions!$G$35*Assumptions!$G$36*Assumptions!$G$37)*Assumptions!$G$42)*Assumptions!$G$44*(Assumptions!$G$47*12/Assumptions!$G$48))) -> 9766.7201
A42: ACV — Enterprise (500+) | B42: MAX(Enterprise minimum, usage) × (1 − discount) | D42: =MAX((Assumptions!$D$49*(Assumptions!$D$45*12/Assumptions!$D$46)+Assumptions!$D$50*(Assumptions!$D$47*12/Assumptions!$D$48)),(((('Market Sizing'!$E$20*Assumptions!$D$35*Assumptions!$D$36*Assumptions!$D$37)*Assumptions!$D$38)*Assumptions!$D$39*Assumptions!$D$40+('Market Sizing'!$E$20*Assumptions!$D$35*Assumptions!$D$36*Assumptions!$D$37)*Assumptions!$D$41+('Market Sizing'!$E$20*Assumptions!$D$35*Assumptions!$D$36*Assumptions!$D$37)*Assumptions!$D$42*Assumptions!$D$43)*(Assumptions!$D$45*12/Assumptions!$D$46)+((('Market Sizing'!$E$20*Assumptions!$D$35*Assumptions!$D$36*Assumptions!$D$37)*Assumptions!$D$38)*Assumptions!$D$39+('Market Sizing'!$E$20*Assumptions!$D$35*Assumptions!$D$36*Assumptions!$D$37)+('Market Sizing'!$E$20*Assumptions!$D$35*Assumptions!$D$36*Assumptions!$D$37)*Assumptions!$D$42)*Assumptions!$D$44*(Assumptions!$D$47*12/Assumptions!$D$48)))*(1-Assumptions!$D$51) -> 46333.692 | E42: =MAX((Assumptions!$E$49*(Assumptions!$E$45*12/Assumptions!$E$46)+Assumptions!$E$50*(Assumptions!$E$47*12/Assumptions!$E$48)),(((('Market Sizing'!$E$20*Assumptions!$E$35*Assumptions!$E$36*Assumptions!$E$37)*Assumptions!$E$38)*Assumptions!$E$39*Assumptions!$E$40+('Market Sizing'!$E$20*Assumptions!$E$35*Assumptions!$E$36*Assumptions!$E$37)*Assumptions!$E$41+('Market Sizing'!$E$20*Assumptions!$E$35*Assumptions!$E$36*Assumptions!$E$37)*Assumptions!$E$42*Assumptions!$E$43)*(Assumptions!$E$45*12/Assumptions!$E$46)+((('Market Sizing'!$E$20*Assumptions!$E$35*Assumptions!$E$36*Assumptions!$E$37)*Assumptions!$E$38)*Assumptions!$E$39+('Market Sizing'!$E$20*Assumptions!$E$35*Assumptions!$E$36*Assumptions!$E$37)+('Market Sizing'!$E$20*Assumptions!$E$35*Assumptions!$E$36*Assumptions!$E$37)*Assumptions!$E$42)*Assumptions!$E$44*(Assumptions!$E$47*12/Assumptions!$E$48)))*(1-Assumptions!$E$51) -> 61778.256 | F42: =MAX((Assumptions!$F$49*(Assumptions!$F$45*12/Assumptions!$F$46)+Assumptions!$F$50*(Assumptions!$F$47*12/Assumptions!$F$48)),(((('Market Sizing'!$E$20*Assumptions!$F$35*Assumptions!$F$36*Assumptions!$F$37)*Assumptions!$F$38)*Assumptions!$F$39*Assumptions!$F$40+('Market Sizing'!$E$20*Assumptions!$F$35*Assumptions!$F$36*Assumptions!$F$37)*Assumptions!$F$41+('Market Sizing'!$E$20*Assumptions!$F$35*Assumptions!$F$36*Assumptions!$F$37)*Assumptions!$F$42*Assumptions!$F$43)*(Assumptions!$F$45*12/Assumptions!$F$46)+((('Market Sizing'!$E$20*Assumptions!$F$35*Assumptions!$F$36*Assumptions!$F$37)*Assumptions!$F$38)*Assumptions!$F$39+('Market Sizing'!$E$20*Assumptions!$F$35*Assumptions!$F$36*Assumptions!$F$37)+('Market Sizing'!$E$20*Assumptions!$F$35*Assumptions!$F$36*Assumptions!$F$37)*Assumptions!$F$42)*Assumptions!$F$44*(Assumptions!$F$47*12/Assumptions!$F$48)))*(1-Assumptions!$F$51) -> 92667.384 | G42: =MAX((Assumptions!$G$49*(Assumptions!$G$45*12/Assumptions!$G$46)+Assumptions!$G$50*(Assumptions!$G$47*12/Assumptions!$G$48)),(((('Market Sizing'!$E$20*Assumptions!$G$35*Assumptions!$G$36*Assumptions!$G$37)*Assumptions!$G$38)*Assumptions!$G$39*Assumptions!$G$40+('Market Sizing'!$E$20*Assumptions!$G$35*Assumptions!$G$36*Assumptions!$G$37)*Assumptions!$G$41+('Market Sizing'!$E$20*Assumptions!$G$35*Assumptions!$G$36*Assumptions!$G$37)*Assumptions!$G$42*Assumptions!$G$43)*(Assumptions!$G$45*12/Assumptions!$G$46)+((('Market Sizing'!$E$20*Assumptions!$G$35*Assumptions!$G$36*Assumptions!$G$37)*Assumptions!$G$38)*Assumptions!$G$39+('Market Sizing'!$E$20*Assumptions!$G$35*Assumptions!$G$36*Assumptions!$G$37)+('Market Sizing'!$E$20*Assumptions!$G$35*Assumptions!$G$36*Assumptions!$G$37)*Assumptions!$G$42)*Assumptions!$G$44*(Assumptions!$G$47*12/Assumptions!$G$48)))*(1-Assumptions!$G$51) -> 61778.256
A44: Check: Base Enterprise ACV vs Vendr median buyer ($59,996, S16) | E44: =E42/59996 -> 1.0297063
A46: Finding: at published rates, an SMB distributor's usage (~$2K/yr) sits well below the Growth floor, so seller density does NOT lift SMB ACV. It matters only from mid-market upward. This tempers Phase 3's revenue-potential argument (stress test T4 there) and is why the pilot's ICP leans to 100+ employee distributors.

Sheet GTM Funnel
A1: GTM Funnel — live model (selected scenario and motion)
A2: Lead generation → qualification → opportunities → wins, with a sales-capacity constraint. Quarters Q1 2027–Q4 2029; annual columns P–R; total S.
A3: ="Live run: "&Assumptions!$E$4&" scenario · "&Assumptions!$E$5 -> Live run: Base scenario · Partner-led pilot
A5: Live model — inputs carried into this run | B5: Unit / note | C5: Q1 2027 | D5: Q2 2027 | E5: Q3 2027 | F5: Q4 2027 | G5: Q1 2028 | H5: Q2 2028 | I5: Q3 2028 | J5: Q4 2028 | K5: Q1 2029 | L5: Q2 2029 | M5: Q3 2029 | N5: Q4 2029 | P5: 2027 | Q5: 2028 | R5: 2029 | S5: 2027–29
A6: SAM accounts — wave 1 (4236 electrical) | B6: firms × filters × (1 − existing) | C6: ='Market Sizing'!$F$12*Assumptions!$G$9*Assumptions!$G$10*(1-Assumptions!$G$11) -> 1281.1679
A7: SAM accounts — wave 2 (4237 PHVAC) | C7: ='Market Sizing'!$F$13*Assumptions!$G$9*Assumptions!$G$10*(1-Assumptions!$G$11) -> 904.71656
A8: SAM accounts — wave 3 (4238 machinery/MRO) | C8: ='Market Sizing'!$F$14*Assumptions!$G$9*Assumptions!$G$10*(1-Assumptions!$G$11) -> 2981.6123
A9: First-year ACV — SMB | B9: usage build (ACV Build) | C9: =MAX(((Assumptions!$G$45+Assumptions!$G$47)*12),(((('Market Sizing'!$E$18*Assumptions!$G$35*Assumptions!$G$36*Assumptions!$G$37)*Assumptions!$G$38)*Assumptions!$G$39*Assumptions!$G$40+('Market Sizing'!$E$18*Assumptions!$G$35*Assumptions!$G$36*Assumptions!$G$37)*Assumptions!$G$41+('Market Sizing'!$E$18*Assumptions!$G$35*Assumptions!$G$36*Assumptions!$G$37)*Assumptions!$G$42*Assumptions!$G$43)*(Assumptions!$G$45*12/Assumptions!$G$46)+((('Market Sizing'!$E$18*Assumptions!$G$35*Assumptions!$G$36*Assumptions!$G$37)*Assumptions!$G$38)*Assumptions!$G$39+('Market Sizing'!$E$18*Assumptions!$G$35*Assumptions!$G$36*Assumptions!$G$37)+('Market Sizing'!$E$18*Assumptions!$G$35*Assumptions!$G$36*Assumptions!$G$37)*Assumptions!$G$42)*Assumptions!$G$44*(Assumptions!$G$47*12/Assumptions!$G$48))) -> 5352
A10: First-year ACV — Mid-Market | C10: =MAX(((Assumptions!$G$45+Assumptions!$G$47)*12),(((('Market Sizing'!$E$19*Assumptions!$G$35*Assumptions!$G$36*Assumptions!$G$37)*Assumptions!$G$38)*Assumptions!$G$39*Assumptions!$G$40+('Market Sizing'!$E$19*Assumptions!$G$35*Assumptions!$G$36*Assumptions!$G$37)*Assumptions!$G$41+('Market Sizing'!$E$19*Assumptions!$G$35*Assumptions!$G$36*Assumptions!$G$37)*Assumptions!$G$42*Assumptions!$G$43)*(Assumptions!$G$45*12/Assumptions!$G$46)+((('Market Sizing'!$E$19*Assumptions!$G$35*Assumptions!$G$36*Assumptions!$G$37)*Assumptions!$G$38)*Assumptions!$G$39+('Market Sizing'!$E$19*Assumptions!$G$35*Assumptions!$G$36*Assumptions!$G$37)+('Market Sizing'!$E$19*Assumptions!$G$35*Assumptions!$G$36*Assumptions!$G$37)*Assumptions!$G$42)*Assumptions!$G$44*(Assumptions!$G$47*12/Assumptions!$G$48))) -> 9766.7201
A11: First-year ACV — Enterprise | C11: =MAX((Assumptions!$G$49*(Assumptions!$G$45*12/Assumptions!$G$46)+Assumptions!$G$50*(Assumptions!$G$47*12/Assumptions!$G$48)),(((('Market Sizing'!$E$20*Assumptions!$G$35*Assumptions!$G$36*Assumptions!$G$37)*Assumptions!$G$38)*Assumptions!$G$39*Assumptions!$G$40+('Market Sizing'!$E$20*Assumptions!$G$35*Assumptions!$G$36*Assumptions!$G$37)*Assumptions!$G$41+('Market Sizing'!$E$20*Assumptions!$G$35*Assumptions!$G$36*Assumptions!$G$37)*Assumptions!$G$42*Assumptions!$G$43)*(Assumptions!$G$45*12/Assumptions!$G$46)+((('Market Sizing'!$E$20*Assumptions!$G$35*Assumptions!$G$36*Assumptions!$G$37)*Assumptions!$G$38)*Assumptions!$G$39+('Market Sizing'!$E$20*Assumptions!$G$35*Assumptions!$G$36*Assumptions!$G$37)+('Market Sizing'!$E$20*Assumptions!$G$35*Assumptions!$G$36*Assumptions!$G$37)*Assumptions!$G$42)*Assumptions!$G$44*(Assumptions!$G$47*12/Assumptions!$G$48)))*(1-Assumptions!$G$51) -> 61778.256
A12: Sales-assisted mix denominator | B12: mixS(1−ss)+mixM+mixE | C12: =Assumptions!$G$29*(1-Assumptions!$G$32)+Assumptions!$G$30+Assumptions!$G$31 -> 0.85
A13: Blended ACV of sales-assisted wins | C13: =(Assumptions!$G$29*(1-Assumptions!$G$32)*$C$9+Assumptions!$G$30*$C$10+Assumptions!$G$31*$C$11)/$C$12 -> 15291.699
A14: AE fully loaded annual cost | B14: OTE ÷ wage share | C14: =Assumptions!$G$64/Assumptions!$G$65 -> 285714.29
A15: Deals per ramped AE per quarter | B15: quota × productivity ÷ 4 ÷ ACV | C15: =Assumptions!$G$62*Assumptions!$G$63/4/$C$13 -> 10.013603
A16: Variable AE cost per deal (shared capacity) | C16: =$C$14/4/$C$15 -> 7133.1542
A17: GTM funnel | B17: Unit / note | C17: Q1 2027 | D17: Q2 2027 | E17: Q3 2027 | F17: Q4 2027 | G17: Q1 2028 | H17: Q2 2028 | I17: Q3 2028 | J17: Q4 2028 | K17: Q1 2029 | L17: Q2 2029 | M17: Q3 2029 | N17: Q4 2029 | P17: 2027 | Q17: 2028 | R17: 2029 | S17: 2027–29
A18: Quarter number | B18: # | C18: 1 | D18: 2 | E18: 3 | F18: 4 | G18: 5 | H18: 6 | I18: 7 | J18: 8 | K18: 9 | L18: 10 | M18: 11 | N18: 12
A19: Program running (1) / stopped (0) | B19: flag | C19: =IF(C18<=Assumptions!$G$79,1,0) -> 1 | D19: =IF(D18<=Assumptions!$G$79,1,0) -> 1 | E19: =IF(E18<=Assumptions!$G$79,1,0) -> 1 | F19: =IF(F18<=Assumptions!$G$79,1,0) -> 1 | G19: =IF(G18<=Assumptions!$G$79,1,0) -> 1 | H19: =IF(H18<=Assumptions!$G$79,1,0) -> 1 | I19: =IF(I18<=Assumptions!$G$79,1,0) -> 1 | J19: =IF(J18<=Assumptions!$G$79,1,0) -> 1 | ... N19: =IF(N18<=Assumptions!$G$79,1,0) -> 1
A20: Wave 1 active (0.5 in launch quarter) | B20: factor | C20: =IF(C18=Assumptions!$G$12,0.5,IF(C18>Assumptions!$G$12,1,0)) -> 0.5 | D20: =IF(D18=Assumptions!$G$12,0.5,IF(D18>Assumptions!$G$12,1,0)) -> 1 | E20: =IF(E18=Assumptions!$G$12,0.5,IF(E18>Assumptions!$G$12,1,0)) -> 1 | F20: =IF(F18=Assumptions!$G$12,0.5,IF(F18>Assumptions!$G$12,1,0)) -> 1 | G20: =IF(G18=Assumptions!$G$12,0.5,IF(G18>Assumptions!$G$12,1,0)) -> 1 | H20: =IF(H18=Assumptions!$G$12,0.5,IF(H18>Assumptions!$G$12,1,0)) -> 1 | I20: =IF(I18=Assumptions!$G$12,0.5,IF(I18>Assumptions!$G$12,1,0)) -> 1 | J20: =IF(J18=Assumptions!$G$12,0.5,IF(J18>Assumptions!$G$12,1,0)) -> 1 | ... N20: =IF(N18=Assumptions!$G$12,0.5,IF(N18>Assumptions!$G$12,1,0)) -> 1
A21: Wave 2 active (0.5 in launch quarter) | B21: factor | C21: =IF(C18=Assumptions!$G$13,0.5,IF(C18>Assumptions!$G$13,1,0)) -> 0 | D21: =IF(D18=Assumptions!$G$13,0.5,IF(D18>Assumptions!$G$13,1,0)) -> 0 | E21: =IF(E18=Assumptions!$G$13,0.5,IF(E18>Assumptions!$G$13,1,0)) -> 0 | F21: =IF(F18=Assumptions!$G$13,0.5,IF(F18>Assumptions!$G$13,1,0)) -> 0 | G21: =IF(G18=Assumptions!$G$13,0.5,IF(G18>Assumptions!$G$13,1,0)) -> 0.5 | H21: =IF(H18=Assumptions!$G$13,0.5,IF(H18>Assumptions!$G$13,1,0)) -> 1 | I21: =IF(I18=Assumptions!$G$13,0.5,IF(I18>Assumptions!$G$13,1,0)) -> 1 | J21: =IF(J18=Assumptions!$G$13,0.5,IF(J18>Assumptions!$G$13,1,0)) -> 1 | ... N21: =IF(N18=Assumptions!$G$13,0.5,IF(N18>Assumptions!$G$13,1,0)) -> 1
A22: Wave 3 active (0.5 in launch quarter) | B22: factor | C22: =IF(C18=Assumptions!$G$14,0.5,IF(C18>Assumptions!$G$14,1,0)) -> 0 | D22: =IF(D18=Assumptions!$G$14,0.5,IF(D18>Assumptions!$G$14,1,0)) -> 0 | E22: =IF(E18=Assumptions!$G$14,0.5,IF(E18>Assumptions!$G$14,1,0)) -> 0 | F22: =IF(F18=Assumptions!$G$14,0.5,IF(F18>Assumptions!$G$14,1,0)) -> 0 | G22: =IF(G18=Assumptions!$G$14,0.5,IF(G18>Assumptions!$G$14,1,0)) -> 0 | H22: =IF(H18=Assumptions!$G$14,0.5,IF(H18>Assumptions!$G$14,1,0)) -> 0 | I22: =IF(I18=Assumptions!$G$14,0.5,IF(I18>Assumptions!$G$14,1,0)) -> 0.5 | J22: =IF(J18=Assumptions!$G$14,0.5,IF(J18>Assumptions!$G$14,1,0)) -> 1 | ... N22: =IF(N18=Assumptions!$G$14,0.5,IF(N18>Assumptions!$G$14,1,0)) -> 1
A23: Active SAM accounts in launched waves | B23: accounts | C23: =$C$6*C20+$C$7*C21+$C$8*C22 -> 640.58396 | D23: =$C$6*D20+$C$7*D21+$C$8*D22 -> 1281.1679 | E23: =$C$6*E20+$C$7*E21+$C$8*E22 -> 1281.1679 | F23: =$C$6*F20+$C$7*F21+$C$8*F22 -> 1281.1679 | G23: =$C$6*G20+$C$7*G21+$C$8*G22 -> 1733.5262 | H23: =$C$6*H20+$C$7*H21+$C$8*H22 -> 2185.8845 | I23: =$C$6*I20+$C$7*I21+$C$8*I22 -> 3676.6906 | J23: =$C$6*J20+$C$7*J21+$C$8*J22 -> 5167.4968 | ... N23: =$C$6*N20+$C$7*N21+$C$8*N22 -> 5167.4968 | P23: =F23 -> 1281.1679 | Q23: =J23 -> 5167.4968 | R23: =N23 -> 5167.4968 | S23: =R23 -> 5167.4968
A24: Accounts sequenced by Clay-run outbound | B24: accounts | C24: =C23*Assumptions!$G$17*C19 -> 256.23359 | D24: =D23*Assumptions!$G$17*D19 -> 512.46717 | E24: =E23*Assumptions!$G$17*E19 -> 512.46717 | F24: =F23*Assumptions!$G$17*F19 -> 512.46717 | G24: =G23*Assumptions!$G$17*G19 -> 693.41048 | H24: =H23*Assumptions!$G$17*H19 -> 874.35379 | I24: =I23*Assumptions!$G$17*I19 -> 1470.6763 | J24: =J23*Assumptions!$G$17*J19 -> 2066.9987 | ... N24: =N23*Assumptions!$G$17*N19 -> 2066.9987 | P24: =SUM(C24:F24) -> 1793.6351 | Q24: =SUM(G24:J24) -> 5105.4392 | R24: =SUM(K24:N24) -> 8267.9949 | S24: =SUM(P24:R24) -> 15167.069
A25: Leads — outbound meetings | B25: leads | C25: =C24*Assumptions!$G$18 -> 7.6870076 | D25: =D24*Assumptions!$G$18 -> 15.374015 | E25: =E24*Assumptions!$G$18 -> 15.374015 | F25: =F24*Assumptions!$G$18 -> 15.374015 | G25: =G24*Assumptions!$G$18 -> 20.802314 | H25: =H24*Assumptions!$G$18 -> 26.230614 | I25: =I24*Assumptions!$G$18 -> 44.120288 | J25: =J24*Assumptions!$G$18 -> 62.009961 | ... N25: =N24*Assumptions!$G$18 -> 62.009961 | P25: =SUM(C25:F25) -> 53.809053 | Q25: =SUM(G25:J25) -> 153.16318 | R25: =SUM(K25:N25) -> 248.03985 | S25: =SUM(P25:R25) -> 455.01208
A26: Leads — inbound / template-led | B26: leads | C26: =C23*Assumptions!$G$19*C19 -> 6.4058396 | D26: =D23*Assumptions!$G$19*D19 -> 12.811679 | E26: =E23*Assumptions!$G$19*E19 -> 12.811679 | F26: =F23*Assumptions!$G$19*F19 -> 12.811679 | G26: =G23*Assumptions!$G$19*G19 -> 17.335262 | H26: =H23*Assumptions!$G$19*H19 -> 21.858845 | I26: =I23*Assumptions!$G$19*I19 -> 36.766906 | J26: =J23*Assumptions!$G$19*J19 -> 51.674968 | ... N26: =N23*Assumptions!$G$19*N19 -> 51.674968 | P26: =SUM(C26:F26) -> 44.840878 | Q26: =SUM(G26:J26) -> 127.63598 | R26: =SUM(K26:N26) -> 206.69987 | S26: =SUM(P26:R26) -> 379.17673
A27: Active partners | B27: partners | C27: =IF(C19=1,MIN(Assumptions!$G$22,Assumptions!$G$20+Assumptions!$G$21*(C18-1)),0) -> 2 | D27: =IF(D19=1,MIN(Assumptions!$G$22,Assumptions!$G$20+Assumptions!$G$21*(D18-1)),0) -> 3 | E27: =IF(E19=1,MIN(Assumptions!$G$22,Assumptions!$G$20+Assumptions!$G$21*(E18-1)),0) -> 4 | F27: =IF(F19=1,MIN(Assumptions!$G$22,Assumptions!$G$20+Assumptions!$G$21*(F18-1)),0) -> 5 | G27: =IF(G19=1,MIN(Assumptions!$G$22,Assumptions!$G$20+Assumptions!$G$21*(G18-1)),0) -> 6 | H27: =IF(H19=1,MIN(Assumptions!$G$22,Assumptions!$G$20+Assumptions!$G$21*(H18-1)),0) -> 7 | I27: =IF(I19=1,MIN(Assumptions!$G$22,Assumptions!$G$20+Assumptions!$G$21*(I18-1)),0) -> 8 | J27: =IF(J19=1,MIN(Assumptions!$G$22,Assumptions!$G$20+Assumptions!$G$21*(J18-1)),0) -> 9 | ... N27: =IF(N19=1,MIN(Assumptions!$G$22,Assumptions!$G$20+Assumptions!$G$21*(N18-1)),0) -> 10 | P27: =F27 -> 5 | Q27: =J27 -> 9 | R27: =N27 -> 10 | S27: =R27 -> 10
A28: Leads — partner-sourced | B28: leads | C28: =C27*Assumptions!$G$23 -> 6 | D28: =D27*Assumptions!$G$23 -> 9 | E28: =E27*Assumptions!$G$23 -> 12 | F28: =F27*Assumptions!$G$23 -> 15 | G28: =G27*Assumptions!$G$23 -> 18 | H28: =H27*Assumptions!$G$23 -> 21 | I28: =I27*Assumptions!$G$23 -> 24 | J28: =J27*Assumptions!$G$23 -> 27 | ... N28: =N27*Assumptions!$G$23 -> 30 | P28: =SUM(C28:F28) -> 42 | Q28: =SUM(G28:J28) -> 90 | R28: =SUM(K28:N28) -> 120 | S28: =SUM(P28:R28) -> 252
A29: Total leads | B29: leads | C29: =C25+C26+C28 -> 20.092847 | D29: =D25+D26+D28 -> 37.185694 | E29: =E25+E26+E28 -> 40.185694 | F29: =F25+F26+F28 -> 43.185694 | G29: =G25+G26+G28 -> 56.137577 | H29: =H25+H26+H28 -> 69.089459 | I29: =I25+I26+I28 -> 104.88719 | J29: =J25+J26+J28 -> 140.68493 | ... N29: =N25+N26+N28 -> 143.68493 | P29: =SUM(C29:F29) -> 140.64993 | Q29: =SUM(G29:J29) -> 370.79916 | R29: =SUM(K29:N29) -> 574.73972 | S29: =SUM(P29:R29) -> 1086.1888
A30: Qualified (SQL) — outbound + inbound | B30: SQLs | C30: =(C25+C26)*Assumptions!$G$24 -> 6.3417813 | D30: =(D25+D26)*Assumptions!$G$24 -> 12.683563 | E30: =(E25+E26)*Assumptions!$G$24 -> 12.683563 | F30: =(F25+F26)*Assumptions!$G$24 -> 12.683563 | G30: =(G25+G26)*Assumptions!$G$24 -> 17.161909 | H30: =(H25+H26)*Assumptions!$G$24 -> 21.640256 | I30: =(I25+I26)*Assumptions!$G$24 -> 36.399237 | J30: =(J25+J26)*Assumptions!$G$24 -> 51.158218 | ... N30: =(N25+N26)*Assumptions!$G$24 -> 51.158218 | P30: =SUM(C30:F30) -> 44.392469 | Q30: =SUM(G30:J30) -> 126.35962 | R30: =SUM(K30:N30) -> 204.63287 | S30: =SUM(P30:R30) -> 375.38496
A31: Qualified (SQL) — partner | B31: SQLs | C31: =C28*Assumptions!$G$25 -> 3.6 | D31: =D28*Assumptions!$G$25 -> 5.4 | E31: =E28*Assumptions!$G$25 -> 7.2 | F31: =F28*Assumptions!$G$25 -> 9 | G31: =G28*Assumptions!$G$25 -> 10.8 | H31: =H28*Assumptions!$G$25 -> 12.6 | I31: =I28*Assumptions!$G$25 -> 14.4 | J31: =J28*Assumptions!$G$25 -> 16.2 | ... N31: =N28*Assumptions!$G$25 -> 18 | P31: =SUM(C31:F31) -> 25.2 | Q31: =SUM(G31:J31) -> 54 | R31: =SUM(K31:N31) -> 72 | S31: =SUM(P31:R31) -> 151.2
A32: Opportunities created | B32: opps | C32: =(C30+C31)*Assumptions!$G$26 -> 4.4738016 | D32: =(D30+D31)*Assumptions!$G$26 -> 8.1376031 | E32: =(E30+E31)*Assumptions!$G$26 -> 8.9476031 | F32: =(F30+F31)*Assumptions!$G$26 -> 9.7576031 | G32: =(G30+G31)*Assumptions!$G$26 -> 12.582859 | H32: =(H30+H31)*Assumptions!$G$26 -> 15.408115 | I32: =(I30+I31)*Assumptions!$G$26 -> 22.859657 | J32: =(J30+J31)*Assumptions!$G$26 -> 30.311198 | ... N32: =(N30+N31)*Assumptions!$G$26 -> 31.121198 | P32: =SUM(C32:F32) -> 31.316611 | Q32: =SUM(G32:J32) -> 81.16183 | R32: =SUM(K32:N32) -> 124.48479 | S32: =SUM(P32:R32) -> 236.96323
A33: of which partner-sourced | B33: opps | C33: =C31*Assumptions!$G$26 -> 1.62 | D33: =D31*Assumptions!$G$26 -> 2.43 | E33: =E31*Assumptions!$G$26 -> 3.24 | F33: =F31*Assumptions!$G$26 -> 4.05 | G33: =G31*Assumptions!$G$26 -> 4.86 | H33: =H31*Assumptions!$G$26 -> 5.67 | I33: =I31*Assumptions!$G$26 -> 6.48 | J33: =J31*Assumptions!$G$26 -> 7.29 | ... N33: =N31*Assumptions!$G$26 -> 8.1 | P33: =SUM(C33:F33) -> 11.34 | Q33: =SUM(G33:J33) -> 24.3 | R33: =SUM(K33:N33) -> 32.4 | S33: =SUM(P33:R33) -> 68.04
A34: Demand-limited wins (opps from 1–2 quarters earlier × win rate) | B34: wins | C34: =0*Assumptions!$G$27 -> 0 | D34: =IF(Assumptions!$G$28=1,C32,0)*Assumptions!$G$27 -> 1.2526644 | E34: =IF(Assumptions!$G$28=1,D32,C32)*Assumptions!$G$27 -> 2.2785289 | F34: =IF(Assumptions!$G$28=1,E32,D32)*Assumptions!$G$27 -> 2.5053289 | G34: =IF(Assumptions!$G$28=1,F32,E32)*Assumptions!$G$27 -> 2.7321289 | H34: =IF(Assumptions!$G$28=1,G32,F32)*Assumptions!$G$27 -> 3.5232006 | I34: =IF(Assumptions!$G$28=1,H32,G32)*Assumptions!$G$27 -> 4.3142723 | J34: =IF(Assumptions!$G$28=1,I32,H32)*Assumptions!$G$27 -> 6.4007039 | K34: =IF(Assumptions!$G$28=1,J32,I32)*Assumptions!$G$27 -> 8.4871355 | L34: =IF(Assumptions!$G$28=1,K32,J32)*Assumptions!$G$27 -> 8.7139355 | ... N34: =IF(Assumptions!$G$28=1,M32,L32)*Assumptions!$G$27 -> 8.7139355 | P34: =SUM(C34:F34) -> 6.0365222 | Q34: =SUM(G34:J34) -> 16.970306 | R34: =SUM(K34:N34) -> 34.628942 | S34: =SUM(P34:R34) -> 57.63577
A35: Partner-sourced share of wins | B35: % | C35: =IFERROR(0/0,0) -> 0 | D35: =IFERROR(IF(Assumptions!$G$28=1,C33,0)/IF(Assumptions!$G$28=1,C32,0),0) -> 0.36210815 | E35: =IFERROR(IF(Assumptions!$G$28=1,D33,C33)/IF(Assumptions!$G$28=1,D32,C32),0) -> 0.29861373 | F35: =IFERROR(IF(Assumptions!$G$28=1,E33,D33)/IF(Assumptions!$G$28=1,E32,D32),0) -> 0.36210815 | G35: =IFERROR(IF(Assumptions!$G$28=1,F33,E33)/IF(Assumptions!$G$28=1,F32,E32),0) -> 0.41506095 | H35: =IFERROR(IF(Assumptions!$G$28=1,G33,F33)/IF(Assumptions!$G$28=1,G32,F32),0) -> 0.38623972 | I35: =IFERROR(IF(Assumptions!$G$28=1,H33,G33)/IF(Assumptions!$G$28=1,H32,G32),0) -> 0.3679879 | J35: =IFERROR(IF(Assumptions!$G$28=1,I33,H33)/IF(Assumptions!$G$28=1,I32,H32),0) -> 0.28346882 | K35: =IFERROR(IF(Assumptions!$G$28=1,J33,I33)/IF(Assumptions!$G$28=1,J32,I32),0) -> 0.24050517 | L35: =IFERROR(IF(Assumptions!$G$28=1,K33,J33)/IF(Assumptions!$G$28=1,K32,J32),0) -> 0.26027276 | ... N35: =IFERROR(IF(Assumptions!$G$28=1,M33,L33)/IF(Assumptions!$G$28=1,M32,L32),0) -> 0.26027276
A36: Self-serve SMB wins (no AE) | B36: wins | C36: =C34*Assumptions!$G$29*Assumptions!$G$32 -> 0 | D36: =D34*Assumptions!$G$29*Assumptions!$G$32 -> 0.18789967 | E36: =E34*Assumptions!$G$29*Assumptions!$G$32 -> 0.34177933 | F36: =F34*Assumptions!$G$29*Assumptions!$G$32 -> 0.37579933 | G36: =G34*Assumptions!$G$29*Assumptions!$G$32 -> 0.40981933 | H36: =H34*Assumptions!$G$29*Assumptions!$G$32 -> 0.52848009 | I36: =I34*Assumptions!$G$29*Assumptions!$G$32 -> 0.64714085 | J36: =J34*Assumptions!$G$29*Assumptions!$G$32 -> 0.96010559 | ... N36: =N34*Assumptions!$G$29*Assumptions!$G$32 -> 1.3070903 | P36: =SUM(C36:F36) -> 0.90547833 | Q36: =SUM(G36:J36) -> 2.5455459 | R36: =SUM(K36:N36) -> 5.1943413 | S36: =SUM(P36:R36) -> 8.6453655
A37: Sales-assisted demand | B37: wins | C37: =C34-C36 -> 0 | D37: =D34-D36 -> 1.0647648 | E37: =E34-E36 -> 1.9367495 | F37: =F34-F36 -> 2.1295295 | G37: =G34-G36 -> 2.3223095 | H37: =H34-H36 -> 2.9947205 | I37: =I34-I36 -> 3.6671315 | J37: =J34-J36 -> 5.4405983 | ... N37: =N34-N36 -> 7.4068452 | P37: =SUM(C37:F37) -> 5.1310439 | Q37: =SUM(G37:J37) -> 14.42476 | R37: =SUM(K37:N37) -> 29.434601 | S37: =SUM(P37:R37) -> 48.990404
A38: Dedicated AEs (headcount) | B38: FTE | C38: =Assumptions!$D$106 -> 0 | D38: =Assumptions!$E$106 -> 0 | E38: =Assumptions!$F$106 -> 0 | F38: =Assumptions!$G$106 -> 0 | G38: =Assumptions!$H$106 -> 0 | H38: =Assumptions!$I$106 -> 0 | I38: =Assumptions!$J$106 -> 0 | J38: =Assumptions!$K$106 -> 0 | K38: =Assumptions!$L$106 -> 0 | L38: =Assumptions!$M$106 -> 0 | M38: =Assumptions!$N$106 -> 0 | N38: =Assumptions!$O$106 -> 0 | P38: =F38 -> 0 | Q38: =J38 -> 0 | R38: =N38 -> 0 | S38: =R38 -> 0
A39: Ramped dedicated AEs (≈6-month ramp) | B39: FTE | C39: =0 -> 0 | D39: =0.5*C38 -> 0 | E39: =C38+0.5*(D38-C38) -> 0 | F39: =D38+0.5*(E38-D38) -> 0 | G39: =E38+0.5*(F38-E38) -> 0 | H39: =F38+0.5*(G38-F38) -> 0 | I39: =G38+0.5*(H38-G38) -> 0 | J39: =H38+0.5*(I38-H38) -> 0 | K39: =I38+0.5*(J38-I38) -> 0 | L39: =J38+0.5*(K38-J38) -> 0 | ... N39: =L38+0.5*(M38-L38) -> 0 | P39: =F39 -> 0 | Q39: =J39 -> 0 | R39: =N39 -> 0 | S39: =R39 -> 0
A40: Sales capacity (dedicated + shared AEs) | B40: deals | C40: =(C39+Assumptions!$G$99*C19)*$C$15 -> 20.027205 | D40: =(D39+Assumptions!$G$99*D19)*$C$15 -> 20.027205 | E40: =(E39+Assumptions!$G$99*E19)*$C$15 -> 20.027205 | F40: =(F39+Assumptions!$G$99*F19)*$C$15 -> 20.027205 | G40: =(G39+Assumptions!$G$99*G19)*$C$15 -> 20.027205 | H40: =(H39+Assumptions!$G$99*H19)*$C$15 -> 20.027205 | I40: =(I39+Assumptions!$G$99*I19)*$C$15 -> 20.027205 | J40: =(J39+Assumptions!$G$99*J19)*$C$15 -> 20.027205 | ... N40: =(N39+Assumptions!$G$99*N19)*$C$15 -> 20.027205 | P40: =SUM(C40:F40) -> 80.108821 | Q40: =SUM(G40:J40) -> 80.108821 | R40: =SUM(K40:N40) -> 80.108821 | S40: =SUM(P40:R40) -> 240.32646
A41: Sales-assisted wins = MIN(demand, capacity) | B41: wins | C41: =MIN(C37,C40) -> 0 | D41: =MIN(D37,D40) -> 1.0647648 | E41: =MIN(E37,E40) -> 1.9367495 | F41: =MIN(F37,F40) -> 2.1295295 | G41: =MIN(G37,G40) -> 2.3223095 | H41: =MIN(H37,H40) -> 2.9947205 | I41: =MIN(I37,I40) -> 3.6671315 | J41: =MIN(J37,J40) -> 5.4405983 | ... N41: =MIN(N37,N40) -> 7.4068452 | P41: =SUM(C41:F41) -> 5.1310439 | Q41: =SUM(G41:J41) -> 14.42476 | R41: =SUM(K41:N41) -> 29.434601 | S41: =SUM(P41:R41) -> 48.990404
...

Sheet Revenue Model
A1: Revenue Model — customers, ARR and recognized revenue
A2: ARR = prior ARR × NRR^(1/4) + new customers × ACV. Recognized revenue = average ARR ÷ 4 (kept separate from ARR). Customers decay at GRR^(1/4).
A3: ="Live run: "&Assumptions!$E$4&" scenario · "&Assumptions!$E$5 -> Live run: Base scenario · Partner-led pilot
A5: Customers, ARR and revenue | B5: Unit / note | C5: Q1 2027 | D5: Q2 2027 | E5: Q3 2027 | F5: Q4 2027 | G5: Q1 2028 | H5: Q2 2028 | I5: Q3 2028 | J5: Q4 2028 | K5: Q1 2029 | L5: Q2 2029 | M5: Q3 2029 | N5: Q4 2029 | P5: 2027 | Q5: 2028 | R5: 2029 | S5: 2027–29
A6: Customers — SMB | B6: customers | C6: =0*Assumptions!$G$54^(1/4)+'GTM Funnel'!C44 -> 0 | D6: =C6*Assumptions!$G$54^(1/4)+'GTM Funnel'!D44 -> 0.62633222 | E6: =D6*Assumptions!$G$54^(1/4)+'GTM Funnel'!E44 -> 1.7458966 | F6: =E6*Assumptions!$G$54^(1/4)+'GTM Funnel'!F44 -> 2.9436472 | G6: =F6*Assumptions!$G$54^(1/4)+'GTM Funnel'!G44 -> 4.2171249 | H6: =G6*Assumptions!$G$54^(1/4)+'GTM Funnel'!H44 -> 5.8460837 | I6: =H6*Assumptions!$G$54^(1/4)+'GTM Funnel'!I44 -> 7.8193425 | J6: =I6*Assumptions!$G$54^(1/4)+'GTM Funnel'!J44 -> 10.773752 | K6: =J6*Assumptions!$G$54^(1/4)+'GTM Funnel'!K44 -> 14.678452 | ... N6: =M6*Assumptions!$G$54^(1/4)+'GTM Funnel'!N44 -> 26.000606 | P6: =F6 -> 2.9436472 | Q6: =J6 -> 10.773752 | R6: =N6 -> 26.000606 | S6: =R6 -> 26.000606
