Workbook

Sheet Cover
A1: 07 — Financial Model v2: should Clay fund a U.S. vertical program in 2027–2029?
A2: Independent portfolio case study by Zhuoran (Zora) Wang · Not commissioned by or affiliated with Clay Labs Inc. · v2 rebuilt 2026-10-19 after partner review
A4: Question | B4: Does any vertical program (distribution or professional services; lean pilot, sales-led team or solution play) create value above a 12% hurdle and above Option 0 — the same money spent in Clay's core motion?
A5: Structure | B5: Assumptions (3 selectors) → Market Sizing → ACV Build → GTM Funnel → Revenue Model → Unit Economics (live) → Scenarios, Sensitivity (full model copies on Engine Runs) → Monte Carlo (Python mirror, reconciled run by run) → Executive Output. Change Log maps v1 → v2.
A6: Time and units | B6: Quarterly, Q1 2027–Q4 2029; annual totals P–R, 2027–29 in S. US$ nominal. ARR is end-of-quarter run-rate; recognized revenue = average ARR ÷ 4.
A7: Valuation | B7: NPV = Σ PV[(gross profit × (1 − incrementality haircut)) − incremental cost] + PV of 5 years of gross profit from the 2029 ARR base (net of CS, decaying at GRR, haircut). Option 0 NPV is computed on the same non-CS spend.
A8: Evidence classes | B8: A verified fact · B benchmark · C analyst estimate · D scenario assumption · E recommendation. Each input row carries its class, Monte Carlo group and source.
A9: Color legend | B9: Blue = input · black = formula · green = link to another tab · yellow fill = judgment · green fill = key output · red fill = negative NPV.
A10: Not a forecast | B10: Outputs are scenario and simulation estimates, not Clay forecasts. Monte Carlo values are static results of appendix/clay_engine.py (seed 42).

Sheet Executive Output
A1: Executive Output — is any vertical program worth funding in 2027–2029? (v2, after partner review)
A2: Scenario and simulation outputs are illustrative estimates built from public data and labeled assumptions. They are not Clay forecasts and use no Clay internal data.
A3: ="Live model: "&Assumptions!$E$5&" · "&Assumptions!$E$4&" · "&Assumptions!$E$6&" (selectors on Assumptions D4:D6)" -> Live model: Industrial distribution · Base · Lean partner-led pilot (selectors on Assumptions D4:D6)
A5: Option (Base case, deterministic) | B5: NPV at 12% | C5: NPV advantage vs Option 0 | D5: Exit ARR Q4 2029 | E5: Average first-year ACV | F5: CAC payback, 2029 cohort | G5: Cumulative P&L 2027–29 | H5: Peak investment
A6: Industrial distribution — Lean partner-led pilot | B6: =Scenarios!D5 -> -1892877 | C6: =Scenarios!D7 -> -3405399 | D6: =Scenarios!D8 -> 509612.73 | E6: =Scenarios!D11 -> 8847.9735 | F6: =Scenarios!D14 -> 53.740167 | G6: =Scenarios!D16 -> -2645899.1 | H6: =Scenarios!D17 -> -2645899.1
A7: Industrial distribution — Sales-led vertical team | B7: =Scenarios!G5 -> -5438648.7 | C7: =Scenarios!G7 -> -9174954.9 | D7: =Scenarios!G8 -> 820721.59 | E7: =Scenarios!G11 -> 8863.8206 | F7: =Scenarios!G14 -> 117.74997 | G7: =Scenarios!G16 -> -7222893 | H7: =Scenarios!G17 -> -7222893
A8: Industrial distribution — Solution play (no vertical team) | B8: =Scenarios!J5 -> -544641.96 | C8: =Scenarios!J7 -> -1072505.1 | D8: =Scenarios!J8 -> 246156.7 | E8: =Scenarios!J11 -> 8850.6126 | F8: =Scenarios!J14 -> 25.70966 | G8: =Scenarios!J16 -> -821017.4 | H8: =Scenarios!J17 -> -821017.4
A9: Professional services — Lean partner-led pilot | B9: =Scenarios!M5 -> -2044076.8 | C9: =Scenarios!M7 -> -3569477.8 | D9: =Scenarios!M8 -> 680163.89 | E9: =Scenarios!M11 -> 6863.9789 | F9: =Scenarios!M14 -> 42.271735 | G9: =Scenarios!M16 -> -2610408.3 | H9: =Scenarios!M17 -> -2610408.3
A10: Professional services — Sales-led vertical team | B10: =Scenarios!P5 -> -5731151.9 | C10: =Scenarios!P7 -> -9458007.8 | D10: =Scenarios!P8 -> 914355.66 | E10: =Scenarios!P11 -> 6868.9908 | F10: =Scenarios!P14 -> 110.90519 | G10: =Scenarios!P16 -> -7171119.1 | H10: =Scenarios!P17 -> -7171119.1
A11: Professional services — Solution play (no vertical team) | B11: =Scenarios!S5 -> -620644.16 | C11: =Scenarios!S7 -> -1153233.5 | D11: =Scenarios!S8 -> 317295.3 | E11: =Scenarios!S11 -> 6865.7947 | F11: =Scenarios!S14 -> 20.487621 | G11: =Scenarios!S16 -> -803970.51 | H11: =Scenarios!S17 -> -803970.51
A13: Simulation (5,000 draws; correlated inputs) | B13: Mean NPV | C13: P10 | D13: P90 | E13: P(NPV > 0) | F13: P(beats Option 0) | G13: Stopped at Gate 1 | H13: Scaled at Gate 1
A14: Industrial distribution — Lean pilot, staged | B14: ='Monte Carlo'!B6 -> -1486097 | C14: ='Monte Carlo'!C6 -> -1979643 | D14: ='Monte Carlo'!E6 -> -868884 | E14: ='Monte Carlo'!F6 -> 0 | F14: ='Monte Carlo'!H6 -> 0 | G14: ='Monte Carlo'!I6 -> 0.337 | H14: ='Monte Carlo'!J6 -> 0.0112
A15: Industrial distribution — Sales-led team | B15: ='Monte Carlo'!B7 -> -5315702 | C15: ='Monte Carlo'!C7 -> -5740374 | D15: ='Monte Carlo'!E7 -> -4775974 | E15: ='Monte Carlo'!F7 -> 0 | F15: ='Monte Carlo'!H7 -> 0 | G15: ='Monte Carlo'!I7 -> 0 | H15: ='Monte Carlo'!J7 -> 0
A16: Industrial distribution — Solution play | B16: ='Monte Carlo'!B8 -> -511201 | C16: ='Monte Carlo'!C8 -> -604824 | D16: ='Monte Carlo'!E8 -> -388453 | E16: ='Monte Carlo'!F8 -> 0.0002 | F16: ='Monte Carlo'!H8 -> 0 | G16: ='Monte Carlo'!I8 -> 0 | H16: ='Monte Carlo'!J8 -> 0
A17: Professional services — Lean pilot, staged | B17: ='Monte Carlo'!B10 -> -1663742 | C17: ='Monte Carlo'!C10 -> -2146572 | D17: ='Monte Carlo'!E10 -> -897861 | E17: ='Monte Carlo'!F10 -> 0 | F17: ='Monte Carlo'!H10 -> 0 | G17: ='Monte Carlo'!I10 -> 0.3346 | H17: ='Monte Carlo'!J10 -> 0.0184
A18: Professional services — Sales-led team | B18: ='Monte Carlo'!B11 -> -5726126 | C18: ='Monte Carlo'!C11 -> -5939510 | D18: ='Monte Carlo'!E11 -> -5456822 | E18: ='Monte Carlo'!F11 -> 0 | F18: ='Monte Carlo'!H11 -> 0 | G18: ='Monte Carlo'!I11 -> 0 | H18: ='Monte Carlo'!J11 -> 0
A19: Professional services — Solution play | B19: ='Monte Carlo'!B12 -> -614778 | C19: ='Monte Carlo'!C12 -> -673722 | D19: ='Monte Carlo'!E12 -> -544597 | E19: ='Monte Carlo'!F12 -> 0 | F19: ='Monte Carlo'!H12 -> 0 | G19: ='Monte Carlo'!I12 -> 0 | H19: ='Monte Carlo'!J12 -> 0
A21: Model checks
A22: Live model reconciles to engine runs (0 = pass) | B22: =ABS(Scenarios!C42)+ABS(Scenarios!C43) -> 0
A23: Python engine reconciles to Excel engine (max abs. NPV difference, $) | B23: ='Monte Carlo'!D54 -> 0
A25: What the model shows (v2)
A26: 1. No option clears a 12% hurdle in Base. Distribution lean pilot: NPV −$1.89M, exit ARR $0.51M, average first-year ACV $8.8K once the win mix is derived from the account base (v1 assumed $13.8K).
A27: 2. Upside is NPV-positive (+$1.53M) only when favorable values occur together. With correlated uncertainty, the staged pilot's P(NPV > 0) is 0% and its P90 is −$0.87M; even near-comonotonic inputs or 2× wider ranges keep P(NPV > 0) at or below 10%.
A28: 3. Against Option 0 (the same spend in Clay's core motion at a discounted benchmark payback) every staffed option loses, in Base and in Upside. The bar a vertical must clear is the core's return, not zero.
A29: 4. A sales-led team now builds its own pipeline and adds ARR (exit $0.82M vs $0.51M lean), but NPV falls to −$5.44M: a ~5,000-account market cannot carry six AEs.
A30: 5. Professional services is no better on the same engine: list-price ACV sits at the Growth floor for SMB and Mid-Market, and more of its wins would have come anyway (Base NPV −$2.04M).
A31: 6. The cheapest test — a solution play with templates and data providers but no vertical team — loses least (distribution Base NPV −$0.54M; simulated P(NPV > 0) 0%) and is the only option that beats Option 0 in Upside. Recommendation: validate before staffing anything.

Sheet Assumptions
A1: Assumptions — every input, by segment and scenario (v2)
A2: Edit blue cells only. 'Live' feeds the main model via the three selectors. Scenarios, Sensitivity and Monte Carlo run their own copies. Segment-level market inputs are fixed across scenarios: the universe does not flex, only performance does.
A4: Scenario (1 = Downside, 2 = Base, 3 = Upside) | D4: 2 | E4: =CHOOSE($D$4,"Downside","Base","Upside") -> Base
A5: Segment (1 = Industrial distribution, 2 = Professional services) | D5: 1 | E5: =CHOOSE($D$5,"Industrial distribution","Professional services") -> Industrial distribution
A6: Motion (1 = Lean partner-led pilot, 2 = Sales-led vertical team, 3 = Solution play, no vertical team) | D6: 1 | E6: =CHOOSE($D$6,"Lean partner-led pilot","Sales-led vertical team","Solution play") -> Lean partner-led pilot
A8: ID | B8: Input | C8: Unit | D8: Dist: Downside | E8: Dist: Base | F8: Dist: Upside | G8: PS: Downside | H8: PS: Base | I8: PS: Upside | J8: Live | K8: Class | L8: MC group | M8: Source / rationale
A9: MARKET (fixed across scenarios)
A10: A1 | B10: SAM filter 1: active outbound / territory sales motion | C10: % | D10: 0.8 | E10: 0.8 | F10: 0.8 | G10: 0.55 | H10: 0.55 | I10: 0.55 | J10: =INDEX(D10:I10,1,(Assumptions!$D$5-1)*3+Assumptions!$D$4) -> 0.8 | K10: D | L10: fixed | M10: Phase 1 (02 A4/A6); sales occupations 22.0% vs 6.2% (S15)
A11: A2 | B11: SAM filter 2: CRM in use (integrable today) | C11: % | D11: 0.56 | E11: 0.56 | F11: 0.56 | G11: 0.7 | H11: 0.7 | I11: 0.7 | J11: =INDEX(D11:I11,1,(Assumptions!$D$5-1)*3+Assumptions!$D$4) -> 0.56 | K11: B/D | L11: fixed | M11: Dist: 56% use CRM, Phocas/DSG 2026 (S25) — newest evidence (v1 used 65%). PS: no public rate; Phase 1 assumption (02 A9)
A12: A3 | B12: Share of SAM already Clay customers (excluded) | C12: % | D12: 0.03 | E12: 0.03 | F12: 0.03 | G12: 0.1 | H12: 0.1 | I12: 0.1 | J12: =INDEX(D12:I12,1,(Assumptions!$D$5-1)*3+Assumptions!$D$4) -> 0.03 | K12: D | L12: fixed | M12: No public data. PS higher: Clay markets to PS (S06) and IT services is a top industry of detected Clay users (S32)
A13: A4 | B13: Wave 1 launch quarter (Dist 4236 electrical · PS 5413 A&E) | C13: qtr | D13: 1 | E13: 1 | F13: 1 | G13: 1 | H13: 1 | I13: 1 | J13: =INDEX(D13:I13,1,(Assumptions!$D$5-1)*3+Assumptions!$D$4) -> 1 | K13: E | L13: fixed | M13: Beachheads: 06 drilldown (Dist); A&E pursuit-data gap, Deltek/Unanet ecosystem (PS, 05)
A14: A5 | B14: Wave 2 launch quarter (Dist 4237 PHVAC · PS 5416 consulting) | C14: qtr | D14: 7 | E14: 5 | F14: 4 | G14: 7 | H14: 5 | I14: 4 | J14: =INDEX(D14:I14,1,(Assumptions!$D$5-1)*3+Assumptions!$D$4) -> 5 | K14: D | L14: timing | M14: After Gate 1; Downside delays
A15: A6 | B15: Wave 3 launch quarter, 99 = never (Dist 4238 MRO · PS 5415 IT services) | C15: qtr | D15: 99 | E15: 7 | F15: 6 | G15: 99 | H15: 7 | I15: 6 | J15: =INDEX(D15:I15,1,(Assumptions!$D$5-1)*3+Assumptions!$D$4) -> 7 | K15: D | L15: timing | M15: PS excludes 5418 advertising/PR: Clay's agency partners (channel conflict) [E]
A16: DEMAND AND FUNNEL
A17: A7 | B17: Automated outbound coverage: share of active SAM sequenced per quarter | C17: % | D17: 0.3 | E17: 0.4 | F17: 0.5 | G17: 0.3 | H17: 0.4 | I17: 0.5 | J17: =INDEX(D17:I17,1,(Assumptions!$D$5-1)*3+Assumptions!$D$4) -> 0.4 | K17: D | L17: demand | M17: Clay-run outbound with its own product
A18: A8 | B18: ICP tilt: outbound weight on Mid-Market accounts (vs SMB = 1) | C18: x | D18: 2 | E18: 2 | F18: 2 | G18: 2 | H18: 2 | I18: 2 | J18: =INDEX(D18:I18,1,(Assumptions!$D$5-1)*3+Assumptions!$D$4) -> 2 | K18: E | L18: fixed | M18: Strategic lever (08 ICP); changes allocation of the same coverage, not the total
A19: A9 | B19: ICP tilt: outbound weight on Enterprise accounts (vs SMB = 1) | C19: x | D19: 2 | E19: 2 | F19: 2 | G19: 2 | H19: 2 | I19: 2 | J19: =INDEX(D19:I19,1,(Assumptions!$D$5-1)*3+Assumptions!$D$4) -> 2 | K19: E | L19: fixed | M19: Strategic lever
A20: A10 | B20: Meeting rate per account sequenced (first year) | C20: % | D20: 0.02 | E20: 0.03 | F20: 0.045 | G20: 0.015 | H20: 0.025 | I20: 0.035 | J20: =INDEX(D20:I20,1,(Assumptions!$D$5-1)*3+Assumptions!$D$4) -> 0.03 | K20: D | L20: demand | M20: Cold outbound 1–5% [K]; PS buyers more heavily prospected → lower
A21: A11 | B21: Meeting-rate retention per year of re-sequencing the same accounts | C21: x/yr | D21: 0.6 | E21: 0.75 | F21: 0.85 | G21: 0.6 | H21: 0.75 | I21: 0.85 | J21: =INDEX(D21:I21,1,(Assumptions!$D$5-1)*3+Assumptions!$D$4) -> 0.75 | K21: D | L21: indep | M21: Outbound fatigue (review m3); applied by wave age
A22: A12 | B22: Inbound / template MQLs per quarter at base program spend (% of active SAM) | C22: % | D22: 0.005 | E22: 0.01 | F22: 0.015 | G22: 0.01 | H22: 0.015 | I22: 0.02 | J22: =INDEX(D22:I22,1,(Assumptions!$D$5-1)*3+Assumptions!$D$4) -> 0.01 | K22: D | L22: demand | M22: PS more digital → higher
A23: A13 | B23: Cost per extra MQL from program spend above base | C23: $ | D23: 600 | E23: 400 | F23: 250 | G23: 600 | H23: 400 | I23: 250 | J23: =INDEX(D23:I23,1,(Assumptions!$D$5-1)*3+Assumptions!$D$4) -> 400 | K23: B/D | L23: cost | M23: SaaS CPL commonly cited at $200–350 (S55); niche industrial audience costs more
A24: A14 | B24: Ceiling on extra MQLs per quarter (% of active SAM) | C24: % | D24: 0.03 | E24: 0.03 | F24: 0.03 | G24: 0.03 | H24: 0.03 | I24: 0.03 | J24: =INDEX(D24:I24,1,(Assumptions!$D$5-1)*3+Assumptions!$D$4) -> 0.03 | K24: D | L24: fixed | M24: Diminishing returns: extra MQLs = cap × (1 − e^(−spend/(CPL × cap)))
A25: A15 | B25: Partners active at launch | C25: # | D25: 1 | E25: 2 | F25: 3 | G25: 2 | H25: 3 | I25: 4 | J25: =INDEX(D25:I25,1,(Assumptions!$D$5-1)*3+Assumptions!$D$4) -> 2 | K25: D | L25: demand | M25: Dist: no distribution partners visible today (S35). PS: agency ecosystem exists (S34) but competes
A26: A16 | B26: Partners added per quarter | C26: #/qtr | D26: 1 | E26: 1 | F26: 2 | G26: 1 | H26: 1 | I26: 2 | J26: =INDEX(D26:I26,1,(Assumptions!$D$5-1)*3+Assumptions!$D$4) -> 1 | K26: D | L26: demand
A27: A17 | B27: Partner network cap | C27: # | D27: 5 | E27: 10 | F27: 15 | G27: 6 | H27: 10 | I27: 14 | J27: =INDEX(D27:I27,1,(Assumptions!$D$5-1)*3+Assumptions!$D$4) -> 10 | K27: D | L27: demand
A28: A18 | B28: Introductions per active partner per quarter | C28: #/qtr | D28: 2 | E28: 3 | F28: 4 | G28: 2 | H28: 3 | I28: 4 | J28: =INDEX(D28:I28,1,(Assumptions!$D$5-1)*3+Assumptions!$D$4) -> 3 | K28: D | L28: demand
A29: A19 | B29: Outbound meeting → opportunity | C29: % | D29: 0.3 | E29: 0.4 | F29: 0.5 | G29: 0.3 | H29: 0.4 | I29: 0.5 | J29: =INDEX(D29:I29,1,(Assumptions!$D$5-1)*3+Assumptions!$D$4) -> 0.4 | K29: B/D | L29: demand | M29: SQL→opportunity 42% (S49); a booked meeting ≈ SQL stage (fixes v1 stage mix-up, review M4)
A30: A20 | B30: Partner introduction → opportunity | C30: % | D30: 0.4 | E30: 0.5 | F30: 0.6 | G30: 0.4 | H30: 0.5 | I30: 0.6 | J30: =INDEX(D30:I30,1,(Assumptions!$D$5-1)*3+Assumptions!$D$4) -> 0.5 | K30: D | L30: demand | M30: Warm, pre-vetted introductions
A31: A21 | B31: Inbound MQL → opportunity | C31: % | D31: 0.1 | E31: 0.16 | F31: 0.22 | G31: 0.1 | H31: 0.16 | I31: 0.22 | J31: =INDEX(D31:I31,1,(Assumptions!$D$5-1)*3+Assumptions!$D$4) -> 0.16 | K31: B | L31: demand | M31: MQL→SQL 39% × SQL→opp 42% (S49)
A32: A22 | B32: Win rate (opportunity → won) | C32: % | D32: 0.15 | E32: 0.21 | F32: 0.3 | G32: 0.13 | H32: 0.18 | I32: 0.25 | J32: =INDEX(D32:I32,1,(Assumptions!$D$5-1)*3+Assumptions!$D$4) -> 0.21 | K32: B/D | L32: demand | M32: HubSpot average 21% (S48) as Base for a new vertical with one reference (v1: 28%). PS lower: competitive position 2.3 vs 4.0 (04)
A33: A23 | B33: Mid-Market opportunity propensity per sequenced account (SMB = 1) | C33: x | D33: 1 | E33: 1 | F33: 1 | G33: 1 | H33: 1 | I33: 1 | J33: =INDEX(D33:I33,1,(Assumptions!$D$5-1)*3+Assumptions!$D$4) -> 1 | K33: D | L33: fixed
A34: A24 | B34: Enterprise opportunity propensity per sequenced account (SMB = 1) | C34: x | D34: 0.5 | E34: 0.7 | F34: 0.9 | G34: 0.5 | H34: 0.7 | I34: 0.9 | J34: =INDEX(D34:I34,1,(Assumptions!$D$5-1)*3+Assumptions!$D$4) -> 0.7 | K34: D | L34: value | M34: Enterprise: buying committees, incumbents; lower conversion (review C2)
A35: A25 | B35: Sales cycle, SMB & Mid-Market (quarters from opportunity to close) | C35: qtr | D35: 1 | E35: 1 | F35: 1 | G35: 1 | H35: 1 | I35: 1 | J35: =INDEX(D35:I35,1,(Assumptions!$D$5-1)*3+Assumptions!$D$4) -> 1 | K35: B | L35: fixed | M35: Deals < $25K close in 2–3 months (S48)
A36: A26 | B36: Sales cycle, Enterprise (quarters) | C36: qtr | D36: 2 | E36: 2 | F36: 2 | G36: 2 | H36: 2 | I36: 2 | J36: =INDEX(D36:I36,1,(Assumptions!$D$5-1)*3+Assumptions!$D$4) -> 2 | K36: B/D | L36: fixed | M36: Longer enterprise cycles (review C2)
A37: A27 | B37: Self-serve share of SMB wins (no AE) | C37: % | D37: 0.15 | E37: 0.3 | F37: 0.4 | G37: 0.3 | H37: 0.45 | I37: 0.6 | J37: =INDEX(D37:I37,1,(Assumptions!$D$5-1)*3+Assumptions!$D$4) -> 0.3 | K37: D | L37: value | M37: Builder capacity: Dist 0.69× vs PS 7.2× technical-talent index (H4)
A38: A28 | B38: Accounts a ramped dedicated AE works per quarter (beyond automated coverage) | C38: #/qtr | D38: 100 | E38: 150 | F38: 200 | G38: 100 | H38: 150 | I38: 200 | J38: =INDEX(D38:I38,1,(Assumptions!$D$5-1)*3+Assumptions!$D$4) -> 150 | K38: D | L38: demand | M38: AE self-sourcing (review C1); practitioner guidance: AEs self-source < ~30% of pipeline [K]
A39: A29 | B39: AE outreach meeting-rate multiplier vs automated outbound | C39: x | D39: 1.25 | E39: 1.5 | F39: 1.75 | G39: 1.25 | H39: 1.5 | I39: 1.75 | J39: =INDEX(D39:I39,1,(Assumptions!$D$5-1)*3+Assumptions!$D$4) -> 1.5 | K39: D | L39: demand | M39: Human, multi-channel prospecting
A40: ACV BUILD (usage-based pricing)
A41: A30 | B41: Sales occupations share of employment | C41: % | D41: 0.22 | E41: 0.22 | F41: 0.22 | G41: 0.062 | H41: 0.062 | I41: 0.062 | J41: =INDEX(D41:I41,1,(Assumptions!$D$5-1)*3+Assumptions!$D$4) -> 0.22 | K41: A→C | L41: fixed | M41: OEWS May 2025 (S15)
A42: A31 | B42: Accounts tracked per seller | C42: # | D42: 150 | E42: 150 | F42: 150 | G42: 150 | H42: 150 | I42: 150 | J42: =INDEX(D42:I42,1,(Assumptions!$D$5-1)*3+Assumptions!$D$4) -> 150 | K42: D | L42: fixed | M42: Same for both segments (neutrality)
...

Sheet Market Sizing
A1: Market Sizing — unique firms with 20+ employees by wave and size band (Census 2022, S14)
A2: Distribution waves: 4236 electrical → 4237 PHVAC → 4238 machinery/MRO. Professional-services waves: 5413 A&E → 5416 consulting → 5415 IT services (5418 advertising/PR excluded: Clay's agency partner channel). Firms, not establishments.
A4: NAICS | B4: Sub-industry | C4: Firms 20–49 | D4: 50–99 | E4: 100–249 | F4: 250–499 | G4: 500+ | H4: Emp. 20–49 | I4: 50–99 | J4: 100–249 | K4: 250–499 | L4: 500+
A5: 4236 | B5: Electrical & electronic goods wholesalers | C5: 1408 | D5: 570 | E5: 350 | F5: 136 | G5: 114 | H5: 42698 | I5: 39297 | J5: 54183 | K5: 47492 | L5: 315093
A6: 4237 | B6: Hardware, plumbing & HVAC wholesalers | C6: 1013 | D6: 424 | E6: 242 | F6: 85 | G6: 57 | H6: 31260 | I6: 29270 | J6: 36995 | K6: 29008 | L6: 116895
A7: 4238 | B7: Machinery, equipment & supplies wholesalers | C7: 3622 | D7: 1218 | E7: 746 | F7: 240 | G7: 183 | H7: 110129 | I7: 83565 | J7: 115979 | K7: 83365 | L7: 220621
A8: 5413 | B8: Architectural & engineering services | C8: 5930 | D8: 2104 | E8: 1251 | F8: 429 | G8: 387 | H8: 179028 | I8: 145073 | J8: 189979 | K8: 149368 | L8: 727292
A9: 5416 | B9: Management & technical consulting | C9: 5789 | D9: 2151 | E9: 1244 | F9: 430 | G9: 339 | H9: 174222 | I9: 148901 | J9: 188821 | K9: 149492 | L9: 677207
A10: 5415 | B10: Computer systems design (IT services) | C10: 5831 | D10: 2359 | E10: 1581 | F10: 561 | G10: 447 | H10: 179046 | I10: 164769 | J10: 240853 | K10: 195289 | L10: 1156449
A12: De-duplication factor by band (sector firms ÷ Σ sub-industry firms)
A13: DIST | B13: Sector 423 (50–499 not measurable: suppressed cells → 1.0) | C13: 0.973 | D13: 1 | E13: 1 | F13: 1 | G13: 1
A14: PS | B14: Sector 54 | C14: 0.988 | D14: 0.979 | E14: 0.967 | F14: 0.951 | G14: 0.972
A16: Wave | B16: Sub-industry | C16: SMB 20–99 | D16: Mid-Market 100–499 | E16: Enterprise 500+ | F16: Total
A17: DIST W1 | B17: =B5 -> Electrical & electronic goods wholesalers | C17: =C5*C$13+D5*D$13 -> 1939.984 | D17: =E5*E$13+F5*F$13 -> 486 | E17: =G5*G$13 -> 114 | F17: =SUM(C17:E17) -> 2539.984
A18: DIST W2 | B18: =B6 -> Hardware, plumbing & HVAC wholesalers | C18: =C6*C$13+D6*D$13 -> 1409.649 | D18: =E6*E$13+F6*F$13 -> 327 | E18: =G6*G$13 -> 57 | F18: =SUM(C18:E18) -> 1793.649
A19: DIST W3 | B19: =B7 -> Machinery, equipment & supplies wholesalers | C19: =C7*C$13+D7*D$13 -> 4742.206 | D19: =E7*E$13+F7*F$13 -> 986 | E19: =G7*G$13 -> 183 | F19: =SUM(C19:E19) -> 5911.206
A20: PS W1 | B20: =B8 -> Architectural & engineering services | C20: =C8*C$14+D8*D$14 -> 7918.656 | D20: =E8*E$14+F8*F$14 -> 1617.696 | E20: =G8*G$14 -> 376.164 | F20: =SUM(C20:E20) -> 9912.516
A21: PS W2 | B21: =B9 -> Management & technical consulting | C21: =C9*C$14+D9*D$14 -> 7825.361 | D21: =E9*E$14+F9*F$14 -> 1611.878 | E21: =G9*G$14 -> 329.508 | F21: =SUM(C21:E21) -> 9766.747
A22: PS W3 | B22: =B10 -> Computer systems design (IT services) | C22: =C10*C$14+D10*D$14 -> 8070.489 | D22: =E10*E$14+F10*F$14 -> 2062.338 | E22: =G10*G$14 -> 434.484 | F22: =SUM(C22:E22) -> 10567.311
A24: Segment | B24: Band | C24: Firms (3 waves) | D24: Employees | E24: Avg employees per firm
A25: Industrial distribution | B25: SMB 20–99 | C25: =C5+C6+C7+D5+D6+D7 -> 8255 | D25: =H5+H6+H7+I5+I6+I7 -> 336219 | E25: =D25/C25 -> 40.729134
A26: Industrial distribution | B26: Mid-Market 100–499 | C26: =E5+E6+E7+F5+F6+F7 -> 1799 | D26: =J5+J6+J7+K5+K6+K7 -> 367022 | E26: =D26/C26 -> 204.01445
A27: Industrial distribution | B27: Enterprise 500+ | C27: =G5+G6+G7 -> 354 | D27: =L5+L6+L7 -> 652609 | E27: =D27/C27 -> 1843.5282
A28: Professional services | B28: SMB 20–99 | C28: =C8+C9+C10+D8+D9+D10 -> 24164 | D28: =H8+H9+H10+I8+I9+I10 -> 991039 | E28: =D28/C28 -> 41.013036
A29: Professional services | B29: Mid-Market 100–499 | C29: =E8+E9+E10+F8+F9+F10 -> 5496 | D29: =J8+J9+J10+K8+K9+K10 -> 1113802 | E29: =D29/C29 -> 202.65684
A30: Professional services | B30: Enterprise 500+ | C30: =G8+G9+G10 -> 1173 | D30: =L8+L9+L10 -> 2560948 | E30: =D30/C30 -> 2183.2464
A32: Serviceable accounts (SAM) are computed inside each model run as firms × filter 1 × filter 2 × (1 − existing Clay customers), with the filters fixed across scenarios (v2, review M1/M2). Known limitation (review M3): Census sizes firms by total firm employment, and NAICS wholesale includes manufacturers' sales branches, so 500+ 'distributors' include manufacturers' sales arms: 4–22% of the band per Census type of operation (02 Firm_Counts Block 7). Removing them moves the lean-pilot Base NPV by −$0.01M to −$0.03M (appendix/msbo_sensitivity.py).

Sheet ACV Build
A1: ACV Build — usage-based first-year ACV by segment, band and scenario
A2: Sellers per firm × accounts tracked × Clay's published usage meters (S01). SMB/Mid-Market floored at the Growth plan; Enterprise floored at the Enterprise minimum, less discount.
A4: Band | B4: Dist: Downside | C4: Dist: Base | D4: Dist: Upside | E4: PS: Downside | F4: PS: Base | G4: PS: Upside | H4: Live
A5: SMB (20–99) | B5: =MAX((Assumptions!$D$51+Assumptions!$D$53)*12,(((('Market Sizing'!$E$25*Assumptions!$D$41*Assumptions!$D$42*Assumptions!$D$43)*Assumptions!$D$44)*Assumptions!$D$45*Assumptions!$D$46+('Market Sizing'!$E$25*Assumptions!$D$41*Assumptions!$D$42*Assumptions!$D$43)*Assumptions!$D$47+('Market Sizing'!$E$25*Assumptions!$D$41*Assumptions!$D$42*Assumptions!$D$43)*Assumptions!$D$48*Assumptions!$D$49)*(Assumptions!$D$51*12/Assumptions!$D$52)+((('Market Sizing'!$E$25*Assumptions!$D$41*Assumptions!$D$42*Assumptions!$D$43)*Assumptions!$D$44)*Assumptions!$D$45+('Market Sizing'!$E$25*Assumptions!$D$41*Assumptions!$D$42*Assumptions!$D$43)+('Market Sizing'!$E$25*Assumptions!$D$41*Assumptions!$D$42*Assumptions!$D$43)*Assumptions!$D$48)*Assumptions!$D$50*(Assumptions!$D$53*12/Assumptions!$D$54))) -> 5352 | C5: =MAX((Assumptions!$E$51+Assumptions!$E$53)*12,(((('Market Sizing'!$E$25*Assumptions!$E$41*Assumptions!$E$42*Assumptions!$E$43)*Assumptions!$E$44)*Assumptions!$E$45*Assumptions!$E$46+('Market Sizing'!$E$25*Assumptions!$E$41*Assumptions!$E$42*Assumptions!$E$43)*Assumptions!$E$47+('Market Sizing'!$E$25*Assumptions!$E$41*Assumptions!$E$42*Assumptions!$E$43)*Assumptions!$E$48*Assumptions!$E$49)*(Assumptions!$E$51*12/Assumptions!$E$52)+((('Market Sizing'!$E$25*Assumptions!$E$41*Assumptions!$E$42*Assumptions!$E$43)*Assumptions!$E$44)*Assumptions!$E$45+('Market Sizing'!$E$25*Assumptions!$E$41*Assumptions!$E$42*Assumptions!$E$43)+('Market Sizing'!$E$25*Assumptions!$E$41*Assumptions!$E$42*Assumptions!$E$43)*Assumptions!$E$48)*Assumptions!$E$50*(Assumptions!$E$53*12/Assumptions!$E$54))) -> 5352 | D5: =MAX((Assumptions!$F$51+Assumptions!$F$53)*12,(((('Market Sizing'!$E$25*Assumptions!$F$41*Assumptions!$F$42*Assumptions!$F$43)*Assumptions!$F$44)*Assumptions!$F$45*Assumptions!$F$46+('Market Sizing'!$E$25*Assumptions!$F$41*Assumptions!$F$42*Assumptions!$F$43)*Assumptions!$F$47+('Market Sizing'!$E$25*Assumptions!$F$41*Assumptions!$F$42*Assumptions!$F$43)*Assumptions!$F$48*Assumptions!$F$49)*(Assumptions!$F$51*12/Assumptions!$F$52)+((('Market Sizing'!$E$25*Assumptions!$F$41*Assumptions!$F$42*Assumptions!$F$43)*Assumptions!$F$44)*Assumptions!$F$45+('Market Sizing'!$E$25*Assumptions!$F$41*Assumptions!$F$42*Assumptions!$F$43)+('Market Sizing'!$E$25*Assumptions!$F$41*Assumptions!$F$42*Assumptions!$F$43)*Assumptions!$F$48)*Assumptions!$F$50*(Assumptions!$F$53*12/Assumptions!$F$54))) -> 5352 | E5: =MAX((Assumptions!$G$51+Assumptions!$G$53)*12,(((('Market Sizing'!$E$28*Assumptions!$G$41*Assumptions!$G$42*Assumptions!$G$43)*Assumptions!$G$44)*Assumptions!$G$45*Assumptions!$G$46+('Market Sizing'!$E$28*Assumptions!$G$41*Assumptions!$G$42*Assumptions!$G$43)*Assumptions!$G$47+('Market Sizing'!$E$28*Assumptions!$G$41*Assumptions!$G$42*Assumptions!$G$43)*Assumptions!$G$48*Assumptions!$G$49)*(Assumptions!$G$51*12/Assumptions!$G$52)+((('Market Sizing'!$E$28*Assumptions!$G$41*Assumptions!$G$42*Assumptions!$G$43)*Assumptions!$G$44)*Assumptions!$G$45+('Market Sizing'!$E$28*Assumptions!$G$41*Assumptions!$G$42*Assumptions!$G$43)+('Market Sizing'!$E$28*Assumptions!$G$41*Assumptions!$G$42*Assumptions!$G$43)*Assumptions!$G$48)*Assumptions!$G$50*(Assumptions!$G$53*12/Assumptions!$G$54))) -> 5352 | F5: =MAX((Assumptions!$H$51+Assumptions!$H$53)*12,(((('Market Sizing'!$E$28*Assumptions!$H$41*Assumptions!$H$42*Assumptions!$H$43)*Assumptions!$H$44)*Assumptions!$H$45*Assumptions!$H$46+('Market Sizing'!$E$28*Assumptions!$H$41*Assumptions!$H$42*Assumptions!$H$43)*Assumptions!$H$47+('Market Sizing'!$E$28*Assumptions!$H$41*Assumptions!$H$42*Assumptions!$H$43)*Assumptions!$H$48*Assumptions!$H$49)*(Assumptions!$H$51*12/Assumptions!$H$52)+((('Market Sizing'!$E$28*Assumptions!$H$41*Assumptions!$H$42*Assumptions!$H$43)*Assumptions!$H$44)*Assumptions!$H$45+('Market Sizing'!$E$28*Assumptions!$H$41*Assumptions!$H$42*Assumptions!$H$43)+('Market Sizing'!$E$28*Assumptions!$H$41*Assumptions!$H$42*Assumptions!$H$43)*Assumptions!$H$48)*Assumptions!$H$50*(Assumptions!$H$53*12/Assumptions!$H$54))) -> 5352 | G5: =MAX((Assumptions!$I$51+Assumptions!$I$53)*12,(((('Market Sizing'!$E$28*Assumptions!$I$41*Assumptions!$I$42*Assumptions!$I$43)*Assumptions!$I$44)*Assumptions!$I$45*Assumptions!$I$46+('Market Sizing'!$E$28*Assumptions!$I$41*Assumptions!$I$42*Assumptions!$I$43)*Assumptions!$I$47+('Market Sizing'!$E$28*Assumptions!$I$41*Assumptions!$I$42*Assumptions!$I$43)*Assumptions!$I$48*Assumptions!$I$49)*(Assumptions!$I$51*12/Assumptions!$I$52)+((('Market Sizing'!$E$28*Assumptions!$I$41*Assumptions!$I$42*Assumptions!$I$43)*Assumptions!$I$44)*Assumptions!$I$45+('Market Sizing'!$E$28*Assumptions!$I$41*Assumptions!$I$42*Assumptions!$I$43)+('Market Sizing'!$E$28*Assumptions!$I$41*Assumptions!$I$42*Assumptions!$I$43)*Assumptions!$I$48)*Assumptions!$I$50*(Assumptions!$I$53*12/Assumptions!$I$54))) -> 5352 | H5: =INDEX(B5:G5,1,(Assumptions!$D$5-1)*3+Assumptions!$D$4) -> 5352
A6: Mid-Market (100–499) | B6: =MAX((Assumptions!$D$51+Assumptions!$D$53)*12,(((('Market Sizing'!$E$26*Assumptions!$D$41*Assumptions!$D$42*Assumptions!$D$43)*Assumptions!$D$44)*Assumptions!$D$45*Assumptions!$D$46+('Market Sizing'!$E$26*Assumptions!$D$41*Assumptions!$D$42*Assumptions!$D$43)*Assumptions!$D$47+('Market Sizing'!$E$26*Assumptions!$D$41*Assumptions!$D$42*Assumptions!$D$43)*Assumptions!$D$48*Assumptions!$D$49)*(Assumptions!$D$51*12/Assumptions!$D$52)+((('Market Sizing'!$E$26*Assumptions!$D$41*Assumptions!$D$42*Assumptions!$D$43)*Assumptions!$D$44)*Assumptions!$D$45+('Market Sizing'!$E$26*Assumptions!$D$41*Assumptions!$D$42*Assumptions!$D$43)+('Market Sizing'!$E$26*Assumptions!$D$41*Assumptions!$D$42*Assumptions!$D$43)*Assumptions!$D$48)*Assumptions!$D$50*(Assumptions!$D$53*12/Assumptions!$D$54))) -> 7325.0401 | C6: =MAX((Assumptions!$E$51+Assumptions!$E$53)*12,(((('Market Sizing'!$E$26*Assumptions!$E$41*Assumptions!$E$42*Assumptions!$E$43)*Assumptions!$E$44)*Assumptions!$E$45*Assumptions!$E$46+('Market Sizing'!$E$26*Assumptions!$E$41*Assumptions!$E$42*Assumptions!$E$43)*Assumptions!$E$47+('Market Sizing'!$E$26*Assumptions!$E$41*Assumptions!$E$42*Assumptions!$E$43)*Assumptions!$E$48*Assumptions!$E$49)*(Assumptions!$E$51*12/Assumptions!$E$52)+((('Market Sizing'!$E$26*Assumptions!$E$41*Assumptions!$E$42*Assumptions!$E$43)*Assumptions!$E$44)*Assumptions!$E$45+('Market Sizing'!$E$26*Assumptions!$E$41*Assumptions!$E$42*Assumptions!$E$43)+('Market Sizing'!$E$26*Assumptions!$E$41*Assumptions!$E$42*Assumptions!$E$43)*Assumptions!$E$48)*Assumptions!$E$50*(Assumptions!$E$53*12/Assumptions!$E$54))) -> 9766.7201 | D6: =MAX((Assumptions!$F$51+Assumptions!$F$53)*12,(((('Market Sizing'!$E$26*Assumptions!$F$41*Assumptions!$F$42*Assumptions!$F$43)*Assumptions!$F$44)*Assumptions!$F$45*Assumptions!$F$46+('Market Sizing'!$E$26*Assumptions!$F$41*Assumptions!$F$42*Assumptions!$F$43)*Assumptions!$F$47+('Market Sizing'!$E$26*Assumptions!$F$41*Assumptions!$F$42*Assumptions!$F$43)*Assumptions!$F$48*Assumptions!$F$49)*(Assumptions!$F$51*12/Assumptions!$F$52)+((('Market Sizing'!$E$26*Assumptions!$F$41*Assumptions!$F$42*Assumptions!$F$43)*Assumptions!$F$44)*Assumptions!$F$45+('Market Sizing'!$E$26*Assumptions!$F$41*Assumptions!$F$42*Assumptions!$F$43)+('Market Sizing'!$E$26*Assumptions!$F$41*Assumptions!$F$42*Assumptions!$F$43)*Assumptions!$F$48)*Assumptions!$F$50*(Assumptions!$F$53*12/Assumptions!$F$54))) -> 14650.08 | E6: =MAX((Assumptions!$G$51+Assumptions!$G$53)*12,(((('Market Sizing'!$E$29*Assumptions!$G$41*Assumptions!$G$42*Assumptions!$G$43)*Assumptions!$G$44)*Assumptions!$G$45*Assumptions!$G$46+('Market Sizing'!$E$29*Assumptions!$G$41*Assumptions!$G$42*Assumptions!$G$43)*Assumptions!$G$47+('Market Sizing'!$E$29*Assumptions!$G$41*Assumptions!$G$42*Assumptions!$G$43)*Assumptions!$G$48*Assumptions!$G$49)*(Assumptions!$G$51*12/Assumptions!$G$52)+((('Market Sizing'!$E$29*Assumptions!$G$41*Assumptions!$G$42*Assumptions!$G$43)*Assumptions!$G$44)*Assumptions!$G$45+('Market Sizing'!$E$29*Assumptions!$G$41*Assumptions!$G$42*Assumptions!$G$43)+('Market Sizing'!$E$29*Assumptions!$G$41*Assumptions!$G$42*Assumptions!$G$43)*Assumptions!$G$48)*Assumptions!$G$50*(Assumptions!$G$53*12/Assumptions!$G$54))) -> 5352 | F6: =MAX((Assumptions!$H$51+Assumptions!$H$53)*12,(((('Market Sizing'!$E$29*Assumptions!$H$41*Assumptions!$H$42*Assumptions!$H$43)*Assumptions!$H$44)*Assumptions!$H$45*Assumptions!$H$46+('Market Sizing'!$E$29*Assumptions!$H$41*Assumptions!$H$42*Assumptions!$H$43)*Assumptions!$H$47+('Market Sizing'!$E$29*Assumptions!$H$41*Assumptions!$H$42*Assumptions!$H$43)*Assumptions!$H$48*Assumptions!$H$49)*(Assumptions!$H$51*12/Assumptions!$H$52)+((('Market Sizing'!$E$29*Assumptions!$H$41*Assumptions!$H$42*Assumptions!$H$43)*Assumptions!$H$44)*Assumptions!$H$45+('Market Sizing'!$E$29*Assumptions!$H$41*Assumptions!$H$42*Assumptions!$H$43)+('Market Sizing'!$E$29*Assumptions!$H$41*Assumptions!$H$42*Assumptions!$H$43)*Assumptions!$H$48)*Assumptions!$H$50*(Assumptions!$H$53*12/Assumptions!$H$54))) -> 5352 | G6: =MAX((Assumptions!$I$51+Assumptions!$I$53)*12,(((('Market Sizing'!$E$29*Assumptions!$I$41*Assumptions!$I$42*Assumptions!$I$43)*Assumptions!$I$44)*Assumptions!$I$45*Assumptions!$I$46+('Market Sizing'!$E$29*Assumptions!$I$41*Assumptions!$I$42*Assumptions!$I$43)*Assumptions!$I$47+('Market Sizing'!$E$29*Assumptions!$I$41*Assumptions!$I$42*Assumptions!$I$43)*Assumptions!$I$48*Assumptions!$I$49)*(Assumptions!$I$51*12/Assumptions!$I$52)+((('Market Sizing'!$E$29*Assumptions!$I$41*Assumptions!$I$42*Assumptions!$I$43)*Assumptions!$I$44)*Assumptions!$I$45+('Market Sizing'!$E$29*Assumptions!$I$41*Assumptions!$I$42*Assumptions!$I$43)+('Market Sizing'!$E$29*Assumptions!$I$41*Assumptions!$I$42*Assumptions!$I$43)*Assumptions!$I$48)*Assumptions!$I$50*(Assumptions!$I$53*12/Assumptions!$I$54))) -> 5352 | H6: =INDEX(B6:G6,1,(Assumptions!$D$5-1)*3+Assumptions!$D$4) -> 9766.7201
A7: Enterprise (500+) | B7: =MAX(Assumptions!$D$55*(Assumptions!$D$51*12/Assumptions!$D$52)+Assumptions!$D$56*(Assumptions!$D$53*12/Assumptions!$D$54),(((('Market Sizing'!$E$27*Assumptions!$D$41*Assumptions!$D$42*Assumptions!$D$43)*Assumptions!$D$44)*Assumptions!$D$45*Assumptions!$D$46+('Market Sizing'!$E$27*Assumptions!$D$41*Assumptions!$D$42*Assumptions!$D$43)*Assumptions!$D$47+('Market Sizing'!$E$27*Assumptions!$D$41*Assumptions!$D$42*Assumptions!$D$43)*Assumptions!$D$48*Assumptions!$D$49)*(Assumptions!$D$51*12/Assumptions!$D$52)+((('Market Sizing'!$E$27*Assumptions!$D$41*Assumptions!$D$42*Assumptions!$D$43)*Assumptions!$D$44)*Assumptions!$D$45+('Market Sizing'!$E$27*Assumptions!$D$41*Assumptions!$D$42*Assumptions!$D$43)+('Market Sizing'!$E$27*Assumptions!$D$41*Assumptions!$D$42*Assumptions!$D$43)*Assumptions!$D$48)*Assumptions!$D$50*(Assumptions!$D$53*12/Assumptions!$D$54)))*(1-Assumptions!$D$57) -> 46333.692 | C7: =MAX(Assumptions!$E$55*(Assumptions!$E$51*12/Assumptions!$E$52)+Assumptions!$E$56*(Assumptions!$E$53*12/Assumptions!$E$54),(((('Market Sizing'!$E$27*Assumptions!$E$41*Assumptions!$E$42*Assumptions!$E$43)*Assumptions!$E$44)*Assumptions!$E$45*Assumptions!$E$46+('Market Sizing'!$E$27*Assumptions!$E$41*Assumptions!$E$42*Assumptions!$E$43)*Assumptions!$E$47+('Market Sizing'!$E$27*Assumptions!$E$41*Assumptions!$E$42*Assumptions!$E$43)*Assumptions!$E$48*Assumptions!$E$49)*(Assumptions!$E$51*12/Assumptions!$E$52)+((('Market Sizing'!$E$27*Assumptions!$E$41*Assumptions!$E$42*Assumptions!$E$43)*Assumptions!$E$44)*Assumptions!$E$45+('Market Sizing'!$E$27*Assumptions!$E$41*Assumptions!$E$42*Assumptions!$E$43)+('Market Sizing'!$E$27*Assumptions!$E$41*Assumptions!$E$42*Assumptions!$E$43)*Assumptions!$E$48)*Assumptions!$E$50*(Assumptions!$E$53*12/Assumptions!$E$54)))*(1-Assumptions!$E$57) -> 61778.256 | D7: =MAX(Assumptions!$F$55*(Assumptions!$F$51*12/Assumptions!$F$52)+Assumptions!$F$56*(Assumptions!$F$53*12/Assumptions!$F$54),(((('Market Sizing'!$E$27*Assumptions!$F$41*Assumptions!$F$42*Assumptions!$F$43)*Assumptions!$F$44)*Assumptions!$F$45*Assumptions!$F$46+('Market Sizing'!$E$27*Assumptions!$F$41*Assumptions!$F$42*Assumptions!$F$43)*Assumptions!$F$47+('Market Sizing'!$E$27*Assumptions!$F$41*Assumptions!$F$42*Assumptions!$F$43)*Assumptions!$F$48*Assumptions!$F$49)*(Assumptions!$F$51*12/Assumptions!$F$52)+((('Market Sizing'!$E$27*Assumptions!$F$41*Assumptions!$F$42*Assumptions!$F$43)*Assumptions!$F$44)*Assumptions!$F$45+('Market Sizing'!$E$27*Assumptions!$F$41*Assumptions!$F$42*Assumptions!$F$43)+('Market Sizing'!$E$27*Assumptions!$F$41*Assumptions!$F$42*Assumptions!$F$43)*Assumptions!$F$48)*Assumptions!$F$50*(Assumptions!$F$53*12/Assumptions!$F$54)))*(1-Assumptions!$F$57) -> 92667.384 | E7: =MAX(Assumptions!$G$55*(Assumptions!$G$51*12/Assumptions!$G$52)+Assumptions!$G$56*(Assumptions!$G$53*12/Assumptions!$G$54),(((('Market Sizing'!$E$30*Assumptions!$G$41*Assumptions!$G$42*Assumptions!$G$43)*Assumptions!$G$44)*Assumptions!$G$45*Assumptions!$G$46+('Market Sizing'!$E$30*Assumptions!$G$41*Assumptions!$G$42*Assumptions!$G$43)*Assumptions!$G$47+('Market Sizing'!$E$30*Assumptions!$G$41*Assumptions!$G$42*Assumptions!$G$43)*Assumptions!$G$48*Assumptions!$G$49)*(Assumptions!$G$51*12/Assumptions!$G$52)+((('Market Sizing'!$E$30*Assumptions!$G$41*Assumptions!$G$42*Assumptions!$G$43)*Assumptions!$G$44)*Assumptions!$G$45+('Market Sizing'!$E$30*Assumptions!$G$41*Assumptions!$G$42*Assumptions!$G$43)+('Market Sizing'!$E$30*Assumptions!$G$41*Assumptions!$G$42*Assumptions!$G$43)*Assumptions!$G$48)*Assumptions!$G$50*(Assumptions!$G$53*12/Assumptions!$G$54)))*(1-Assumptions!$G$57) -> 44310 | F7: =MAX(Assumptions!$H$55*(Assumptions!$H$51*12/Assumptions!$H$52)+Assumptions!$H$56*(Assumptions!$H$53*12/Assumptions!$H$54),(((('Market Sizing'!$E$30*Assumptions!$H$41*Assumptions!$H$42*Assumptions!$H$43)*Assumptions!$H$44)*Assumptions!$H$45*Assumptions!$H$46+('Market Sizing'!$E$30*Assumptions!$H$41*Assumptions!$H$42*Assumptions!$H$43)*Assumptions!$H$47+('Market Sizing'!$E$30*Assumptions!$H$41*Assumptions!$H$42*Assumptions!$H$43)*Assumptions!$H$48*Assumptions!$H$49)*(Assumptions!$H$51*12/Assumptions!$H$52)+((('Market Sizing'!$E$30*Assumptions!$H$41*Assumptions!$H$42*Assumptions!$H$43)*Assumptions!$H$44)*Assumptions!$H$45+('Market Sizing'!$E$30*Assumptions!$H$41*Assumptions!$H$42*Assumptions!$H$43)+('Market Sizing'!$E$30*Assumptions!$H$41*Assumptions!$H$42*Assumptions!$H$43)*Assumptions!$H$48)*Assumptions!$H$50*(Assumptions!$H$53*12/Assumptions!$H$54)))*(1-Assumptions!$H$57) -> 44310 | G7: =MAX(Assumptions!$I$55*(Assumptions!$I$51*12/Assumptions!$I$52)+Assumptions!$I$56*(Assumptions!$I$53*12/Assumptions!$I$54),(((('Market Sizing'!$E$30*Assumptions!$I$41*Assumptions!$I$42*Assumptions!$I$43)*Assumptions!$I$44)*Assumptions!$I$45*Assumptions!$I$46+('Market Sizing'!$E$30*Assumptions!$I$41*Assumptions!$I$42*Assumptions!$I$43)*Assumptions!$I$47+('Market Sizing'!$E$30*Assumptions!$I$41*Assumptions!$I$42*Assumptions!$I$43)*Assumptions!$I$48*Assumptions!$I$49)*(Assumptions!$I$51*12/Assumptions!$I$52)+((('Market Sizing'!$E$30*Assumptions!$I$41*Assumptions!$I$42*Assumptions!$I$43)*Assumptions!$I$44)*Assumptions!$I$45+('Market Sizing'!$E$30*Assumptions!$I$41*Assumptions!$I$42*Assumptions!$I$43)+('Market Sizing'!$E$30*Assumptions!$I$41*Assumptions!$I$42*Assumptions!$I$43)*Assumptions!$I$48)*Assumptions!$I$50*(Assumptions!$I$53*12/Assumptions!$I$54)))*(1-Assumptions!$I$57) -> 44310 | H7: =INDEX(B7:G7,1,(Assumptions!$D$5-1)*3+Assumptions!$D$4) -> 61778.256
A9: Sellers per firm (Base)
A10: SMB | C10: ='Market Sizing'!$E$25*Assumptions!$E$41 -> 8.9604094 | F10: ='Market Sizing'!$E$28*Assumptions!$H$41 -> 2.5428082
A11: Mid-Market | C11: ='Market Sizing'!$E$26*Assumptions!$E$41 -> 44.88318 | F11: ='Market Sizing'!$E$29*Assumptions!$H$41 -> 12.564724
A12: Enterprise | C12: ='Market Sizing'!$E$27*Assumptions!$E$41 -> 405.57621 | F12: ='Market Sizing'!$E$30*Assumptions!$H$41 -> 135.36128
A14: Reading: at list prices, a distributor's seller density lifts ACV above the Growth floor only from Mid-Market up. Professional-services firms have ~4× fewer sellers per firm, so their SMB and Mid-Market ACV both sit at the floor. Base Enterprise ACV for distribution ≈ Vendr's median Clay buyer ($59,996, S16).

Sheet GTM Funnel
A1: GTM Funnel — live model (selected segment, scenario and motion)
A2: Accounts → meetings, MQLs and partner introductions → opportunities (mix by band derived from accounts) → wins, with a closing-capacity constraint.
A3: ="Live run: "&Assumptions!$E$5&" · "&Assumptions!$E$4&" · "&Assumptions!$E$6 -> Live run: Industrial distribution · Base · Lean partner-led pilot
A5: Live model — run constants | B5: Unit / note | C5: Q1 2027 | D5: Q2 2027 | E5: Q3 2027 | F5: Q4 2027 | G5: Q1 2028 | H5: Q2 2028 | I5: Q3 2028 | J5: Q4 2028 | K5: Q1 2029 | L5: Q2 2029 | M5: Q3 2029 | N5: Q4 2029 | P5: 2027 | Q5: 2028 | R5: 2029 | S5: 2027–29
A6: SAM accounts — wave 1, S | B6: firms × filters | C6: =IF(Assumptions!$D$5=1,'Market Sizing'!$C$17,'Market Sizing'!$C$20)*Assumptions!$J$10*Assumptions!$J$11*(1-Assumptions!$J$12) -> 843.03945
A7: SAM accounts — wave 1, M | B7: firms × filters | C7: =IF(Assumptions!$D$5=1,'Market Sizing'!$D$17,'Market Sizing'!$D$20)*Assumptions!$J$10*Assumptions!$J$11*(1-Assumptions!$J$12) -> 211.19616
A8: SAM accounts — wave 1, E | B8: firms × filters | C8: =IF(Assumptions!$D$5=1,'Market Sizing'!$E$17,'Market Sizing'!$E$20)*Assumptions!$J$10*Assumptions!$J$11*(1-Assumptions!$J$12) -> 49.53984
A9: SAM accounts — wave 1, total | C9: =$C$6+$C$7+$C$8 -> 1103.7754
A10: SAM accounts — wave 2, S | B10: firms × filters | C10: =IF(Assumptions!$D$5=1,'Market Sizing'!$C$18,'Market Sizing'!$C$21)*Assumptions!$J$10*Assumptions!$J$11*(1-Assumptions!$J$12) -> 612.57707
A11: SAM accounts — wave 2, M | B11: firms × filters | C11: =IF(Assumptions!$D$5=1,'Market Sizing'!$D$18,'Market Sizing'!$D$21)*Assumptions!$J$10*Assumptions!$J$11*(1-Assumptions!$J$12) -> 142.10112
A12: SAM accounts — wave 2, E | B12: firms × filters | C12: =IF(Assumptions!$D$5=1,'Market Sizing'!$E$18,'Market Sizing'!$E$21)*Assumptions!$J$10*Assumptions!$J$11*(1-Assumptions!$J$12) -> 24.76992
A13: SAM accounts — wave 2, total | C13: =$C$10+$C$11+$C$12 -> 779.44811
A14: SAM accounts — wave 3, S | B14: firms × filters | C14: =IF(Assumptions!$D$5=1,'Market Sizing'!$C$19,'Market Sizing'!$C$22)*Assumptions!$J$10*Assumptions!$J$11*(1-Assumptions!$J$12) -> 2060.773
A15: SAM accounts — wave 3, M | B15: firms × filters | C15: =IF(Assumptions!$D$5=1,'Market Sizing'!$D$19,'Market Sizing'!$D$22)*Assumptions!$J$10*Assumptions!$J$11*(1-Assumptions!$J$12) -> 428.47616
A16: SAM accounts — wave 3, E | B16: firms × filters | C16: =IF(Assumptions!$D$5=1,'Market Sizing'!$E$19,'Market Sizing'!$E$22)*Assumptions!$J$10*Assumptions!$J$11*(1-Assumptions!$J$12) -> 79.52448
A17: SAM accounts — wave 3, total | C17: =$C$14+$C$15+$C$16 -> 2568.7737
A18: First-year ACV — S | B18: usage build | C18: =IF(Assumptions!$D$5=1,MAX((Assumptions!$J$51+Assumptions!$J$53)*12,(((('Market Sizing'!$E$25*Assumptions!$J$41*Assumptions!$J$42*Assumptions!$J$43)*Assumptions!$J$44)*Assumptions!$J$45*Assumptions!$J$46+('Market Sizing'!$E$25*Assumptions!$J$41*Assumptions!$J$42*Assumptions!$J$43)*Assumptions!$J$47+('Market Sizing'!$E$25*Assumptions!$J$41*Assumptions!$J$42*Assumptions!$J$43)*Assumptions!$J$48*Assumptions!$J$49)*(Assumptions!$J$51*12/Assumptions!$J$52)+((('Market Sizing'!$E$25*Assumptions!$J$41*Assumptions!$J$42*Assumptions!$J$43)*Assumptions!$J$44)*Assumptions!$J$45+('Market Sizing'!$E$25*Assumptions!$J$41*Assumptions!$J$42*Assumptions!$J$43)+('Market Sizing'!$E$25*Assumptions!$J$41*Assumptions!$J$42*Assumptions!$J$43)*Assumptions!$J$48)*Assumptions!$J$50*(Assumptions!$J$53*12/Assumptions!$J$54))),MAX((Assumptions!$J$51+Assumptions!$J$53)*12,(((('Market Sizing'!$E$28*Assumptions!$J$41*Assumptions!$J$42*Assumptions!$J$43)*Assumptions!$J$44)*Assumptions!$J$45*Assumptions!$J$46+('Market Sizing'!$E$28*Assumptions!$J$41*Assumptions!$J$42*Assumptions!$J$43)*Assumptions!$J$47+('Market Sizing'!$E$28*Assumptions!$J$41*Assumptions!$J$42*Assumptions!$J$43)*Assumptions!$J$48*Assumptions!$J$49)*(Assumptions!$J$51*12/Assumptions!$J$52)+((('Market Sizing'!$E$28*Assumptions!$J$41*Assumptions!$J$42*Assumptions!$J$43)*Assumptions!$J$44)*Assumptions!$J$45+('Market Sizing'!$E$28*Assumptions!$J$41*Assumptions!$J$42*Assumptions!$J$43)+('Market Sizing'!$E$28*Assumptions!$J$41*Assumptions!$J$42*Assumptions!$J$43)*Assumptions!$J$48)*Assumptions!$J$50*(Assumptions!$J$53*12/Assumptions!$J$54)))) -> 5352
A19: First-year ACV — M | B19: usage build | C19: =IF(Assumptions!$D$5=1,MAX((Assumptions!$J$51+Assumptions!$J$53)*12,(((('Market Sizing'!$E$26*Assumptions!$J$41*Assumptions!$J$42*Assumptions!$J$43)*Assumptions!$J$44)*Assumptions!$J$45*Assumptions!$J$46+('Market Sizing'!$E$26*Assumptions!$J$41*Assumptions!$J$42*Assumptions!$J$43)*Assumptions!$J$47+('Market Sizing'!$E$26*Assumptions!$J$41*Assumptions!$J$42*Assumptions!$J$43)*Assumptions!$J$48*Assumptions!$J$49)*(Assumptions!$J$51*12/Assumptions!$J$52)+((('Market Sizing'!$E$26*Assumptions!$J$41*Assumptions!$J$42*Assumptions!$J$43)*Assumptions!$J$44)*Assumptions!$J$45+('Market Sizing'!$E$26*Assumptions!$J$41*Assumptions!$J$42*Assumptions!$J$43)+('Market Sizing'!$E$26*Assumptions!$J$41*Assumptions!$J$42*Assumptions!$J$43)*Assumptions!$J$48)*Assumptions!$J$50*(Assumptions!$J$53*12/Assumptions!$J$54))),MAX((Assumptions!$J$51+Assumptions!$J$53)*12,(((('Market Sizing'!$E$29*Assumptions!$J$41*Assumptions!$J$42*Assumptions!$J$43)*Assumptions!$J$44)*Assumptions!$J$45*Assumptions!$J$46+('Market Sizing'!$E$29*Assumptions!$J$41*Assumptions!$J$42*Assumptions!$J$43)*Assumptions!$J$47+('Market Sizing'!$E$29*Assumptions!$J$41*Assumptions!$J$42*Assumptions!$J$43)*Assumptions!$J$48*Assumptions!$J$49)*(Assumptions!$J$51*12/Assumptions!$J$52)+((('Market Sizing'!$E$29*Assumptions!$J$41*Assumptions!$J$42*Assumptions!$J$43)*Assumptions!$J$44)*Assumptions!$J$45+('Market Sizing'!$E$29*Assumptions!$J$41*Assumptions!$J$42*Assumptions!$J$43)+('Market Sizing'!$E$29*Assumptions!$J$41*Assumptions!$J$42*Assumptions!$J$43)*Assumptions!$J$48)*Assumptions!$J$50*(Assumptions!$J$53*12/Assumptions!$J$54)))) -> 9766.7201
A20: First-year ACV — E | B20: usage build | C20: =IF(Assumptions!$D$5=1,MAX(Assumptions!$J$55*(Assumptions!$J$51*12/Assumptions!$J$52)+Assumptions!$J$56*(Assumptions!$J$53*12/Assumptions!$J$54),(((('Market Sizing'!$E$27*Assumptions!$J$41*Assumptions!$J$42*Assumptions!$J$43)*Assumptions!$J$44)*Assumptions!$J$45*Assumptions!$J$46+('Market Sizing'!$E$27*Assumptions!$J$41*Assumptions!$J$42*Assumptions!$J$43)*Assumptions!$J$47+('Market Sizing'!$E$27*Assumptions!$J$41*Assumptions!$J$42*Assumptions!$J$43)*Assumptions!$J$48*Assumptions!$J$49)*(Assumptions!$J$51*12/Assumptions!$J$52)+((('Market Sizing'!$E$27*Assumptions!$J$41*Assumptions!$J$42*Assumptions!$J$43)*Assumptions!$J$44)*Assumptions!$J$45+('Market Sizing'!$E$27*Assumptions!$J$41*Assumptions!$J$42*Assumptions!$J$43)+('Market Sizing'!$E$27*Assumptions!$J$41*Assumptions!$J$42*Assumptions!$J$43)*Assumptions!$J$48)*Assumptions!$J$50*(Assumptions!$J$53*12/Assumptions!$J$54)))*(1-Assumptions!$J$57),MAX(Assumptions!$J$55*(Assumptions!$J$51*12/Assumptions!$J$52)+Assumptions!$J$56*(Assumptions!$J$53*12/Assumptions!$J$54),(((('Market Sizing'!$E$30*Assumptions!$J$41*Assumptions!$J$42*Assumptions!$J$43)*Assumptions!$J$44)*Assumptions!$J$45*Assumptions!$J$46+('Market Sizing'!$E$30*Assumptions!$J$41*Assumptions!$J$42*Assumptions!$J$43)*Assumptions!$J$47+('Market Sizing'!$E$30*Assumptions!$J$41*Assumptions!$J$42*Assumptions!$J$43)*Assumptions!$J$48*Assumptions!$J$49)*(Assumptions!$J$51*12/Assumptions!$J$52)+((('Market Sizing'!$E$30*Assumptions!$J$41*Assumptions!$J$42*Assumptions!$J$43)*Assumptions!$J$44)*Assumptions!$J$45+('Market Sizing'!$E$30*Assumptions!$J$41*Assumptions!$J$42*Assumptions!$J$43)+('Market Sizing'!$E$30*Assumptions!$J$41*Assumptions!$J$42*Assumptions!$J$43)*Assumptions!$J$48)*Assumptions!$J$50*(Assumptions!$J$53*12/Assumptions!$J$54)))*(1-Assumptions!$J$57)) -> 61778.256
A21: Automated outbound coverage per quarter | B21: coverage × motion multiplier | C21: =Assumptions!$J$17*Assumptions!$J$106 -> 0.4
A22: AE fully loaded annual cost | B22: OTE ÷ wage share | C22: =Assumptions!$J$68/Assumptions!$J$69 -> 285714.29
A23: ARR one ramped AE closes per quarter | B23: quota × productivity ÷ 4 | C23: =Assumptions!$J$66*Assumptions!$J$67/4 -> 153125
A24: AE cost per $ of first-year ACV closed | C24: =$C$22/Assumptions!$J$66/Assumptions!$J$67 -> 0.4664723
A25: Program spend above base, per quarter | C25: =MAX(0,Assumptions!$J$103-Assumptions!$J$78) -> 0
A26: Demand and funnel | B26: Unit / note | C26: Q1 2027 | D26: Q2 2027 | E26: Q3 2027 | F26: Q4 2027 | G26: Q1 2028 | H26: Q2 2028 | I26: Q3 2028 | J26: Q4 2028 | K26: Q1 2029 | L26: Q2 2029 | M26: Q3 2029 | N26: Q4 2029 | P26: 2027 | Q26: 2028 | R26: 2029 | S26: 2027–29
A27: Quarter number | B27: # | C27: 1 | D27: 2 | E27: 3 | F27: 4 | G27: 5 | H27: 6 | I27: 7 | J27: 8 | K27: 9 | L27: 10 | M27: 11 | N27: 12
A28: Program running (1) / stopped (0) | B28: flag | C28: =IF(C27<=Assumptions!$J$84,1,0) -> 1 | D28: =IF(D27<=Assumptions!$J$84,1,0) -> 1 | E28: =IF(E27<=Assumptions!$J$84,1,0) -> 1 | F28: =IF(F27<=Assumptions!$J$84,1,0) -> 1 | G28: =IF(G27<=Assumptions!$J$84,1,0) -> 1 | H28: =IF(H27<=Assumptions!$J$84,1,0) -> 1 | I28: =IF(I27<=Assumptions!$J$84,1,0) -> 1 | J28: =IF(J27<=Assumptions!$J$84,1,0) -> 1 | ... N28: =IF(N27<=Assumptions!$J$84,1,0) -> 1
A29: Wave 1 active (0.5 in launch quarter) | B29: factor | C29: =IF(C27=Assumptions!$J$13,0.5,IF(C27>Assumptions!$J$13,1,0)) -> 0.5 | D29: =IF(D27=Assumptions!$J$13,0.5,IF(D27>Assumptions!$J$13,1,0)) -> 1 | E29: =IF(E27=Assumptions!$J$13,0.5,IF(E27>Assumptions!$J$13,1,0)) -> 1 | F29: =IF(F27=Assumptions!$J$13,0.5,IF(F27>Assumptions!$J$13,1,0)) -> 1 | G29: =IF(G27=Assumptions!$J$13,0.5,IF(G27>Assumptions!$J$13,1,0)) -> 1 | H29: =IF(H27=Assumptions!$J$13,0.5,IF(H27>Assumptions!$J$13,1,0)) -> 1 | I29: =IF(I27=Assumptions!$J$13,0.5,IF(I27>Assumptions!$J$13,1,0)) -> 1 | J29: =IF(J27=Assumptions!$J$13,0.5,IF(J27>Assumptions!$J$13,1,0)) -> 1 | ... N29: =IF(N27=Assumptions!$J$13,0.5,IF(N27>Assumptions!$J$13,1,0)) -> 1
A30: Wave 2 active (0.5 in launch quarter) | B30: factor | C30: =IF(C27=Assumptions!$J$14,0.5,IF(C27>Assumptions!$J$14,1,0)) -> 0 | D30: =IF(D27=Assumptions!$J$14,0.5,IF(D27>Assumptions!$J$14,1,0)) -> 0 | E30: =IF(E27=Assumptions!$J$14,0.5,IF(E27>Assumptions!$J$14,1,0)) -> 0 | F30: =IF(F27=Assumptions!$J$14,0.5,IF(F27>Assumptions!$J$14,1,0)) -> 0 | G30: =IF(G27=Assumptions!$J$14,0.5,IF(G27>Assumptions!$J$14,1,0)) -> 0.5 | H30: =IF(H27=Assumptions!$J$14,0.5,IF(H27>Assumptions!$J$14,1,0)) -> 1 | I30: =IF(I27=Assumptions!$J$14,0.5,IF(I27>Assumptions!$J$14,1,0)) -> 1 | J30: =IF(J27=Assumptions!$J$14,0.5,IF(J27>Assumptions!$J$14,1,0)) -> 1 | ... N30: =IF(N27=Assumptions!$J$14,0.5,IF(N27>Assumptions!$J$14,1,0)) -> 1
A31: Wave 3 active (0.5 in launch quarter) | B31: factor | C31: =IF(C27=Assumptions!$J$15,0.5,IF(C27>Assumptions!$J$15,1,0)) -> 0 | D31: =IF(D27=Assumptions!$J$15,0.5,IF(D27>Assumptions!$J$15,1,0)) -> 0 | E31: =IF(E27=Assumptions!$J$15,0.5,IF(E27>Assumptions!$J$15,1,0)) -> 0 | F31: =IF(F27=Assumptions!$J$15,0.5,IF(F27>Assumptions!$J$15,1,0)) -> 0 | G31: =IF(G27=Assumptions!$J$15,0.5,IF(G27>Assumptions!$J$15,1,0)) -> 0 | H31: =IF(H27=Assumptions!$J$15,0.5,IF(H27>Assumptions!$J$15,1,0)) -> 0 | I31: =IF(I27=Assumptions!$J$15,0.5,IF(I27>Assumptions!$J$15,1,0)) -> 0.5 | J31: =IF(J27=Assumptions!$J$15,0.5,IF(J27>Assumptions!$J$15,1,0)) -> 1 | ... N31: =IF(N27=Assumptions!$J$15,0.5,IF(N27>Assumptions!$J$15,1,0)) -> 1
A32: Wave 1 outbound fatigue factor | B32: factor | C32: =Assumptions!$J$21^(MAX(0,C27-Assumptions!$J$13)/4) -> 1 | D32: =Assumptions!$J$21^(MAX(0,D27-Assumptions!$J$13)/4) -> 0.93060486 | E32: =Assumptions!$J$21^(MAX(0,E27-Assumptions!$J$13)/4) -> 0.8660254 | F32: =Assumptions!$J$21^(MAX(0,F27-Assumptions!$J$13)/4) -> 0.80592745 | G32: =Assumptions!$J$21^(MAX(0,G27-Assumptions!$J$13)/4) -> 0.75 | H32: =Assumptions!$J$21^(MAX(0,H27-Assumptions!$J$13)/4) -> 0.69795364 | I32: =Assumptions!$J$21^(MAX(0,I27-Assumptions!$J$13)/4) -> 0.64951905 | J32: =Assumptions!$J$21^(MAX(0,J27-Assumptions!$J$13)/4) -> 0.60444559 | ... N32: =Assumptions!$J$21^(MAX(0,N27-Assumptions!$J$13)/4) -> 0.45333419
A33: Wave 2 outbound fatigue factor | B33: factor | C33: =Assumptions!$J$21^(MAX(0,C27-Assumptions!$J$14)/4) -> 1 | D33: =Assumptions!$J$21^(MAX(0,D27-Assumptions!$J$14)/4) -> 1 | E33: =Assumptions!$J$21^(MAX(0,E27-Assumptions!$J$14)/4) -> 1 | F33: =Assumptions!$J$21^(MAX(0,F27-Assumptions!$J$14)/4) -> 1 | G33: =Assumptions!$J$21^(MAX(0,G27-Assumptions!$J$14)/4) -> 1 | H33: =Assumptions!$J$21^(MAX(0,H27-Assumptions!$J$14)/4) -> 0.93060486 | I33: =Assumptions!$J$21^(MAX(0,I27-Assumptions!$J$14)/4) -> 0.8660254 | J33: =Assumptions!$J$21^(MAX(0,J27-Assumptions!$J$14)/4) -> 0.80592745 | ... N33: =Assumptions!$J$21^(MAX(0,N27-Assumptions!$J$14)/4) -> 0.60444559
A34: Wave 3 outbound fatigue factor | B34: factor | C34: =Assumptions!$J$21^(MAX(0,C27-Assumptions!$J$15)/4) -> 1 | D34: =Assumptions!$J$21^(MAX(0,D27-Assumptions!$J$15)/4) -> 1 | E34: =Assumptions!$J$21^(MAX(0,E27-Assumptions!$J$15)/4) -> 1 | F34: =Assumptions!$J$21^(MAX(0,F27-Assumptions!$J$15)/4) -> 1 | G34: =Assumptions!$J$21^(MAX(0,G27-Assumptions!$J$15)/4) -> 1 | H34: =Assumptions!$J$21^(MAX(0,H27-Assumptions!$J$15)/4) -> 1 | I34: =Assumptions!$J$21^(MAX(0,I27-Assumptions!$J$15)/4) -> 1 | J34: =Assumptions!$J$21^(MAX(0,J27-Assumptions!$J$15)/4) -> 0.93060486 | ... N34: =Assumptions!$J$21^(MAX(0,N27-Assumptions!$J$15)/4) -> 0.69795364
A35: Active SAM accounts — S | B35: accounts | C35: =$C$6*C29+$C$10*C30+$C$14*C31 -> 421.51972 | D35: =$C$6*D29+$C$10*D30+$C$14*D31 -> 843.03945 | E35: =$C$6*E29+$C$10*E30+$C$14*E31 -> 843.03945 | F35: =$C$6*F29+$C$10*F30+$C$14*F31 -> 843.03945 | G35: =$C$6*G29+$C$10*G30+$C$14*G31 -> 1149.328 | H35: =$C$6*H29+$C$10*H30+$C$14*H31 -> 1455.6165 | I35: =$C$6*I29+$C$10*I30+$C$14*I31 -> 2486.003 | J35: =$C$6*J29+$C$10*J30+$C$14*J31 -> 3516.3896 | ... N35: =$C$6*N29+$C$10*N30+$C$14*N31 -> 3516.3896 | P35: =F35 -> 843.03945 | Q35: =J35 -> 3516.3896 | R35: =N35 -> 3516.3896 | S35: =R35 -> 3516.3896
A36: Active SAM accounts — M | B36: accounts | C36: =$C$7*C29+$C$11*C30+$C$15*C31 -> 105.59808 | D36: =$C$7*D29+$C$11*D30+$C$15*D31 -> 211.19616 | E36: =$C$7*E29+$C$11*E30+$C$15*E31 -> 211.19616 | F36: =$C$7*F29+$C$11*F30+$C$15*F31 -> 211.19616 | G36: =$C$7*G29+$C$11*G30+$C$15*G31 -> 282.24672 | H36: =$C$7*H29+$C$11*H30+$C$15*H31 -> 353.29728 | I36: =$C$7*I29+$C$11*I30+$C$15*I31 -> 567.53536 | J36: =$C$7*J29+$C$11*J30+$C$15*J31 -> 781.77344 | ... N36: =$C$7*N29+$C$11*N30+$C$15*N31 -> 781.77344 | P36: =F36 -> 211.19616 | Q36: =J36 -> 781.77344 | R36: =N36 -> 781.77344 | S36: =R36 -> 781.77344
A37: Active SAM accounts — E | B37: accounts | C37: =$C$8*C29+$C$12*C30+$C$16*C31 -> 24.76992 | D37: =$C$8*D29+$C$12*D30+$C$16*D31 -> 49.53984 | E37: =$C$8*E29+$C$12*E30+$C$16*E31 -> 49.53984 | F37: =$C$8*F29+$C$12*F30+$C$16*F31 -> 49.53984 | G37: =$C$8*G29+$C$12*G30+$C$16*G31 -> 61.9248 | H37: =$C$8*H29+$C$12*H30+$C$16*H31 -> 74.30976 | I37: =$C$8*I29+$C$12*I30+$C$16*I31 -> 114.072 | J37: =$C$8*J29+$C$12*J30+$C$16*J31 -> 153.83424 | ... N37: =$C$8*N29+$C$12*N30+$C$16*N31 -> 153.83424 | P37: =F37 -> 49.53984 | Q37: =J37 -> 153.83424 | R37: =N37 -> 153.83424 | S37: =R37 -> 153.83424
A38: Active SAM accounts — total | B38: accounts | C38: =C35+C36+C37 -> 551.88772 | D38: =D35+D36+D37 -> 1103.7754 | E38: =E35+E36+E37 -> 1103.7754 | F38: =F35+F36+F37 -> 1103.7754 | G38: =G35+G36+G37 -> 1493.4995 | H38: =H35+H36+H37 -> 1883.2236 | I38: =I35+I36+I37 -> 3167.6104 | J38: =J35+J36+J37 -> 4451.9972 | ... N38: =N35+N36+N37 -> 4451.9972 | P38: =F38 -> 1103.7754 | Q38: =J38 -> 4451.9972 | R38: =N38 -> 4451.9972 | S38: =R38 -> 4451.9972
A39: Fatigue-weighted active accounts | B39: accounts | C39: =$C$9*C29*C32+$C$13*C30*C33+$C$17*C31*C34 -> 551.88772 | D39: =$C$9*D29*D32+$C$13*D30*D33+$C$17*D31*D34 -> 1027.1788 | E39: =$C$9*E29*E32+$C$13*E30*E33+$C$17*E31*E34 -> 955.89758 | F39: =$C$9*F29*F32+$C$13*F30*F33+$C$17*F31*F34 -> 889.56293 | G39: =$C$9*G29*G32+$C$13*G30*G33+$C$17*G31*G34 -> 1217.5556 | H39: =$C$9*H29*H32+$C$13*H30*H33+$C$17*H31*H34 -> 1495.7423 | I39: =$C$9*I29*I32+$C$13*I30*I33+$C$17*I31*I34 -> 2676.3319 | J39: =$C$9*J29*J32+$C$13*J30*J33+$C$17*J31*J34 -> 3685.8641 | ... N39: =$C$9*N29*N32+$C$13*N30*N33+$C$17*N31*N34 -> 2764.3981
A40: Meetings — automated outbound | B40: meetings | C40: =$C$21*Assumptions!$J$20*C28*C39 -> 6.6226527 | D40: =$C$21*Assumptions!$J$20*D28*D39 -> 12.326146 | E40: =$C$21*Assumptions!$J$20*E28*E39 -> 11.470771 | F40: =$C$21*Assumptions!$J$20*F28*F39 -> 10.674755 | G40: =$C$21*Assumptions!$J$20*G28*G39 -> 14.610668 | H40: =$C$21*Assumptions!$J$20*H28*H39 -> 17.948908 | I40: =$C$21*Assumptions!$J$20*I28*I39 -> 32.115983 | J40: =$C$21*Assumptions!$J$20*J28*J39 -> 44.230369 | ... N40: =$C$21*Assumptions!$J$20*N28*N39 -> 33.172777 | P40: =SUM(C40:F40) -> 41.094324 | Q40: =SUM(G40:J40) -> 108.90593 | R40: =SUM(K40:N40) -> 148.28487 | S40: =SUM(P40:R40) -> 298.28512
A41: Dedicated AEs (headcount) | B41: FTE | C41: =Assumptions!$D$115 -> 0 | D41: =Assumptions!$E$115 -> 0 | E41: =Assumptions!$F$115 -> 0 | F41: =Assumptions!$G$115 -> 0 | G41: =Assumptions!$H$115 -> 0 | H41: =Assumptions!$I$115 -> 0 | I41: =Assumptions!$J$115 -> 0 | J41: =Assumptions!$K$115 -> 0 | K41: =Assumptions!$L$115 -> 0 | L41: =Assumptions!$M$115 -> 0 | M41: =Assumptions!$N$115 -> 0 | N41: =Assumptions!$O$115 -> 0 | P41: =F41 -> 0 | Q41: =J41 -> 0 | R41: =N41 -> 0 | S41: =R41 -> 0
...

Sheet Revenue Model
A1: Revenue Model — customers, ARR and recognized revenue
A2: ARR = prior ARR × NRR^(1/4) + new customers × ACV. Recognized revenue = average ARR ÷ 4 (kept separate from ARR).
A3: ="Live run: "&Assumptions!$E$5&" · "&Assumptions!$E$4&" · "&Assumptions!$E$6 -> Live run: Industrial distribution · Base · Lean partner-led pilot
A5: Customers, ARR and revenue | B5: Unit / note | C5: Q1 2027 | D5: Q2 2027 | E5: Q3 2027 | F5: Q4 2027 | G5: Q1 2028 | H5: Q2 2028 | I5: Q3 2028 | J5: Q4 2028 | K5: Q1 2029 | L5: Q2 2029 | M5: Q3 2029 | N5: Q4 2029 | P5: 2027 | Q5: 2028 | R5: 2029 | S5: 2027–29
A6: Customers — SMB | B6: customers | C6: =0*Assumptions!$J$59^(1/4)+'GTM Funnel'!C69 -> 0 | D6: =C6*Assumptions!$J$59^(1/4)+'GTM Funnel'!D69 -> 0.86637645 | E6: =D6*Assumptions!$J$59^(1/4)+'GTM Funnel'!E69 -> 2.3241633 | F6: =E6*Assumptions!$J$59^(1/4)+'GTM Funnel'!F69 -> 3.8896686 | G6: =F6*Assumptions!$J$59^(1/4)+'GTM Funnel'!G69 -> 5.5626536 | H6: =G6*Assumptions!$J$59^(1/4)+'GTM Funnel'!H69 -> 7.6978878 | I6: =H6*Assumptions!$J$59^(1/4)+'GTM Funnel'!I69 -> 10.246876 | J6: =I6*Assumptions!$J$59^(1/4)+'GTM Funnel'!J69 -> 14.055274 | K6: =J6*Assumptions!$J$59^(1/4)+'GTM Funnel'!K69 -> 18.956351 | ... N6: =M6*Assumptions!$J$59^(1/4)+'GTM Funnel'!N69 -> 32.402329 | P6: =F6 -> 3.8896686 | Q6: =J6 -> 14.055274 | R6: =N6 -> 32.402329 | S6: =R6 -> 32.402329
A7: Customers — Mid-Market | B7: customers | C7: =0*Assumptions!$J$60^(1/4)+'GTM Funnel'!C70 -> 0 | D7: =C7*Assumptions!$J$60^(1/4)+'GTM Funnel'!D70 -> 0.43408497 | E7: =D7*Assumptions!$J$60^(1/4)+'GTM Funnel'!E70 -> 1.166856 | F7: =E7*Assumptions!$J$60^(1/4)+'GTM Funnel'!F70 -> 1.9575219 | G7: =F7*Assumptions!$J$60^(1/4)+'GTM Funnel'!G70 -> 2.8061554 | H7: =G7*Assumptions!$J$60^(1/4)+'GTM Funnel'!H70 -> 3.8678611 | I7: =H7*Assumptions!$J$60^(1/4)+'GTM Funnel'!I70 -> 5.1221897 | J7: =I7*Assumptions!$J$60^(1/4)+'GTM Funnel'!J70 -> 6.8750429 | K7: =J7*Assumptions!$J$60^(1/4)+'GTM Funnel'!K70 -> 9.0721291 | ... N7: =M7*Assumptions!$J$60^(1/4)+'GTM Funnel'!N70 -> 15.170152 | P7: =F7 -> 1.9575219 | Q7: =J7 -> 6.8750429 | R7: =N7 -> 15.170152 | S7: =R7 -> 15.170152
A8: Customers — Enterprise | B8: customers | C8: =0*Assumptions!$J$61^(1/4)+'GTM Funnel'!C71 -> 0 | D8: =C8*Assumptions!$J$61^(1/4)+'GTM Funnel'!D71 -> 0 | E8: =D8*Assumptions!$J$61^(1/4)+'GTM Funnel'!E71 -> 0.071275681 | F8: =E8*Assumptions!$J$61^(1/4)+'GTM Funnel'!F71 -> 0.19197739 | G8: =F8*Assumptions!$J$61^(1/4)+'GTM Funnel'!G71 -> 0.3228231 | H8: =G8*Assumptions!$J$61^(1/4)+'GTM Funnel'!H71 -> 0.46386262 | I8: =H8*Assumptions!$J$61^(1/4)+'GTM Funnel'!I71 -> 0.62855328 | J8: =I8*Assumptions!$J$61^(1/4)+'GTM Funnel'!J71 -> 0.81506857 | K8: =J8*Assumptions!$J$61^(1/4)+'GTM Funnel'!K71 -> 1.0636097 | ... N8: =M8*Assumptions!$J$61^(1/4)+'GTM Funnel'!N71 -> 1.9556183 | P8: =F8 -> 0.19197739 | Q8: =J8 -> 0.81506857 | R8: =N8 -> 1.9556183 | S8: =R8 -> 1.9556183
A9: Customers — total | B9: customers | C9: =C6+C7+C8 -> 0 | D9: =D6+D7+D8 -> 1.3004614 | E9: =E6+E7+E8 -> 3.562295 | F9: =F6+F7+F8 -> 6.0391679 | G9: =G6+G7+G8 -> 8.6916321 | H9: =H6+H7+H8 -> 12.029611 | I9: =I6+I7+I8 -> 15.997619 | J9: =J6+J7+J8 -> 21.745385 | ... N9: =N6+N7+N8 -> 49.528099 | P9: =F9 -> 6.0391679 | Q9: =J9 -> 21.745385 | R9: =N9 -> 49.528099 | S9: =R9 -> 49.528099
